Workbook
Name bb: LANÇAMENTO[[#Headers],[OBRA]]
Name bb: LANÇAMENTO[[#Headers],[OBRA]]
Name FORNECEDORES: FORNECEDOR[]
Name FORNECEDORES: FORNECEDOR[]
Name FORNECEDORES: FORNECEDOR[]
Name FORNECEDORES: FORNECEDOR[]
Name FORNECEDORES: FORNECEDOR[]
Name FORNECEDORES: FORNECEDOR[]
Name OBRA: LANÇAMENTO[[#Headers],[OBRA]]
Name OBRA: LANÇAMENTO[[#Headers],[OBRA]]
Name OBRA: LANÇAMENTO[[#Headers],[OBRA]]
Name OBRA: LANÇAMENTO[[#Headers],[OBRA]]
Name OBRA: LANÇAMENTO[[#Headers],[OBRA]]
Name OBRA: LANÇAMENTO[[#Headers],[OBRA]]
Name OBRA: LANÇAMENTO[[#Headers],[OBRA]]

Sheet LANÇAMENTO
E1: =TODAY() -> 46129
A2: DATA SOLICITAÇÃO | B2: OBRA | C2: FATURAMENTO | D2: ITEM | E2: MATERIAL SOLICITADO | F2: QTDADE | G2: UNID | H2: PEDIDO | I2: FORNECEDOR | J2: DESCRIÇÃO MATERIAL | K2: VALOR UNITARIO | L2: VALOR TOTAL | M2: DATA PEDIDO | N2: MÊS/ANO PEDIDO | O2: CONDIÇÃO PAGAMENTO | P2: FORMA DE PAGAMENTO | Q2: RETIRA OU ENTREGA | R2: PRAZO | S2: PREVISÃO ENTREGA OBRA | T2: RESTA | U2: OBRA COM MATERIAL | V2: OBSERVAÇÃO
A3: 45795 | B3: SYLVIA DE MELLO | C3: =VLOOKUP(LANÇAMENTO[[#This Row],[OBRA]],OBRAS[],2,FALSE) -> B&B | D3: ELETRICA | E3: PLACA 4X4 CEGA BR SIENA | F3: 2 | G3: UNID. | H3: 1846 | I3: AREA ELETRICOS | J3: PLACA 4X4 CEGA BR SIENA | K3: 5.5 | L3: =LANÇAMENTO[[#This Row],[VALOR UNITARIO]]*LANÇAMENTO[[#This Row],[QTDADE]] -> 11 | M3: 45887 | N3: =TEXT(LANÇAMENTO[[#This Row],[DATA PEDIDO]],"MMM")&"-"&TEXT(M3,"AAAA") -> ago-2025 | O3: 30/60/90 | P3: BOLETO | Q3: RETIRA | R3: 0 | S3: =IF(LANÇAMENTO[[#This Row],[DATA PEDIDO]]="","",LANÇAMENTO[[#This Row],[DATA PEDIDO]]+LANÇAMENTO[[#This Row],[PRAZO]]) -> 45887 | T3: =IF(LANÇAMENTO[[#This Row],[OBRA COM MATERIAL]]="OK","ENTREGUE",IF(LANÇAMENTO[[#This Row],[PRAZO]]="","",LANÇAMENTO[[#This Row],[PREVISÃO ENTREGA OBRA]]-$E$1)) -> ENTREGUE | U3: OK
A4: 45795 | B4: SYLVIA DE MELLO | C4: =VLOOKUP(LANÇAMENTO[[#This Row],[OBRA]],OBRAS[],2,FALSE) -> B&B | D4: ELETRICA | E4: PLACA 4X4 2MOD BR SIENA | F4: 1 | G4: UNID. | H4: 1846 | I4: AREA ELETRICOS | J4: PLACA 4X4 2MOD BR SIENA | K4: 5.5 | L4: =LANÇAMENTO[[#This Row],[VALOR UNITARIO]]*LANÇAMENTO[[#This Row],[QTDADE]] -> 5.5 | M4: 45887 | N4: =TEXT(LANÇAMENTO[[#This Row],[DATA PEDIDO]],"MMM")&"-"&TEXT(M4,"AAAA") -> ago-2025 | O4: 30/60/90 | P4: BOLETO | Q4: RETIRA | R4: 0 | S4: =IF(LANÇAMENTO[[#This Row],[DATA PEDIDO]]="","",LANÇAMENTO[[#This Row],[DATA PEDIDO]]+LANÇAMENTO[[#This Row],[PRAZO]]) -> 45887 | T4: =IF(LANÇAMENTO[[#This Row],[OBRA COM MATERIAL]]="OK","ENTREGUE",IF(LANÇAMENTO[[#This Row],[PRAZO]]="","",LANÇAMENTO[[#This Row],[PREVISÃO ENTREGA OBRA]]-$E$1)) -> ENTREGUE | U4: OK
A5: 45795 | B5: SYLVIA DE MELLO | C5: =VLOOKUP(LANÇAMENTO[[#This Row],[OBRA]],OBRAS[],2,FALSE) -> B&B | D5: ELETRICA | E5: MODULO INT BIPOLAR SIMP 10A BR SIENA | F5: 1 | G5: UNID. | H5: 1846 | I5: AREA ELETRICOS | J5: MODULO INT BIPOLAR SIMP 10A BR SIENA | K5: 24.9 | L5: =LANÇAMENTO[[#This Row],[VALOR UNITARIO]]*LANÇAMENTO[[#This Row],[QTDADE]] -> 24.9 | M5: 45887 | N5: =TEXT(LANÇAMENTO[[#This Row],[DATA PEDIDO]],"MMM")&"-"&TEXT(M5,"AAAA") -> ago-2025 | O5: 30/60/90 | P5: BOLETO | Q5: RETIRA | R5: 0 | S5: =IF(LANÇAMENTO[[#This Row],[DATA PEDIDO]]="","",LANÇAMENTO[[#This Row],[DATA PEDIDO]]+LANÇAMENTO[[#This Row],[PRAZO]]) -> 45887 | T5: =IF(LANÇAMENTO[[#This Row],[OBRA COM MATERIAL]]="OK","ENTREGUE",IF(LANÇAMENTO[[#This Row],[PRAZO]]="","",LANÇAMENTO[[#This Row],[PREVISÃO ENTREGA OBRA]]-$E$1)) -> ENTREGUE | U5: OK
A6: 45795 | B6: SYLVIA DE MELLO | C6: =VLOOKUP(LANÇAMENTO[[#This Row],[OBRA]],OBRAS[],2,FALSE) -> B&B | D6: ELETRICA | E6: MODULO CEGO BR SIENA | F6: 1 | G6: UNID. | H6: 1846 | I6: AREA ELETRICOS | J6: MODULO CEGO BR SIENA | K6: 1.1 | L6: =LANÇAMENTO[[#This Row],[VALOR UNITARIO]]*LANÇAMENTO[[#This Row],[QTDADE]] -> 1.1 | M6: 45887 | N6: =TEXT(LANÇAMENTO[[#This Row],[DATA PEDIDO]],"MMM")&"-"&TEXT(M6,"AAAA") -> ago-2025 | O6: 30/60/90 | P6: BOLETO | Q6: RETIRA | R6: 0 | S6: =IF(LANÇAMENTO[[#This Row],[DATA PEDIDO]]="","",LANÇAMENTO[[#This Row],[DATA PEDIDO]]+LANÇAMENTO[[#This Row],[PRAZO]]) -> 45887 | T6: =IF(LANÇAMENTO[[#This Row],[OBRA COM MATERIAL]]="OK","ENTREGUE",IF(LANÇAMENTO[[#This Row],[PRAZO]]="","",LANÇAMENTO[[#This Row],[PREVISÃO ENTREGA OBRA]]-$E$1)) -> ENTREGUE | U6: OK
A7: 45795 | B7: SYLVIA DE MELLO | C7: =VLOOKUP(LANÇAMENTO[[#This Row],[OBRA]],OBRAS[],2,FALSE) -> B&B | D7: ELETRICA | E7: PLACA 4X2 1MOD HORIZONTA BR SIENA | F7: 1 | G7: UNID. | H7: 1846 | I7: AREA ELETRICOS | J7: PLACA 4X2 1MOD HORIZONTA BR SIENA | K7: 2.8 | L7: =LANÇAMENTO[[#This Row],[VALOR UNITARIO]]*LANÇAMENTO[[#This Row],[QTDADE]] -> 2.8 | M7: 45887 | N7: =TEXT(LANÇAMENTO[[#This Row],[DATA PEDIDO]],"MMM")&"-"&TEXT(M7,"AAAA") -> ago-2025 | O7: 30/60/90 | P7: BOLETO | Q7: RETIRA | R7: 0 | S7: =IF(LANÇAMENTO[[#This Row],[DATA PEDIDO]]="","",LANÇAMENTO[[#This Row],[DATA PEDIDO]]+LANÇAMENTO[[#This Row],[PRAZO]]) -> 45887 | T7: =IF(LANÇAMENTO[[#This Row],[OBRA COM MATERIAL]]="OK","ENTREGUE",IF(LANÇAMENTO[[#This Row],[PRAZO]]="","",LANÇAMENTO[[#This Row],[PREVISÃO ENTREGA OBRA]]-$E$1)) -> ENTREGUE | U7: OK
A8: 45795 | B8: SYLVIA DE MELLO | C8: =VLOOKUP(LANÇAMENTO[[#This Row],[OBRA]],OBRAS[],2,FALSE) -> B&B | D8: ELETRICA | E8: MODULO INT BIPOLAR SIMP 10A BR SIENA | F8: 1 | G8: UNID. | H8: 1846 | I8: AREA ELETRICOS | J8: MODULO INT BIPOLAR SIMP 10A BR SIENA | K8: 26 | L8: =LANÇAMENTO[[#This Row],[VALOR UNITARIO]]*LANÇAMENTO[[#This Row],[QTDADE]] -> 26 | M8: 45887 | N8: =TEXT(LANÇAMENTO[[#This Row],[DATA PEDIDO]],"MMM")&"-"&TEXT(M8,"AAAA") -> ago-2025 | O8: 30/60/90 | P8: BOLETO | Q8: RETIRA | R8: 0 | S8: =IF(LANÇAMENTO[[#This Row],[DATA PEDIDO]]="","",LANÇAMENTO[[#This Row],[DATA PEDIDO]]+LANÇAMENTO[[#This Row],[PRAZO]]) -> 45887 | T8: =IF(LANÇAMENTO[[#This Row],[OBRA COM MATERIAL]]="OK","ENTREGUE",IF(LANÇAMENTO[[#This Row],[PRAZO]]="","",LANÇAMENTO[[#This Row],[PREVISÃO ENTREGA OBRA]]-$E$1)) -> ENTREGUE | U8: OK
A9: 45795 | B9: SYLVIA DE MELLO | C9: =VLOOKUP(LANÇAMENTO[[#This Row],[OBRA]],OBRAS[],2,FALSE) -> B&B | D9: ELETRICA | E9: PLACA 4X2 CEGA BR SIENA | F9: 1 | G9: UNID. | H9: 1846 | I9: AREA ELETRICOS | J9: PLACA 4X2 CEGA BR SIENA | K9: 2.8 | L9: =LANÇAMENTO[[#This Row],[VALOR UNITARIO]]*LANÇAMENTO[[#This Row],[QTDADE]] -> 2.8 | M9: 45887 | N9: =TEXT(LANÇAMENTO[[#This Row],[DATA PEDIDO]],"MMM")&"-"&TEXT(M9,"AAAA") -> ago-2025 | O9: 30/60/90 | P9: BOLETO | Q9: RETIRA | R9: 0 | S9: =IF(LANÇAMENTO[[#This Row],[DATA PEDIDO]]="","",LANÇAMENTO[[#This Row],[DATA PEDIDO]]+LANÇAMENTO[[#This Row],[PRAZO]]) -> 45887 | T9: =IF(LANÇAMENTO[[#This Row],[OBRA COM MATERIAL]]="OK","ENTREGUE",IF(LANÇAMENTO[[#This Row],[PRAZO]]="","",LANÇAMENTO[[#This Row],[PREVISÃO ENTREGA OBRA]]-$E$1)) -> ENTREGUE | U9: OK
A10: 45795 | B10: SYLVIA DE MELLO | C10: =VLOOKUP(LANÇAMENTO[[#This Row],[OBRA]],OBRAS[],2,FALSE) -> B&B | D10: ELETRICA | E10: PLACA 4X2 SAIDA DE FIO BR SIENA | F10: 1 | G10: UNID. | H10: 1846 | I10: AREA ELETRICOS | J10: PLACA 4X2 SAIDA DE FIO BR SIENA | K10: 2.8 | L10: =LANÇAMENTO[[#This Row],[VALOR UNITARIO]]*LANÇAMENTO[[#This Row],[QTDADE]] -> 2.8 | M10: 45887 | N10: =TEXT(LANÇAMENTO[[#This Row],[DATA PEDIDO]],"MMM")&"-"&TEXT(M10,"AAAA") -> ago-2025 | O10: 30/60/90 | P10: BOLETO | Q10: RETIRA | R10: 0 | S10: =IF(LANÇAMENTO[[#This Row],[DATA PEDIDO]]="","",LANÇAMENTO[[#This Row],[DATA PEDIDO]]+LANÇAMENTO[[#This Row],[PRAZO]]) -> 45887 | T10: =IF(LANÇAMENTO[[#This Row],[OBRA COM MATERIAL]]="OK","ENTREGUE",IF(LANÇAMENTO[[#This Row],[PRAZO]]="","",LANÇAMENTO[[#This Row],[PREVISÃO ENTREGA OBRA]]-$E$1)) -> ENTREGUE | U10: OK
A11: 45795 | B11: SYLVIA DE MELLO | C11: =VLOOKUP(LANÇAMENTO[[#This Row],[OBRA]],OBRAS[],2,FALSE) -> B&B | D11: ELETRICA | E11: PARAFUSO SEXTAVADO 3/16X60MM P/BUCHA S08 | F11: 500 | G11: UNID. | H11: 1846 | I11: AREA ELETRICOS | J11: PARAFUSO SEXTAVADO 3/16X60MM P/BUCHA S08 | K11: 0.1 | L11: =LANÇAMENTO[[#This Row],[VALOR UNITARIO]]*LANÇAMENTO[[#This Row],[QTDADE]] -> 50 | M11: 45887 | N11: =TEXT(LANÇAMENTO[[#This Row],[DATA PEDIDO]],"MMM")&"-"&TEXT(M11,"AAAA") -> ago-2025 | O11: 30/60/90 | P11: BOLETO | Q11: RETIRA | R11: 0 | S11: =IF(LANÇAMENTO[[#This Row],[DATA PEDIDO]]="","",LANÇAMENTO[[#This Row],[DATA PEDIDO]]+LANÇAMENTO[[#This Row],[PRAZO]]) -> 45887 | T11: =IF(LANÇAMENTO[[#This Row],[OBRA COM MATERIAL]]="OK","ENTREGUE",IF(LANÇAMENTO[[#This Row],[PRAZO]]="","",LANÇAMENTO[[#This Row],[PREVISÃO ENTREGA OBRA]]-$E$1)) -> ENTREGUE | U11: OK
A12: 45795 | B12: SYLVIA DE MELLO | C12: =VLOOKUP(LANÇAMENTO[[#This Row],[OBRA]],OBRAS[],2,FALSE) -> B&B | D12: ELETRICA | E12: BUCHA FUS-8 P/ PARAFUSO PVC BLOCO | F12: 500 | G12: UNID. | H12: 1846 | I12: AREA ELETRICOS | J12: BUCHA FUS-8 P/ PARAFUSO PVC BLOCO | K12: 0.2 | L12: =LANÇAMENTO[[#This Row],[VALOR UNITARIO]]*LANÇAMENTO[[#This Row],[QTDADE]] -> 100 | M12: 45887 | N12: =TEXT(LANÇAMENTO[[#This Row],[DATA PEDIDO]],"MMM")&"-"&TEXT(M12,"AAAA") -> ago-2025 | O12: 30/60/90 | P12: BOLETO | Q12: RETIRA | R12: 0 | S12: =IF(LANÇAMENTO[[#This Row],[DATA PEDIDO]]="","",LANÇAMENTO[[#This Row],[DATA PEDIDO]]+LANÇAMENTO[[#This Row],[PRAZO]]) -> 45887 | T12: =IF(LANÇAMENTO[[#This Row],[OBRA COM MATERIAL]]="OK","ENTREGUE",IF(LANÇAMENTO[[#This Row],[PRAZO]]="","",LANÇAMENTO[[#This Row],[PREVISÃO ENTREGA OBRA]]-$E$1)) -> ENTREGUE | U12: OK
A13: 45795 | B13: SYLVIA DE MELLO | C13: =VLOOKUP(LANÇAMENTO[[#This Row],[OBRA]],OBRAS[],2,FALSE) -> B&B | D13: ELETRICA | E13: PARAFUSO SEXTAVADO AUTO BROCANTE 1/4X1 | F13: 200 | G13: UNID. | H13: 1846 | I13: AREA ELETRICOS | J13: PARAFUSO SEXTAVADO AUTO BROCANTE 1/4X1 | K13: 0.7 | L13: =LANÇAMENTO[[#This Row],[VALOR UNITARIO]]*LANÇAMENTO[[#This Row],[QTDADE]] -> 140 | M13: 45887 | N13: =TEXT(LANÇAMENTO[[#This Row],[DATA PEDIDO]],"MMM")&"-"&TEXT(M13,"AAAA") -> ago-2025 | O13: 30/60/90 | P13: BOLETO | Q13: RETIRA | R13: 0 | S13: =IF(LANÇAMENTO[[#This Row],[DATA PEDIDO]]="","",LANÇAMENTO[[#This Row],[DATA PEDIDO]]+LANÇAMENTO[[#This Row],[PRAZO]]) -> 45887 | T13: =IF(LANÇAMENTO[[#This Row],[OBRA COM MATERIAL]]="OK","ENTREGUE",IF(LANÇAMENTO[[#This Row],[PRAZO]]="","",LANÇAMENTO[[#This Row],[PREVISÃO ENTREGA OBRA]]-$E$1)) -> ENTREGUE | U13: OK
A14: 45795 | B14: SYLVIA DE MELLO | C14: =VLOOKUP(LANÇAMENTO[[#This Row],[OBRA]],OBRAS[],2,FALSE) -> B&B | D14: ELETRICA | E14: CABO FLEX750V 2,5MM2 PT | F14: 14 | G14: ROLO | H14: 1846 | I14: AREA ELETRICOS | J14: CABO FLEX750V 2,5MM2 PT | K14: 192 | L14: =LANÇAMENTO[[#This Row],[VALOR UNITARIO]]*LANÇAMENTO[[#This Row],[QTDADE]] -> 2688 | M14: 45887 | N14: =TEXT(LANÇAMENTO[[#This Row],[DATA PEDIDO]],"MMM")&"-"&TEXT(M14,"AAAA") -> ago-2025 | O14: 30/60/90 | P14: BOLETO | Q14: RETIRA | R14: 0 | S14: =IF(LANÇAMENTO[[#This Row],[DATA PEDIDO]]="","",LANÇAMENTO[[#This Row],[DATA PEDIDO]]+LANÇAMENTO[[#This Row],[PRAZO]]) -> 45887 | T14: =IF(LANÇAMENTO[[#This Row],[OBRA COM MATERIAL]]="OK","ENTREGUE",IF(LANÇAMENTO[[#This Row],[PRAZO]]="","",LANÇAMENTO[[#This Row],[PREVISÃO ENTREGA OBRA]]-$E$1)) -> ENTREGUE | U14: OK
... A31: 45874 | B31: DAGOBERTO SALLES FILHO | C31: =VLOOKUP(LANÇAMENTO[[#This Row],[OBRA]],OBRAS[],2,FALSE) -> INTERIORANA | D31: OUTROS | E31: 64 pçs c/ 1.150mm(Sup) x 1.000mm(Inf) - dir/esq | F31: 73.6 | G31: M | H31: 1774 | I31: BIG TELHAS | J31: 64 pçs c/ 1.150mm(Sup) x 1.000mm(Inf) - dir/esq | K31: 118.9 | L31: =LANÇAMENTO[[#This Row],[VALOR UNITARIO]]*LANÇAMENTO[[#This Row],[QTDADE]] -> 8751.04 | M31: 45874 | N31: =TEXT(LANÇAMENTO[[#This Row],[DATA PEDIDO]],"MMM")&"-"&TEXT(M31,"AAAA") -> ago-2025 | O31: 30/60/90 | P31: BOLETO | Q31: ENTREGA | R31: 10 | S31: =IF(LANÇAMENTO[[#This Row],[DATA PEDIDO]]="","",LANÇAMENTO[[#This Row],[DATA PEDIDO]]+LANÇAMENTO[[#This Row],[PRAZO]]) -> 45884 | T31: =IF(LANÇAMENTO[[#This Row],[OBRA COM MATERIAL]]="OK","ENTREGUE",IF(LANÇAMENTO[[#This Row],[PRAZO]]="","",LANÇAMENTO[[#This Row],[PREVISÃO ENTREGA OBRA]]-$E$1)) -> ENTREGUE | U31: OK
A32: 45874 | B32: JOSE DE ALMEIDA PINHEIRO | C32: =VLOOKUP(LANÇAMENTO[[#This Row],[OBRA]],OBRAS[],2,FALSE) -> B&B | D32: HIDRAULICA | E32: LEVE BARRA APOIO RETA 80CM PCD POL | F32: 2 | G32: UNID. | H32: 1775 | I32: CASA MIMOSA | J32: LEVE BARRA APOIO RETA 80CM PCD POL | K32: 164.98 | L32: =LANÇAMENTO[[#This Row],[VALOR UNITARIO]]*LANÇAMENTO[[#This Row],[QTDADE]] -> 329.96 | M32: 45874 | N32: =TEXT(LANÇAMENTO[[#This Row],[DATA PEDIDO]],"MMM")&"-"&TEXT(M32,"AAAA") -> ago-2025 | O32: 28 | P32: BOLETO | Q32: RETIRA | R32: 1 | S32: =IF(LANÇAMENTO[[#This Row],[DATA PEDIDO]]="","",LANÇAMENTO[[#This Row],[DATA PEDIDO]]+LANÇAMENTO[[#This Row],[PRAZO]]) -> 45875 | T32: =IF(LANÇAMENTO[[#This Row],[OBRA COM MATERIAL]]="OK","ENTREGUE",IF(LANÇAMENTO[[#This Row],[PRAZO]]="","",LANÇAMENTO[[#This Row],[PREVISÃO ENTREGA OBRA]]-$E$1)) -> ENTREGUE | U32: OK | V32: MATERIAL PARA OBRA PEI CRISTIANE CHAVES, FATURAR PARA A B&B
A33: 45874 | B33: JOSE DE ALMEIDA PINHEIRO | C33: =VLOOKUP(LANÇAMENTO[[#This Row],[OBRA]],OBRAS[],2,FALSE) -> B&B | D33: HIDRAULICA | E33: LEVE BARRA APOIO RETA 40CM PCD POL | F33: 3 | G33: UNID. | H33: 1775 | I33: CASA MIMOSA | J33: LEVE BARRA APOIO RETA 40CM PCD POL | K33: 128.23 | L33: =LANÇAMENTO[[#This Row],[VALOR UNITARIO]]*LANÇAMENTO[[#This Row],[QTDADE]] -> 384.69 | M33: 45874 | N33: =TEXT(LANÇAMENTO[[#This Row],[DATA PEDIDO]],"MMM")&"-"&TEXT(M33,"AAAA") -> ago-2025 | O33: 28 | P33: BOLETO | Q33: RETIRA | R33: 1 | S33: =IF(LANÇAMENTO[[#This Row],[DATA PEDIDO]]="","",LANÇAMENTO[[#This Row],[DATA PEDIDO]]+LANÇAMENTO[[#This Row],[PRAZO]]) -> 45875 | T33: =IF(LANÇAMENTO[[#This Row],[OBRA COM MATERIAL]]="OK","ENTREGUE",IF(LANÇAMENTO[[#This Row],[PRAZO]]="","",LANÇAMENTO[[#This Row],[PREVISÃO ENTREGA OBRA]]-$E$1)) -> ENTREGUE | U33: OK | V33: MATERIAL PARA OBRA PEI CRISTIANE CHAVES, FATURAR PARA A B&B
A34: 45874 | B34: JOSE DE ALMEIDA PINHEIRO | C34: =VLOOKUP(LANÇAMENTO[[#This Row],[OBRA]],OBRAS[],2,FALSE) -> B&B | D34: HIDRAULICA | E34: CENSI TUBO EXTENS.CROMADO 7154 | F34: 1 | G34: UNID. | H34: 1775 | I34: CASA MIMOSA | J34: CENSI TUBO EXTENS.CROMADO 7154 | K34: 28.13 | L34: =LANÇAMENTO[[#This Row],[VALOR UNITARIO]]*LANÇAMENTO[[#This Row],[QTDADE]] -> 28.13 | M34: 45874 | N34: =TEXT(LANÇAMENTO[[#This Row],[DATA PEDIDO]],"MMM")&"-"&TEXT(M34,"AAAA") -> ago-2025 | O34: 28 | P34: BOLETO | Q34: RETIRA | R34: 1 | S34: =IF(LANÇAMENTO[[#This Row],[DATA PEDIDO]]="","",LANÇAMENTO[[#This Row],[DATA PEDIDO]]+LANÇAMENTO[[#This Row],[PRAZO]]) -> 45875 | T34: =IF(LANÇAMENTO[[#This Row],[OBRA COM MATERIAL]]="OK","ENTREGUE",IF(LANÇAMENTO[[#This Row],[PRAZO]]="","",LANÇAMENTO[[#This Row],[PREVISÃO ENTREGA OBRA]]-$E$1)) -> ENTREGUE | U34: OK | V34: MATERIAL PARA OBRA PEI CRISTIANE CHAVES, FATURAR PARA A B&B
A35: 45874 | B35: JOSE DE ALMEIDA PINHEIRO | C35: =VLOOKUP(LANÇAMENTO[[#This Row],[OBRA]],OBRAS[],2,FALSE) -> B&B | D35: HIDRAULICA | E35: TORALF PARAFUSO B-10 LAT. 75MM C/2 P/BACIA 1070 | F35: 1 | G35: UNID. | H35: 1775 | I35: CASA MIMOSA | J35: TORALF PARAFUSO B-10 LAT. 75MM C/2 P/BACIA 1070 | K35: 10.9 | L35: =LANÇAMENTO[[#This Row],[VALOR UNITARIO]]*LANÇAMENTO[[#This Row],[QTDADE]] -> 10.9 | M35: 45874 | N35: =TEXT(LANÇAMENTO[[#This Row],[DATA PEDIDO]],"MMM")&"-"&TEXT(M35,"AAAA") -> ago-2025 | O35: 28 | P35: BOLETO | Q35: RETIRA | R35: 1 | S35: =IF(LANÇAMENTO[[#This Row],[DATA PEDIDO]]="","",LANÇAMENTO[[#This Row],[DATA PEDIDO]]+LANÇAMENTO[[#This Row],[PRAZO]]) -> 45875 | T35: =IF(LANÇAMENTO[[#This Row],[OBRA COM MATERIAL]]="OK","ENTREGUE",IF(LANÇAMENTO[[#This Row],[PRAZO]]="","",LANÇAMENTO[[#This Row],[PREVISÃO ENTREGA OBRA]]-$E$1)) -> ENTREGUE | U35: OK | V35: MATERIAL PARA OBRA PEI CRISTIANE CHAVES, FATURAR PARA A B&B
A36: 45874 | B36: JOSE DE ALMEIDA PINHEIRO | C36: =VLOOKUP(LANÇAMENTO[[#This Row],[OBRA]],OBRAS[],2,FALSE) -> B&B | D36: HIDRAULICA | E36: TORALF PARAFUSO B-12 LAT. 90MM C/2 P/TANQUE | F36: 1 | G36: UNID. | H36: 1775 | I36: CASA MIMOSA | J36: TORALF PARAFUSO B-12 LAT. 90MM C/2 P/TANQUE | K36: 15.31 | L36: =LANÇAMENTO[[#This Row],[VALOR UNITARIO]]*LANÇAMENTO[[#This Row],[QTDADE]] -> 15.31 | M36: 45874 | N36: =TEXT(LANÇAMENTO[[#This Row],[DATA PEDIDO]],"MMM")&"-"&TEXT(M36,"AAAA") -> ago-2025 | O36: 28 | P36: BOLETO | Q36: RETIRA | R36: 1 | S36: =IF(LANÇAMENTO[[#This Row],[DATA PEDIDO]]="","",LANÇAMENTO[[#This Row],[DATA PEDIDO]]+LANÇAMENTO[[#This Row],[PRAZO]]) -> 45875 | T36: =IF(LANÇAMENTO[[#This Row],[OBRA COM MATERIAL]]="OK","ENTREGUE",IF(LANÇAMENTO[[#This Row],[PRAZO]]="","",LANÇAMENTO[[#This Row],[PREVISÃO ENTREGA OBRA]]-$E$1)) -> ENTREGUE | U36: OK | V36: MATERIAL PARA OBRA PEI CRISTIANE CHAVES, FATURAR PARA A B&B
A37: 45874 | B37: JOSE DE ALMEIDA PINHEIRO | C37: =VLOOKUP(LANÇAMENTO[[#This Row],[OBRA]],OBRAS[],2,FALSE) -> B&B | D37: HIDRAULICA | E37: TUPAN ASS.UNIV PP PREMIUM CONV BR | F37: 1 | G37: UNID. | H37: 1775 | I37: CASA MIMOSA | J37: TUPAN ASS.UNIV PP PREMIUM CONV BR | K37: 34.33 | L37: =LANÇAMENTO[[#This Row],[VALOR UNITARIO]]*LANÇAMENTO[[#This Row],[QTDADE]] -> 34.33 | M37: 45874 | N37: =TEXT(LANÇAMENTO[[#This Row],[DATA PEDIDO]],"MMM")&"-"&TEXT(M37,"AAAA") -> ago-2025 | O37: 28 | P37: BOLETO | Q37: RETIRA | R37: 1 | S37: =IF(LANÇAMENTO[[#This Row],[DATA PEDIDO]]="","",LANÇAMENTO[[#This Row],[DATA PEDIDO]]+LANÇAMENTO[[#This Row],[PRAZO]]) -> 45875 | T37: =IF(LANÇAMENTO[[#This Row],[OBRA COM MATERIAL]]="OK","ENTREGUE",IF(LANÇAMENTO[[#This Row],[PRAZO]]="","",LANÇAMENTO[[#This Row],[PREVISÃO ENTREGA OBRA]]-$E$1)) -> ENTREGUE | U37: OK | V37: MATERIAL PARA OBRA PEI CRISTIANE CHAVES, FATURAR PARA A B&B
A38: 45874 | B38: JOSE DE ALMEIDA PINHEIRO | C38: =VLOOKUP(LANÇAMENTO[[#This Row],[OBRA]],OBRAS[],2,FALSE) -> B&B | D38: HIDRAULICA | E38: DECA CANOPLA VALV.HYDRA MAX C | F38: 1 | G38: UNID. | H38: 1775 | I38: CASA MIMOSA | J38: DECA CANOPLA VALV.HYDRA MAX C | K38: 122.26 | L38: =LANÇAMENTO[[#This Row],[VALOR UNITARIO]]*LANÇAMENTO[[#This Row],[QTDADE]] -> 122.26 | M38: 45874 | N38: =TEXT(LANÇAMENTO[[#This Row],[DATA PEDIDO]],"MMM")&"-"&TEXT(M38,"AAAA") -> ago-2025 | O38: 28 | P38: BOLETO | Q38: RETIRA | R38: 1 | S38: =IF(LANÇAMENTO[[#This Row],[DATA PEDIDO]]="","",LANÇAMENTO[[#This Row],[DATA PEDIDO]]+LANÇAMENTO[[#This Row],[PRAZO]]) -> 45875 | T38: =IF(LANÇAMENTO[[#This Row],[OBRA COM MATERIAL]]="OK","ENTREGUE",IF(LANÇAMENTO[[#This Row],[PRAZO]]="","",LANÇAMENTO[[#This Row],[PREVISÃO ENTREGA OBRA]]-$E$1)) -> ENTREGUE | U38: OK | V38: MATERIAL PARA OBRA PEI CRISTIANE CHAVES, FATURAR PARA A B&B
A39: 45874 | B39: JOSE DE ALMEIDA PINHEIRO | C39: =VLOOKUP(LANÇAMENTO[[#This Row],[OBRA]],OBRAS[],2,FALSE) -> B&B | D39: HIDRAULICA | E39: CEMIX ACABAMENTO C50 3/4 F | F39: 1 | G39: UNID. | H39: 1775 | I39: CASA MIMOSA | J39: CEMIX ACABAMENTO C50 3/4 F | K39: 13.81 | L39: =LANÇAMENTO[[#This Row],[VALOR UNITARIO]]*LANÇAMENTO[[#This Row],[QTDADE]] -> 13.81 | M39: 45874 | N39: =TEXT(LANÇAMENTO[[#This Row],[DATA PEDIDO]],"MMM")&"-"&TEXT(M39,"AAAA") -> ago-2025 | O39: 28 | P39: BOLETO | Q39: RETIRA | R39: 1 | S39: =IF(LANÇAMENTO[[#This Row],[DATA PEDIDO]]="","",LANÇAMENTO[[#This Row],[DATA PEDIDO]]+LANÇAMENTO[[#This Row],[PRAZO]]) -> 45875 | T39: =IF(LANÇAMENTO[[#This Row],[OBRA COM MATERIAL]]="OK","ENTREGUE",IF(LANÇAMENTO[[#This Row],[PRAZO]]="","",LANÇAMENTO[[#This Row],[PREVISÃO ENTREGA OBRA]]-$E$1)) -> ENTREGUE | U39: OK | V39: MATERIAL PARA OBRA PEI CRISTIANE CHAVES, FATURAR PARA A B&B
A40: 45874 | B40: JOSE DE ALMEIDA PINHEIRO | C40: =VLOOKUP(LANÇAMENTO[[#This Row],[OBRA]],OBRAS[],2,FALSE) -> B&B | D40: HIDRAULICA | E40: CEMIX ACABAMENTO C50 1.1/2 | F40: 1 | G40: UNID. | H40: 1775 | I40: CASA MIMOSA | J40: CEMIX ACABAMENTO C50 1.1/2 | K40: 15.34 | L40: =LANÇAMENTO[[#This Row],[VALOR UNITARIO]]*LANÇAMENTO[[#This Row],[QTDADE]] -> 15.34 | M40: 45874 | N40: =TEXT(LANÇAMENTO[[#This Row],[DATA PEDIDO]],"MMM")&"-"&TEXT(M40,"AAAA") -> ago-2025 | O40: 28 | P40: BOLETO | Q40: RETIRA | R40: 1 | S40: =IF(LANÇAMENTO[[#This Row],[DATA PEDIDO]]="","",LANÇAMENTO[[#This Row],[DATA PEDIDO]]+LANÇAMENTO[[#This Row],[PRAZO]]) -> 45875 | T40: =IF(LANÇAMENTO[[#This Row],[OBRA COM MATERIAL]]="OK","ENTREGUE",IF(LANÇAMENTO[[#This Row],[PRAZO]]="","",LANÇAMENTO[[#This Row],[PREVISÃO ENTREGA OBRA]]-$E$1)) -> ENTREGUE | U40: OK | V40: MATERIAL PARA OBRA PEI CRISTIANE CHAVES, FATURAR PARA A B&B
A41: 45874 | B41: JOSE DE ALMEIDA PINHEIRO | C41: =VLOOKUP(LANÇAMENTO[[#This Row],[OBRA]],OBRAS[],2,FALSE) -> B&B | D41: HIDRAULICA | E41: EMMETI DUCHA HIG.ECO.1/2 GAT.ABS BR RG.MET. | F41: 1 | G41: UNID. | H41: 1775 | I41: CASA MIMOSA | J41: EMMETI DUCHA HIG.ECO.1/2 GAT.ABS BR RG.MET. | K41: 66.73 | L41: =LANÇAMENTO[[#This Row],[VALOR UNITARIO]]*LANÇAMENTO[[#This Row],[QTDADE]] -> 66.73 | M41: 45874 | N41: =TEXT(LANÇAMENTO[[#This Row],[DATA PEDIDO]],"MMM")&"-"&TEXT(M41,"AAAA") -> ago-2025 | O41: 28 | P41: BOLETO | Q41: RETIRA | R41: 1 | S41: =IF(LANÇAMENTO[[#This Row],[DATA PEDIDO]]="","",LANÇAMENTO[[#This Row],[DATA PEDIDO]]+LANÇAMENTO[[#This Row],[PRAZO]]) -> 45875 | T41: =IF(LANÇAMENTO[[#This Row],[OBRA COM MATERIAL]]="OK","ENTREGUE",IF(LANÇAMENTO[[#This Row],[PRAZO]]="","",LANÇAMENTO[[#This Row],[PREVISÃO ENTREGA OBRA]]-$E$1)) -> ENTREGUE | U41: OK | V41: MATERIAL PARA OBRA PEI CRISTIANE CHAVES, FATURAR PARA A B&B
A42: 45874 | B42: JOSE DE ALMEIDA PINHEIRO | C42: =VLOOKUP(LANÇAMENTO[[#This Row],[OBRA]],OBRAS[],2,FALSE) -> B&B | D42: HIDRAULICA | E42: EMMETI FLEX.1/2X60CM MF C/CANOPLA H0524600 | F42: 1 | G42: UNID. | H42: 1775 | I42: CASA MIMOSA | J42: EMMETI FLEX.1/2X60CM MF C/CANOPLA H0524600 | K42: 20.69 | L42: =LANÇAMENTO[[#This Row],[VALOR UNITARIO]]*LANÇAMENTO[[#This Row],[QTDADE]] -> 20.69 | M42: 45874 | N42: =TEXT(LANÇAMENTO[[#This Row],[DATA PEDIDO]],"MMM")&"-"&TEXT(M42,"AAAA") -> ago-2025 | O42: 28 | P42: BOLETO | Q42: RETIRA | R42: 1 | S42: =IF(LANÇAMENTO[[#This Row],[DATA PEDIDO]]="","",LANÇAMENTO[[#This Row],[DATA PEDIDO]]+LANÇAMENTO[[#This Row],[PRAZO]]) -> 45875 | T42: =IF(LANÇAMENTO[[#This Row],[OBRA COM MATERIAL]]="OK","ENTREGUE",IF(LANÇAMENTO[[#This Row],[PRAZO]]="","",LANÇAMENTO[[#This Row],[PREVISÃO ENTREGA OBRA]]-$E$1)) -> ENTREGUE | U42: OK | V42: MATERIAL PARA OBRA PEI CRISTIANE CHAVES, FATURAR PARA A B&B
A43: 45874 | B43: LEA APARECIDA | C43: =VLOOKUP(LANÇAMENTO[[#This Row],[OBRA]],OBRAS[],2,FALSE) -> INTERIORANA | D43: OUTROS | E43: TELA POP | F43: 44 | G43: UNID. | H43: 1776 | I43: RISATEC | J43: TELA SOLDADA TOP PA Q45 2X3 M LEVE CD | K43: 30.99 | L43: =LANÇAMENTO[[#This Row],[VALOR UNITARIO]]*LANÇAMENTO[[#This Row],[QTDADE]] -> 1363.56 | M43: 45874 | N43: =TEXT(LANÇAMENTO[[#This Row],[DATA PEDIDO]],"MMM")&"-"&TEXT(M43,"AAAA") -> ago-2025 | O43: 28 | P43: BOLETO | Q43: RETIRA | R43: 2 | S43: =IF(LANÇAMENTO[[#This Row],[DATA PEDIDO]]="","",LANÇAMENTO[[#This Row],[DATA PEDIDO]]+LANÇAMENTO[[#This Row],[PRAZO]]) -> 45876 | T43: =IF(LANÇAMENTO[[#This Row],[OBRA COM MATERIAL]]="OK","ENTREGUE",IF(LANÇAMENTO[[#This Row],[PRAZO]]="","",LANÇAMENTO[[#This Row],[PREVISÃO ENTREGA OBRA]]-$E$1)) -> ENTREGUE | U43: OK
A44: 45874 | B44: ERICO VERISSIMO | C44: =VLOOKUP(LANÇAMENTO[[#This Row],[OBRA]],OBRAS[],2,FALSE) -> INTERIORANA | D44: PINTURA | E44: ADERE FITA CREPE 24X50M | F44: 25 | G44: PACOTE | H44: 1777 | I44: OLD RIVER | J44: ADERE FITA CREPE 24X50M | K44: 5.99 | L44: =LANÇAMENTO[[#This Row],[VALOR UNITARIO]]*LANÇAMENTO[[#This Row],[QTDADE]] -> 149.75 | M44: 45874 | N44: =TEXT(LANÇAMENTO[[#This Row],[DATA PEDIDO]],"MMM")&"-"&TEXT(M44,"AAAA") -> ago-2025 | O44: 28/56/84 | P44: BOLETO | Q44: ENTREGA | R44: 1 | S44: =IF(LANÇAMENTO[[#This Row],[DATA PEDIDO]]="","",LANÇAMENTO[[#This Row],[DATA PEDIDO]]+LANÇAMENTO[[#This Row],[PRAZO]]) -> 45875 | T44: =IF(LANÇAMENTO[[#This Row],[OBRA COM MATERIAL]]="OK","ENTREGUE",IF(LANÇAMENTO[[#This Row],[PRAZO]]="","",LANÇAMENTO[[#This Row],[PREVISÃO ENTREGA OBRA]]-$E$1)) -> ENTREGUE | U44: OK
A45: 45874 | B45: ERICO VERISSIMO | C45: =VLOOKUP(LANÇAMENTO[[#This Row],[OBRA]],OBRAS[],2,FALSE) -> INTERIORANA | D45: PINTURA | E45: COMPEL 1423 ROLO DE LA RESPINGO ZERO ECONOMICO 23CM | F45: 6 | G45: PACOTE | H45: 1777 | I45: OLD RIVER | J45: COMPEL 1423 ROLO DE LA RESPINGO ZERO ECONOMICO 23CM | K45: 8.99 | L45: =LANÇAMENTO[[#This Row],[VALOR UNITARIO]]*LANÇAMENTO[[#This Row],[QTDADE]] -> 53.94 | M45: 45874 | N45: =TEXT(LANÇAMENTO[[#This Row],[DATA PEDIDO]],"MMM")&"-"&TEXT(M45,"AAAA") -> ago-2025 | O45: 28/56/84 | P45: BOLETO | Q45: ENTREGA | R45: 1 | S45: =IF(LANÇAMENTO[[#This Row],[DATA PEDIDO]]="","",LANÇAMENTO[[#This Row],[DATA PEDIDO]]+LANÇAMENTO[[#This Row],[PRAZO]]) -> 45875 | T45: =IF(LANÇAMENTO[[#This Row],[OBRA COM MATERIAL]]="OK","ENTREGUE",IF(LANÇAMENTO[[#This Row],[PRAZO]]="","",LANÇAMENTO[[#This Row],[PREVISÃO ENTREGA OBRA]]-$E$1)) -> ENTREGUE | U45: OK
A46: 45874 | B46: ERICO VERISSIMO | C46: =VLOOKUP(LANÇAMENTO[[#This Row],[OBRA]],OBRAS[],2,FALSE) -> INTERIORANA | D46: PINTURA | E46: COMPEL 2072 SUPORTE DE PRESSAO 23CM | F46: 6 | G46: PACOTE | H46: 1777 | I46: OLD RIVER | J46: COMPEL 2072 SUPORTE DE PRESSAO 23CM | K46: 4.99 | L46: =LANÇAMENTO[[#This Row],[VALOR UNITARIO]]*LANÇAMENTO[[#This Row],[QTDADE]] -> 29.94 | M46: 45874 | N46: =TEXT(LANÇAMENTO[[#This Row],[DATA PEDIDO]],"MMM")&"-"&TEXT(M46,"AAAA") -> ago-2025 | O46: 28/56/84 | P46: BOLETO | Q46: ENTREGA | R46: 1 | S46: =IF(LANÇAMENTO[[#This Row],[DATA PEDIDO]]="","",LANÇAMENTO[[#This Row],[DATA PEDIDO]]+LANÇAMENTO[[#This Row],[PRAZO]]) -> 45875 | T46: =IF(LANÇAMENTO[[#This Row],[OBRA COM MATERIAL]]="OK","ENTREGUE",IF(LANÇAMENTO[[#This Row],[PRAZO]]="","",LANÇAMENTO[[#This Row],[PREVISÃO ENTREGA OBRA]]-$E$1)) -> ENTREGUE | U46: OK
A47: 45874 | B47: ERICO VERISSIMO | C47: =VLOOKUP(LANÇAMENTO[[#This Row],[OBRA]],OBRAS[],2,FALSE) -> INTERIORANA | D47: PINTURA | E47: FUTURA PREMIUM TINTA PARA PISO AMARELO 3,6L | F47: 1 | G47: GALÃO | H47: 1777 | I47: OLD RIVER | J47: FUTURA PREMIUM TINTA PARA PISO AMARELO 3,6L | K47: 69.9 | L47: =LANÇAMENTO[[#This Row],[VALOR UNITARIO]]*LANÇAMENTO[[#This Row],[QTDADE]] -> 69.9 | M47: 45874 | N47: =TEXT(LANÇAMENTO[[#This Row],[DATA PEDIDO]],"MMM")&"-"&TEXT(M47,"AAAA") -> ago-2025 | O47: 28/56/84 | P47: BOLETO | Q47: ENTREGA | R47: 1 | S47: =IF(LANÇAMENTO[[#This Row],[DATA PEDIDO]]="","",LANÇAMENTO[[#This Row],[DATA PEDIDO]]+LANÇAMENTO[[#This Row],[PRAZO]]) -> 45875 | T47: =IF(LANÇAMENTO[[#This Row],[OBRA COM MATERIAL]]="OK","ENTREGUE",IF(LANÇAMENTO[[#This Row],[PRAZO]]="","",LANÇAMENTO[[#This Row],[PREVISÃO ENTREGA OBRA]]-$E$1)) -> ENTREGUE | U47: OK
A48: 45874 | B48: ERICO VERISSIMO | C48: =VLOOKUP(LANÇAMENTO[[#This Row],[OBRA]],OBRAS[],2,FALSE) -> INTERIORANA | D48: PINTURA | E48: FUTURA PREMIUM TINTA PARA PISO AZUL 18L | F48: 6 | G48: LATA | H48: 1777 | I48: OLD RIVER | J48: FUTURA PREMIUM TINTA PARA PISO AZUL 18L | K48: 249.9 | L48: =LANÇAMENTO[[#This Row],[VALOR UNITARIO]]*LANÇAMENTO[[#This Row],[QTDADE]] -> 1499.4 | M48: 45874 | N48: =TEXT(LANÇAMENTO[[#This Row],[DATA PEDIDO]],"MMM")&"-"&TEXT(M48,"AAAA") -> ago-2025 | O48: 28/56/84 | P48: BOLETO | Q48: ENTREGA | R48: 1 | S48: =IF(LANÇAMENTO[[#This Row],[DATA PEDIDO]]="","",LANÇAMENTO[[#This Row],[DATA PEDIDO]]+LANÇAMENTO[[#This Row],[PRAZO]]) -> 45875 | T48: =IF(LANÇAMENTO[[#This Row],[OBRA COM MATERIAL]]="OK","ENTREGUE",IF(LANÇAMENTO[[#This Row],[PRAZO]]="","",LANÇAMENTO[[#This Row],[PREVISÃO ENTREGA OBRA]]-$E$1)) -> ENTREGUE | U48: OK
A49: 45874 | B49: ERICO VERISSIMO | C49: =VLOOKUP(LANÇAMENTO[[#This Row],[OBRA]],OBRAS[],2,FALSE) -> INTERIORANA | D49: PINTURA | E49: FUTURA PREMIUM TINTA PARA PISO BRANCO 3,6L | F49: 1 | G49: GALÃO | H49: 1777 | I49: OLD RIVER | J49: FUTURA PREMIUM TINTA PARA PISO BRANCO 3,6L | K49: 69.9 | L49: =LANÇAMENTO[[#This Row],[VALOR UNITARIO]]*LANÇAMENTO[[#This Row],[QTDADE]] -> 69.9 | M49: 45874 | N49: =TEXT(LANÇAMENTO[[#This Row],[DATA PEDIDO]],"MMM")&"-"&TEXT(M49,"AAAA") -> ago-2025 | O49: 28/56/84 | P49: BOLETO | Q49: ENTREGA | R49: 1 | S49: =IF(LANÇAMENTO[[#This Row],[DATA PEDIDO]]="","",LANÇAMENTO[[#This Row],[DATA PEDIDO]]+LANÇAMENTO[[#This Row],[PRAZO]]) -> 45875 | T49: =IF(LANÇAMENTO[[#This Row],[OBRA COM MATERIAL]]="OK","ENTREGUE",IF(LANÇAMENTO[[#This Row],[PRAZO]]="","",LANÇAMENTO[[#This Row],[PREVISÃO ENTREGA OBRA]]-$E$1)) -> ENTREGUE | U49: OK
A50: 45874 | B50: ERICO VERISSIMO | C50: =VLOOKUP(LANÇAMENTO[[#This Row],[OBRA]],OBRAS[],2,FALSE) -> INTERIORANA | D50: PINTURA | E50: FUTURA PREMIUM TINTA PARA PISO VERDE 3,6L | F50: 1 | G50: GALÃO | H50: 1777 | I50: OLD RIVER | J50: FUTURA PREMIUM TINTA PARA PISO VERDE 3,6L | K50: 69.9 | L50: =LANÇAMENTO[[#This Row],[VALOR UNITARIO]]*LANÇAMENTO[[#This Row],[QTDADE]] -> 69.9 | M50: 45874 | N50: =TEXT(LANÇAMENTO[[#This Row],[DATA PEDIDO]],"MMM")&"-"&TEXT(M50,"AAAA") -> ago-2025 | O50: 28/56/84 | P50: BOLETO | Q50: ENTREGA | R50: 1 | S50: =IF(LANÇAMENTO[[#This Row],[DATA PEDIDO]]="","",LANÇAMENTO[[#This Row],[DATA PEDIDO]]+LANÇAMENTO[[#This Row],[PRAZO]]) -> 45875 | T50: =IF(LANÇAMENTO[[#This Row],[OBRA COM MATERIAL]]="OK","ENTREGUE",IF(LANÇAMENTO[[#This Row],[PRAZO]]="","",LANÇAMENTO[[#This Row],[PREVISÃO ENTREGA OBRA]]-$E$1)) -> ENTREGUE | U50: OK
A51: 45874 | B51: ERICO VERISSIMO | C51: =VLOOKUP(LANÇAMENTO[[#This Row],[OBRA]],OBRAS[],2,FALSE) -> INTERIORANA | D51: PINTURA | E51: FUTURA PREMIUM TINTA PARA PISO VERMELHO SEGURANÇA 18L | F51: 2 | G51: LATA | H51: 1777 | I51: OLD RIVER | J51: FUTURA PREMIUM TINTA PARA PISO VERMELHO SEGURANÇA 18L | K51: 249.9 | L51: =LANÇAMENTO[[#This Row],[VALOR UNITARIO]]*LANÇAMENTO[[#This Row],[QTDADE]] -> 499.8 | M51: 45874 | N51: =TEXT(LANÇAMENTO[[#This Row],[DATA PEDIDO]],"MMM")&"-"&TEXT(M51,"AAAA") -> ago-2025 | O51: 28/56/84 | P51: BOLETO | Q51: ENTREGA | R51: 1 | S51: =IF(LANÇAMENTO[[#This Row],[DATA PEDIDO]]="","",LANÇAMENTO[[#This Row],[DATA PEDIDO]]+LANÇAMENTO[[#This Row],[PRAZO]]) -> 45875 | T51: =IF(LANÇAMENTO[[#This Row],[OBRA COM MATERIAL]]="OK","ENTREGUE",IF(LANÇAMENTO[[#This Row],[PRAZO]]="","",LANÇAMENTO[[#This Row],[PREVISÃO ENTREGA OBRA]]-$E$1)) -> ENTREGUE | U51: OK
A52: 45874 | B52: ERICO VERISSIMO | C52: =VLOOKUP(LANÇAMENTO[[#This Row],[OBRA]],OBRAS[],2,FALSE) -> INTERIORANA | D52: PINTURA | E52: ROMA 301/005 TRINCHA CABO PRETO/CERDA GRIS 301 2" | F52: 6 | G52: PACOTE | H52: 1777 | I52: OLD RIVER | J52: ROMA 301/005 TRINCHA CABO PRETO/CERDA GRIS 301 2" | K52: 4.99 | L52: =LANÇAMENTO[[#This Row],[VALOR UNITARIO]]*LANÇAMENTO[[#This Row],[QTDADE]] -> 29.94 | M52: 45874 | N52: =TEXT(LANÇAMENTO[[#This Row],[DATA PEDIDO]],"MMM")&"-"&TEXT(M52,"AAAA") -> ago-2025 | O52: 28/56/84 | P52: BOLETO | Q52: ENTREGA | R52: 1 | S52: =IF(LANÇAMENTO[[#This Row],[DATA PEDIDO]]="","",LANÇAMENTO[[#This Row],[DATA PEDIDO]]+LANÇAMENTO[[#This Row],[PRAZO]]) -> 45875 | T52: =IF(LANÇAMENTO[[#This Row],[OBRA COM MATERIAL]]="OK","ENTREGUE",IF(LANÇAMENTO[[#This Row],[PRAZO]]="","",LANÇAMENTO[[#This Row],[PREVISÃO ENTREGA OBRA]]-$E$1)) -> ENTREGUE | U52: OK
A53: 45874 | B53: ERICO VERISSIMO | C53: =VLOOKUP(LANÇAMENTO[[#This Row],[OBRA]],OBRAS[],2,FALSE) -> INTERIORANA | D53: PINTURA | E53: RESINA ACRILICA EUCATEX 18 LTS | F53: 6 | G53: LATA | H53: 1778 | I53: DEPOSITO PADRÃO | J53: RESINA ACRILICA EUCATEX 18 LTS | K53: 450 | L53: =LANÇAMENTO[[#This Row],[VALOR UNITARIO]]*LANÇAMENTO[[#This Row],[QTDADE]] -> 2700 | M53: 45874 | N53: =TEXT(LANÇAMENTO[[#This Row],[DATA PEDIDO]],"MMM")&"-"&TEXT(M53,"AAAA") -> ago-2025 | O53: 28/35/42 | P53: BOLETO | Q53: ENTREGA | R53: 1 | S53: =IF(LANÇAMENTO[[#This Row],[DATA PEDIDO]]="","",LANÇAMENTO[[#This Row],[DATA PEDIDO]]+LANÇAMENTO[[#This Row],[PRAZO]]) -> 45875 | T53: =IF(LANÇAMENTO[[#This Row],[OBRA COM MATERIAL]]="OK","ENTREGUE",IF(LANÇAMENTO[[#This Row],[PRAZO]]="","",LANÇAMENTO[[#This Row],[PREVISÃO ENTREGA OBRA]]-$E$1)) -> ENTREGUE | U53: OK
A54: 45874 | B54: ERICO VERISSIMO | C54: =VLOOKUP(LANÇAMENTO[[#This Row],[OBRA]],OBRAS[],2,FALSE) -> INTERIORANA | D54: PINTURA | E54: FITA DUPLAFACE 3M FORTE TRANSP.19MMX2MT | F54: 1 | G54: UNID. | H54: 1778 | I54: DEPOSITO PADRÃO | J54: FITA DUPLAFACE 3M FORTE TRANSP.19MMX2MT | K54: 18.88 | L54: =LANÇAMENTO[[#This Row],[VALOR UNITARIO]]*LANÇAMENTO[[#This Row],[QTDADE]] -> 18.88 | M54: 45874 | N54: =TEXT(LANÇAMENTO[[#This Row],[DATA PEDIDO]],"MMM")&"-"&TEXT(M54,"AAAA") -> ago-2025 | O54: 28/35/42 | P54: BOLETO | Q54: ENTREGA | R54: 1 | S54: =IF(LANÇAMENTO[[#This Row],[DATA PEDIDO]]="","",LANÇAMENTO[[#This Row],[DATA PEDIDO]]+LANÇAMENTO[[#This Row],[PRAZO]]) -> 45875 | T54: =IF(LANÇAMENTO[[#This Row],[OBRA COM MATERIAL]]="OK","ENTREGUE",IF(LANÇAMENTO[[#This Row],[PRAZO]]="","",LANÇAMENTO[[#This Row],[PREVISÃO ENTREGA OBRA]]-$E$1)) -> ENTREGUE | U54: OK
... A87: 45875 | B87: SYLVIA DE MELLO | C87: =VLOOKUP(LANÇAMENTO[[#This Row],[OBRA]],OBRAS[],2,FALSE) -> B&B | D87: OUTROS | E87: CAMARA P PNEU CARRINHO | F87: 2 | G87: UNID. | H87: 1784 | I87: DEPOSITO PADRÃO | J87: CAMARA P/CARRI.PEDR 3,25X8 MOLDADA FERTAK | K87: 18.29 | L87: =LANÇAMENTO[[#This Row],[VALOR UNITARIO]]*LANÇAMENTO[[#This Row],[QTDADE]] -> 36.58 | M87: 45875 | N87: =TEXT(LANÇAMENTO[[#This Row],[DATA PEDIDO]],"MMM")&"-"&TEXT(M87,"AAAA") -> ago-2025 | O87: 14 | P87: BOLETO | Q87: RETIRA | R87: 0 | S87: =IF(LANÇAMENTO[[#This Row],[DATA PEDIDO]]="","",LANÇAMENTO[[#This Row],[DATA PEDIDO]]+LANÇAMENTO[[#This Row],[PRAZO]]) -> 45875 | T87: =IF(LANÇAMENTO[[#This Row],[OBRA COM MATERIAL]]="OK","ENTREGUE",IF(LANÇAMENTO[[#This Row],[PRAZO]]="","",LANÇAMENTO[[#This Row],[PREVISÃO ENTREGA OBRA]]-$E$1)) -> ENTREGUE | U87: OK
A88: 45875 | B88: JOSE DE ALMEIDA PINHEIRO | C88: =VLOOKUP(LANÇAMENTO[[#This Row],[OBRA]],OBRAS[],2,FALSE) -> B&B | D88: OUTROS | E88: TB RD 50,80 X 1,55 MM (2") GALV | F88: 2 | G88: BARRA | H88: 1785 | I88: IMPERIO AÇO | J88: TB RD 50,80 X 1,55 MM (2") GALV | K88: 105 | L88: =LANÇAMENTO[[#This Row],[VALOR UNITARIO]]*LANÇAMENTO[[#This Row],[QTDADE]] -> 210 | M88: 45875 | N88: =TEXT(LANÇAMENTO[[#This Row],[DATA PEDIDO]],"MMM")&"-"&TEXT(M88,"AAAA") -> ago-2025 | O88: 30/45 | P88: BOLETO | Q88: RETIRA | R88: 0 | S88: =IF(LANÇAMENTO[[#This Row],[DATA PEDIDO]]="","",LANÇAMENTO[[#This Row],[DATA PEDIDO]]+LANÇAMENTO[[#This Row],[PRAZO]]) -> 45875 | T88: =IF(LANÇAMENTO[[#This Row],[OBRA COM MATERIAL]]="OK","ENTREGUE",IF(LANÇAMENTO[[#This Row],[PRAZO]]="","",LANÇAMENTO[[#This Row],[PREVISÃO ENTREGA OBRA]]-$E$1)) -> ENTREGUE | U88: OK | V88: MATERIAL PARA OBRA EE ANDRE FRANCO MONTORO
...

Sheet Planilha1

Sheet Planilha2

Sheet Planilha3

Sheet PEDIDOS EMITIDOS
A1: DATA PEDIDO | B1: 46128
E2: COMPRADOR: | F2: IURY
A3: PEDIDO | B3: FORNECEDOR | C3: OBRA | D3: CONDIÇÃO PAGAMENTO | E3: FORMA DE PAGAMENTO | F3: Soma de VALOR TOTAL
A4: 2570 | B4: LEROY MERLIN | C4: ANTONIO NUNES LOPES | D4: 0 | E4: PIX | F4: 97.68
A5: 2571 | B5: RENNOVA LOCAÇÕES | C5: MARIA RITA ARAÚJO | D5: 28 | E5: BOLETO | F5: 390
A6: Total Geral | F6: 487.68

Sheet BASE PEDIDO
A1: PEDIDO | B1: 2575
A3: DATA PEDIDO | B3: PRAZO | C3: RETIRA OU ENTREGA | D3: ESCOLA | E3: FORNECEDOR | F3: CONDIÇÃO PAGAMENTO | G3: FORMA DE PAGAMENTO | H3: DESCRIÇÃO MATERIAL | I3: UNID | J3: QTDADE | K3: VALOR UNITARIO | L3: FATURAMENTO | M3: Soma de VALOR TOTAL
A4: 46129 | B4: 5 | C4: ENTREGA | D4: ELIAS MASSUD | E4: TELHA NORTE | F4: 28/56/84/112 | G4: BOLETO | H4: REJ CERAMIC CINZA PLATINA5KG QUARTZOLIT | I4: SACO | J4: 20 | K4: 49.41 | L4: INTERIORANA | M4: 988.2
A5: 46129 | B5: 5 | C5: ENTREGA | D5: ELIAS MASSUD | E5: TELHA NORTE | F5: 28/56/84/112 | G5: BOLETO | H5: ARG PORCEL INT CZ 20KGQUARTZOLIT | I5: SACO | J5: 120 | K5: 21.51 | L5: INTERIORANA | M5: 2581.2
A6: 46129 | B6: 5 | C6: ENTREGA | D6: ELIAS MASSUD | E6: TELHA NORTE | F6: 28/56/84/112 | G6: BOLETO | H6: PORC MUNARI BRANCO AC60X60 RET | I6: M2 | J6: 300.6 | K6: 79.03 | L6: INTERIORANA | M6: 23756.418
A7: 46129 | B7: 5 | C7: ENTREGA | D7: ELIAS MASSUD | E7: TELHA NORTE | F7: 28/56/84/112 | G7: BOLETO | H7: DESCONTO TOTAL | I7: VERBA | J7: 1 | K7: -131.79 | L7: INTERIORANA | M7: -131.79

Sheet JB IMPRIMIR
M1: JB CONSTRUÇÕES E EMPREENDIMENTOS LTDA
M2: Av luis dummount vilares 2078, São Paulo, Brazil 02239-000
M3: Telefone: (11) 3313-8220
M4: e-mail: compras2@brasulconstrutora.com.br
C6: DATA: | D6: ='BASE PEDIDO'!A4 -> 46129 | H6: PEDIDO DE COMPRA | K6: Nº | L6: ='BASE PEDIDO'!B1 -> 2575
L7: ='BASE PEDIDO'!D4 -> ELIAS MASSUD
B9: Razão Social: | E9: =VLOOKUP(E10,FORNECEDOR[#All],2,FALSE) -> SAINT-GOBAIN DISTRIBUIÇÃO BRASUL LTDA
B10: Fornecedor: | E10: ='BASE PEDIDO'!E4 -> TELHA NORTE | J10: Vendedor: | K10: =VLOOKUP(E10,FORNECEDOR[#All],4,FALSE) -> Augusto
B11: E-mail: | E11: =VLOOKUP(E10,FORNECEDOR[#All],3,FALSE) -> augusto.endes@saint-gobain.com | J11: Telefone: | K11: =VLOOKUP(E10,FORNECEDOR[#All],5,FALSE) -> 11 9.8510-6170
B13: Endereço de Cobrança: Rua Coronel Jordão, 440 /450 | I13: Bairro: Vila Paiva | L13: CEP: 02075-030
B14: Cidade: São Paulo | I14: UF: SP | L14: Comprador: IURY
B16: Faturamento: | E16: =MID(B17,1,2) -> 28 | F16: =IF(E16="","","dias") -> dias | G16: ='BASE PEDIDO'!G4 -> BOLETO | H16: =IF(G16="PIX",VLOOKUP(E10,FORNECEDOR[#All],6,FALSE),"") | K16: Estimativa de vencimento: | L16: =$L$22+E16 -> 46162
B17: ='BASE PEDIDO'!F4 -> 28/56/84/112 | E17: =MID(B17,4,2) -> 56 | F17: =IF(E17="","","dias") -> dias | H17: =IF(G16="PIX",VLOOKUP(E10,FORNECEDOR[#All],7,FALSE),"") | L17: =$L$22+E17 -> 46190
B18: {=_xlfn.TEXTSPLIT(C17," ")} -> #VALUE! | C18: OBS: CONTAR FATURAMENTO A PARTIR DO DIA 27/12/24 PARA MANTER OS FATURAMENTOS ANTERIORES DA JB | E18: =MID(B17,7,2) -> 84 | F18: =IF(E18="","","dias") -> dias | L18: =$L$22+E18 -> 46218
E19: =MID(B17,10,3) -> 112 | F19: =IF(E19="","","dias") -> dias | L19: =IF(E19=""," ",$D$6+E19) -> 46241
B20: OBSERVAÇÃO: | E20: NOTA FISCAL DEVE SER FATURADA EM NOME DA EMPRESA | I20: =IF('BASE PEDIDO'!L4="JB","JB CONSTRUÇÕES E EMPREENDIMENTOS LTDA",IF('BASE PEDIDO'!L4="JB CONSTRUÇÕES E EMPREENDIMENTOS LTDA","JB CONSTRUÇÕES E EMPREENDIMENTOS LTDA","JB CONSTRUÇÕES E EMPREENDIMENTOS LTDA")) -> JB CONSTRUÇÕES E EMPREENDIMENTOS LTDA
B22: PRAZO | D22: ='BASE PEDIDO'!C4 -> ENTREGA | F22: ='BASE PEDIDO'!B4 -> 5 | G22: dias | K22: ="DATA PREVISTA DA "&'BASE PEDIDO'!C4 -> DATA PREVISTA DA ENTREGA | L22: =F22+D6 -> 46134
B24: Local de Entrega: | E24: =VLOOKUP(L7,OBRAS[#All],4,FALSE) -> Rua Prof Fauze Calil 30 | H24: Bairro: | I24: =VLOOKUP(L7,OBRAS[#All],5,FALSE) -> Centro
B25: OBRA: | D25: =VLOOKUP(L7,OBRAS[#All],3,FALSE) -> E.E Dr Elias Massud | H25: Contrato Obra: | I25: =VLOOKUP(L7,OBRAS[#All],7,FALSE) -> 0
B26: CEP: | D26: =VLOOKUP(L7,OBRAS[#All],6,FALSE) -> 13190-000 | H26: Cidade: | I26: =VLOOKUP(L7,OBRAS[#All],8,FALSE) -> Monte Mor | K26: UF: | L26: =VLOOKUP(L7,OBRAS[#All],9,FALSE) -> SP
C29: ITEM | D29: DESCRIÇÃO | I29: QTDADE | J29: UNID. | K29: VALOR UNITÁRIO | L29: VALOR TOTAL
C31: 1 | D31: ='BASE PEDIDO'!H4 -> REJ CERAMIC CINZA PLATINA5KG QUARTZOLIT | I31: ='BASE PEDIDO'!J4 -> 20 | J31: ='BASE PEDIDO'!I4 -> SACO | K31: ='BASE PEDIDO'!K4 -> 49.41 | L31: =I31*K31 -> 988.2
C32: 2 | D32: ='BASE PEDIDO'!H5 -> ARG PORCEL INT CZ 20KGQUARTZOLIT | I32: ='BASE PEDIDO'!J5 -> 120 | J32: ='BASE PEDIDO'!I5 -> SACO | K32: ='BASE PEDIDO'!K5 -> 21.51 | L32: =I32*K32 -> 2581.2
C33: 3 | D33: ='BASE PEDIDO'!H6 -> PORC MUNARI BRANCO AC60X60 RET | I33: ='BASE PEDIDO'!J6 -> 300.6 | J33: ='BASE PEDIDO'!I6 -> M2 | K33: ='BASE PEDIDO'!K6 -> 79.03 | L33: =I33*K33 -> 23756.418
C34: 4 | D34: ='BASE PEDIDO'!H7 -> DESCONTO TOTAL | I34: ='BASE PEDIDO'!J7 -> 1 | J34: ='BASE PEDIDO'!I7 -> VERBA | K34: ='BASE PEDIDO'!K7 -> -131.79 | L34: =I34*K34 -> -131.79
C35: 5 | D35: ='BASE PEDIDO'!H8 -> 0 | I35: ='BASE PEDIDO'!J8 -> 0 | J35: ='BASE PEDIDO'!I8 -> 0 | K35: ='BASE PEDIDO'!K8 -> 0 | L35: =I35*K35 -> 0
C36: 6 | D36: ='BASE PEDIDO'!H9 -> 0 | I36: ='BASE PEDIDO'!J9 -> 0 | J36: ='BASE PEDIDO'!I9 -> 0 | K36: ='BASE PEDIDO'!K9 -> 0 | L36: =I36*K36 -> 0
C37: 7 | D37: ='BASE PEDIDO'!H10 -> 0 | I37: ='BASE PEDIDO'!J10 -> 0 | J37: ='BASE PEDIDO'!I10 -> 0 | K37: ='BASE PEDIDO'!K10 -> 0 | L37: =I37*K37 -> 0
C38: 8 | D38: ='BASE PEDIDO'!H11 -> 0 | I38: ='BASE PEDIDO'!J11 -> 0 | J38: ='BASE PEDIDO'!I11 -> 0 | K38: ='BASE PEDIDO'!K11 -> 0 | L38: =I38*K38 -> 0
C39: 9 | D39: ='BASE PEDIDO'!H12 -> 0 | I39: ='BASE PEDIDO'!J12 -> 0 | J39: ='BASE PEDIDO'!I12 -> 0 | K39: ='BASE PEDIDO'!K12 -> 0 | L39: =I39*K39 -> 0
C40: 10 | D40: ='BASE PEDIDO'!H13 -> 0 | I40: ='BASE PEDIDO'!J13 -> 0 | J40: ='BASE PEDIDO'!I13 -> 0 | K40: ='BASE PEDIDO'!K13 -> 0 | L40: =I40*K40 -> 0
C41: 11 | D41: ='BASE PEDIDO'!H14 -> 0 | I41: ='BASE PEDIDO'!J14 -> 0 | J41: ='BASE PEDIDO'!I14 -> 0 | K41: ='BASE PEDIDO'!K14 -> 0 | L41: =I41*K41 -> 0
C42: 12 | D42: ='BASE PEDIDO'!H15 -> 0 | I42: ='BASE PEDIDO'!J15 -> 0 | J42: ='BASE PEDIDO'!I15 -> 0 | K42: ='BASE PEDIDO'!K15 -> 0 | L42: =I42*K42 -> 0
... C60: 30 | D60: ='BASE PEDIDO'!H33 -> 0 | I60: ='BASE PEDIDO'!J33 -> 0 | J60: ='BASE PEDIDO'!I33 -> 0 | K60: ='BASE PEDIDO'!K33 -> 0 | L60: =I60*K60 -> 0
K61: SUB TOTAL | L61: =SUM(L31:L60)-L62 -> 27194.028
K62: DESCONTO | L62: =SUMIF(D31:D58,"DESCONTO",L31:L58) -> 0
K63: TOTAL | L63: =L61+L62 -> 27194.028
L65: Horario de RECEBIMENTO NA OBRA
L66: Segunda a Quinta-feira das 07:30h às 11:30h e das 13:00h as 15:30h
L67: Sexta-feira das 07:30h às 11:30h e das 13:00h as 14:30h

Sheet BRASUL IMPRIMIR
M1: BRASUL CONSTRUTORA LTDA
M2: Rua Coronel Jordão, 440, Vila Paiva - São Paulo, SP - CEP 02075-030
M3: Telefone: (11) 3313-8220
M4: e-mail: compras2@brasulconstrutora.com.br
C6: DATA: | D6: ='BASE PEDIDO'!A4 -> 46129 | H6: PEDIDO DE COMPRA | K6: Nº | L6: ='BASE PEDIDO'!B1 -> 2575
L7: ='BASE PEDIDO'!D4 -> ELIAS MASSUD
B9: Razão Social: | E9: =VLOOKUP(E10,FORNECEDOR[#All],2,FALSE) -> SAINT-GOBAIN DISTRIBUIÇÃO BRASUL LTDA
B10: Fornecedor: | E10: ='BASE PEDIDO'!E4 -> TELHA NORTE | J10: Vendedor: | K10: =VLOOKUP(E10,FORNECEDOR[#All],4,FALSE) -> Augusto
B11: E-mail: | E11: =VLOOKUP(E10,FORNECEDOR[#All],3,FALSE) -> augusto.endes@saint-gobain.com | J11: Telefone: | K11: =VLOOKUP(E10,FORNECEDOR[#All],5,FALSE) -> 11 9.8510-6170
B13: Endereço de Cobrança: Rua Coronel Jordão, 440 /450 | I13: Bairro: Vila Paiva | L13: CEP: 02075-030
B14: Cidade: São Paulo | I14: UF: SP | L14: Comprador: IURY
B16: Faturamento: | E16: =MID(B17,1,2) -> 28 | F16: =IF(E16="","","dias") -> dias | G16: ='BASE PEDIDO'!G4 -> BOLETO | H16: =IF(G16="PIX",VLOOKUP(E10,FORNECEDOR[#All],6,FALSE),"") | K16: Estimativa de vencimento: | L16: =$L$23+E16 -> 46162
B17: ='BASE PEDIDO'!F4 -> 28/56/84/112 | E17: =MID(B17,4,2) -> 56 | F17: =IF(E17="","","dias") -> dias | H17: =IF(G16="PIX",VLOOKUP(E10,FORNECEDOR[#All],7,FALSE),"") | L17: =IF(E17=""," ",$D$6+E17) -> 46185
E18: =MID(B17,7,2) -> 84 | L18: =IF(E18=""," ",$D$6+E18) -> 46213
E19: =MID(B17,10,3) -> 112 | F19: =IF(E19="","","dias") -> dias | L19: =IF(E19=""," ",$D$6+E19) -> 46241
F20: =IF(E20="","","dias") | L20: =IF(E20=""," ",$D$6+E20)
B21: OBSERVAÇÃO: | E21: NOTA FISCAL DEVE SER FATURADA EM NOME DA EMPRESA | I21: =IF('BASE PEDIDO'!L4="JB","JB CONSTRUÇÕES E EMPREENDIMENTOS LTDA",IF('BASE PEDIDO'!L4="BRASUL","BRASUL CONSTRUTORA LTDA","BRASUL CONSTRUTORA LTDA")) -> BRASUL CONSTRUTORA LTDA
B23: PRAZO | D23: ='BASE PEDIDO'!C4 -> ENTREGA | F23: ='BASE PEDIDO'!B4 -> 5 | G23: dias | K23: ="DATA PREVISTA DA "&'BASE PEDIDO'!C4 -> DATA PREVISTA DA ENTREGA | L23: =D6+F23 -> 46134
B25: Local de Entrega: | E25: =VLOOKUP(L7,OBRAS[#All],4,FALSE) -> Rua Prof Fauze Calil 30 | H25: Bairro: | I25: =VLOOKUP(L7,OBRAS[#All],5,FALSE) -> Centro
B26: OBRA: | D26: =VLOOKUP(L7,OBRAS[#All],3,FALSE) -> E.E Dr Elias Massud | H26: Contrato Obra: | I26: =VLOOKUP(L7,OBRAS[#All],7,FALSE) -> 0
B27: CEP: | D27: =VLOOKUP(L7,OBRAS[#All],6,FALSE) -> 13190-000 | H27: Cidade: | I27: =VLOOKUP(L7,OBRAS[#All],8,FALSE) -> Monte Mor | K27: UF: | L27: =VLOOKUP(L7,OBRAS[#All],9,FALSE) -> SP
C30: ITEM | D30: DESCRIÇÃO | I30: QTDADE | J30: UNID. | K30: VALOR UNITÁRIO | L30: VALOR TOTAL
C32: 1 | D32: ='BASE PEDIDO'!H4 -> REJ CERAMIC CINZA PLATINA5KG QUARTZOLIT | I32: ='BASE PEDIDO'!J4 -> 20 | J32: ='BASE PEDIDO'!I4 -> SACO | K32: ='BASE PEDIDO'!K4 -> 49.41 | L32: =I32*K32 -> 988.2
C33: 2 | D33: ='BASE PEDIDO'!H5 -> ARG PORCEL INT CZ 20KGQUARTZOLIT | I33: ='BASE PEDIDO'!J5 -> 120 | J33: ='BASE PEDIDO'!I5 -> SACO | K33: ='BASE PEDIDO'!K5 -> 21.51 | L33: =I33*K33 -> 2581.2
C34: 3 | D34: ='BASE PEDIDO'!H6 -> PORC MUNARI BRANCO AC60X60 RET | I34: ='BASE PEDIDO'!J6 -> 300.6 | J34: ='BASE PEDIDO'!I6 -> M2 | K34: ='BASE PEDIDO'!K6 -> 79.03 | L34: =I34*K34 -> 23756.418
C35: 4 | D35: ='BASE PEDIDO'!H7 -> DESCONTO TOTAL | I35: ='BASE PEDIDO'!J7 -> 1 | J35: ='BASE PEDIDO'!I7 -> VERBA | K35: ='BASE PEDIDO'!K7 -> -131.79 | L35: =I35*K35 -> -131.79
C36: 5 | D36: ='BASE PEDIDO'!H8 -> 0 | I36: ='BASE PEDIDO'!J8 -> 0 | J36: ='BASE PEDIDO'!I8 -> 0 | K36: ='BASE PEDIDO'!K8 -> 0 | L36: =I36*K36 -> 0
C37: 6 | D37: ='BASE PEDIDO'!H9 -> 0 | I37: ='BASE PEDIDO'!J9 -> 0 | J37: ='BASE PEDIDO'!I9 -> 0 | K37: ='BASE PEDIDO'!K9 -> 0 | L37: =I37*K37 -> 0
C38: 7 | D38: ='BASE PEDIDO'!H10 -> 0 | I38: ='BASE PEDIDO'!J10 -> 0 | J38: ='BASE PEDIDO'!I10 -> 0 | K38: ='BASE PEDIDO'!K10 -> 0 | L38: =I38*K38 -> 0
C39: 8 | D39: ='BASE PEDIDO'!H11 -> 0 | I39: ='BASE PEDIDO'!J11 -> 0 | J39: ='BASE PEDIDO'!I11 -> 0 | K39: ='BASE PEDIDO'!K11 -> 0 | L39: =I39*K39 -> 0
C40: 9 | D40: ='BASE PEDIDO'!H12 -> 0 | I40: ='BASE PEDIDO'!J12 -> 0 | J40: ='BASE PEDIDO'!I12 -> 0 | K40: ='BASE PEDIDO'!K12 -> 0 | L40: =I40*K40 -> 0
C41: 10 | D41: ='BASE PEDIDO'!H13 -> 0 | I41: ='BASE PEDIDO'!J13 -> 0 | J41: ='BASE PEDIDO'!I13 -> 0 | K41: ='BASE PEDIDO'!K13 -> 0 | L41: =I41*K41 -> 0
C42: 11 | D42: ='BASE PEDIDO'!H14 -> 0 | I42: ='BASE PEDIDO'!J14 -> 0 | J42: ='BASE PEDIDO'!I14 -> 0 | K42: ='BASE PEDIDO'!K14 -> 0 | L42: =I42*K42 -> 0
C43: 12 | D43: ='BASE PEDIDO'!H15 -> 0 | I43: ='BASE PEDIDO'!J15 -> 0 | J43: ='BASE PEDIDO'!I15 -> 0 | K43: ='BASE PEDIDO'!K15 -> 0 | L43: =I43*K43 -> 0
... C58: 27 | D58: ='BASE PEDIDO'!H30 -> 0 | I58: ='BASE PEDIDO'!J30 -> 0 | J58: ='BASE PEDIDO'!I30 -> 0 | K58: ='BASE PEDIDO'!K30 -> 0 | L58: =I58*K58 -> 0
C59: 30 | D59: ='BASE PEDIDO'!H33 -> 0 | I59: ='BASE PEDIDO'!J33 -> 0 | J59: ='BASE PEDIDO'!I33 -> 0 | K59: ='BASE PEDIDO'!K33 -> 0 | L59: =I59*K59 -> 0
C60: 31 | D60: ='BASE PEDIDO'!H34 -> 0 | I60: ='BASE PEDIDO'!J34 -> 0 | J60: ='BASE PEDIDO'!I34 -> 0 | K60: ='BASE PEDIDO'!K34 -> 0 | L60: =I60*K60 -> 0
K61: SUB TOTAL | L61: =SUM(L32:L60)-L62 -> 27194.028
K62: DESCONTO | L62: =SUMIF(D32:D58,"DESCONTO",L32:L58) -> 0
K63: TOTAL | L63: =L61+L62 -> 27194.028
...

Sheet B&B
M1: B & B Engenharia e Construções LTDA
M2: Rua itamonte 33, 440 , Vila Medeiros - São Paulo, SP - CEP 02220-000
M3: Telefone: (11) 3313-8220
M4: e-mail: compras2@brasulconstrutora.com.br
C6: DATA: | D6: ='BASE PEDIDO'!A4 -> 46129 | H6: PEDIDO DE COMPRA | K6: Nº | L6: ='BASE PEDIDO'!B1 -> 2575
L7: ='BASE PEDIDO'!D4 -> ELIAS MASSUD
B9: Razão Social: | E9: =VLOOKUP(E10,FORNECEDOR[#All],2,FALSE) -> SAINT-GOBAIN DISTRIBUIÇÃO BRASUL LTDA
B10: Fornecedor: | E10: ='BASE PEDIDO'!E4 -> TELHA NORTE | J10: Vendedor: | K10: =VLOOKUP(E10,FORNECEDOR[#All],4,FALSE) -> Augusto
B11: E-mail: | E11: =VLOOKUP(E10,FORNECEDOR[#All],3,FALSE) -> augusto.endes@saint-gobain.com | J11: Telefone: | K11: =VLOOKUP(E10,FORNECEDOR[#All],5,FALSE) -> 11 9.8510-6170
B13: Endereço de Cobrança: Rua Coronel Jordão, 440 /450 | I13: Bairro: Vila Paiva | L13: CEP: 02075-030
B14: Cidade: São Paulo | I14: UF: SP | L14: Comprador: IURY
B16: Faturamento: | E16: =MID(B17,1,2) -> 28 | F16: =IF(E16="","","dias") -> dias | G16: ='BASE PEDIDO'!G4 -> BOLETO | H16: =IF(G16="PIX",VLOOKUP(E10,FORNECEDOR[#All],6,FALSE),"") | K16: Estimativa de vencimento: | L16: =$L$23+E16 -> 46162
B17: ='BASE PEDIDO'!F4 -> 28/56/84/112 | E17: =MID(B17,4,2) -> 56 | F17: =IF(E17="","","dias") -> dias | G17: =IF(G16="PIX",VLOOKUP(E10,FORNECEDOR[#All],7,FALSE),"") | L17: =IF(E17=""," ",$D$6+E17) -> 46185
B18: {=_xlfn.TEXTSPLIT(C17," ")} -> #VALUE! | E18: =MID(B17,7,2) -> 84 | F18: =IF(E18="","","dias") -> dias | L18: =IF(E18=""," ",$D$6+E18) -> 46213
E19: =MID(B17,10,3) -> 112 | L19: =IF(E19=""," ",$D$6+E19) -> 46241
B21: OBSERVAÇÃO: | E21: NOTA FISCAL DEVE SER FATURADA EM NOME DA EMPRESA | I21: =IF('BASE PEDIDO'!L4="B&B","B&B Engenharia e Construções LTDA",IF('BASE PEDIDO'!L4="B&B Engenharia e Construções LTDA","B&B Engenharia e Construções LTDA","B&B Engenharia e Construções LTDA")) -> B&B Engenharia e Construções LTDA
B23: PRAZO | D23: ='BASE PEDIDO'!C4 -> ENTREGA | F23: ='BASE PEDIDO'!B4 -> 5 | G23: dias | K23: ="DATA PREVISTA DA "&'BASE PEDIDO'!C4 -> DATA PREVISTA DA ENTREGA | L23: =D6+F23 -> 46134
B25: Local de Entrega: | E25: =VLOOKUP(L7,OBRAS[#All],4,FALSE) -> Rua Prof Fauze Calil 30 | H25: Bairro: | I25: =VLOOKUP(L7,OBRAS[#All],5,FALSE) -> Centro
B26: OBRA: | D26: =VLOOKUP(L7,OBRAS[#All],3,FALSE) -> E.E Dr Elias Massud | H26: Contrato Obra: | I26: =VLOOKUP(L7,OBRAS[#All],7,FALSE) -> 0
B27: CEP: | D27: =VLOOKUP(L7,OBRAS[#All],6,FALSE) -> 13190-000 | H27: Cidade: | I27: =VLOOKUP(L7,OBRAS[#All],8,FALSE) -> Monte Mor | K27: UF: | L27: =VLOOKUP(L7,OBRAS[#All],9,FALSE) -> SP
C30: ITEM | D30: DESCRIÇÃO | I30: QTDADE | J30: UNID. | K30: VALOR UNITÁRIO | L30: VALOR TOTAL
C32: 1 | D32: ='BASE PEDIDO'!H4 -> REJ CERAMIC CINZA PLATINA5KG QUARTZOLIT | I32: ='BASE PEDIDO'!J4 -> 20 | J32: ='BASE PEDIDO'!I4 -> SACO | K32: ='BASE PEDIDO'!K4 -> 49.41 | L32: =I32*K32 -> 988.2
C33: 2 | D33: ='BASE PEDIDO'!H5 -> ARG PORCEL INT CZ 20KGQUARTZOLIT | I33: ='BASE PEDIDO'!J5 -> 120 | J33: ='BASE PEDIDO'!I5 -> SACO | K33: ='BASE PEDIDO'!K5 -> 21.51 | L33: =I33*K33 -> 2581.2
C34: 3 | D34: ='BASE PEDIDO'!H6 -> PORC MUNARI BRANCO AC60X60 RET | I34: ='BASE PEDIDO'!J6 -> 300.6 | J34: ='BASE PEDIDO'!I6 -> M2 | K34: ='BASE PEDIDO'!K6 -> 79.03 | L34: =I34*K34 -> 23756.418
C35: 4 | D35: ='BASE PEDIDO'!H7 -> DESCONTO TOTAL | I35: ='BASE PEDIDO'!J7 -> 1 | J35: ='BASE PEDIDO'!I7 -> VERBA | K35: ='BASE PEDIDO'!K7 -> -131.79 | L35: =I35*K35 -> -131.79
C36: 5 | D36: ='BASE PEDIDO'!H8 -> 0 | I36: ='BASE PEDIDO'!J8 -> 0 | J36: ='BASE PEDIDO'!I8 -> 0 | K36: ='BASE PEDIDO'!K8 -> 0 | L36: =I36*K36 -> 0
C37: 6 | D37: ='BASE PEDIDO'!H9 -> 0 | I37: ='BASE PEDIDO'!J9 -> 0 | J37: ='BASE PEDIDO'!I9 -> 0 | K37: ='BASE PEDIDO'!K9 -> 0 | L37: =I37*K37 -> 0
C38: 7 | D38: ='BASE PEDIDO'!H10 -> 0 | I38: ='BASE PEDIDO'!J10 -> 0 | J38: ='BASE PEDIDO'!I10 -> 0 | K38: ='BASE PEDIDO'!K10 -> 0 | L38: =I38*K38 -> 0
C39: 8 | D39: ='BASE PEDIDO'!H11 -> 0 | I39: ='BASE PEDIDO'!J11 -> 0 | J39: ='BASE PEDIDO'!I11 -> 0 | K39: ='BASE PEDIDO'!K11 -> 0 | L39: =I39*K39 -> 0
C40: 9 | D40: ='BASE PEDIDO'!H12 -> 0 | I40: ='BASE PEDIDO'!J12 -> 0 | J40: ='BASE PEDIDO'!I12 -> 0 | K40: ='BASE PEDIDO'!K12 -> 0 | L40: =I40*K40 -> 0
C41: 10 | D41: ='BASE PEDIDO'!H13 -> 0 | I41: ='BASE PEDIDO'!J13 -> 0 | J41: ='BASE PEDIDO'!I13 -> 0 | K41: ='BASE PEDIDO'!K13 -> 0 | L41: =I41*K41 -> 0
C42: 11 | D42: ='BASE PEDIDO'!H14 -> 0 | I42: ='BASE PEDIDO'!J14 -> 0 | J42: ='BASE PEDIDO'!I14 -> 0 | K42: ='BASE PEDIDO'!K14 -> 0 | L42: =I42*K42 -> 0
C43: 12 | D43: ='BASE PEDIDO'!H15 -> 0 | I43: ='BASE PEDIDO'!J15 -> 0 | J43: ='BASE PEDIDO'!I15 -> 0 | K43: ='BASE PEDIDO'!K15 -> 0 | L43: =I43*K43 -> 0
... C61: 30 | D61: ='BASE PEDIDO'!H33 -> 0 | I61: ='BASE PEDIDO'!J33 -> 0 | J61: ='BASE PEDIDO'!I33 -> 0 | K61: ='BASE PEDIDO'!K33 -> 0 | L61: =I61*K61 -> 0
K62: SUB TOTAL | L62: =SUM(L32:L61)-L63 -> 27194.028
K63: DESCONTO | L63: =SUMIF(D32:D59,"DESCONTO",L32:L59) -> 0
K64: TOTAL | L64: =L62+L63 -> 27194.028
L66: Horario de RECEBIMENTO NA OBRA
L67: Segunda a Quinta-feira das 07:30h às 11:30h e das 13:00h as 15:30h
L68: Sexta-feira das 07:30h às 11:30h e das 13:00h as 14:30h

Sheet INTERIORANA IMPRIMIR
M1: INTERIORANA CONSTRUTORA LTDA
M2: Avª Mofarrej, 348 – Sala 703 – Vila Leopoldina – São Paulo/SP
M3: Telefone: (11) 2892.8916
M4: e-mail: compras2@brasulconstrutora.com.br
C6: DATA: | D6: ='BASE PEDIDO'!A4 -> 46129 | H6: PEDIDO DE COMPRA | K6: Nº | L6: ='BASE PEDIDO'!B1 -> 2575
L7: ='BASE PEDIDO'!D4 -> ELIAS MASSUD
B9: Razão Social: | E9: =VLOOKUP(E10,FORNECEDOR[#All],2,FALSE) -> SAINT-GOBAIN DISTRIBUIÇÃO BRASUL LTDA
B10: Fornecedor: | E10: ='BASE PEDIDO'!E4 -> TELHA NORTE | J10: Vendedor: | K10: =VLOOKUP(E10,FORNECEDOR[#All],4,FALSE) -> Augusto
B11: E-mail: | E11: =VLOOKUP(E10,FORNECEDOR[#All],3,FALSE) -> augusto.endes@saint-gobain.com | J11: Telefone: | K11: =VLOOKUP(E10,FORNECEDOR[#All],5,FALSE) -> 11 9.8510-6170
B13: Endereço de Cobrança: Rua Coronel Jordão, 440 /450 | I13: Bairro: Vila Paiva | L13: CEP: 02075-030
B14: Cidade: São Paulo | I14: UF: SP | L14: Comprador: IURY
B16: Faturamento: | E16: =MID(B17,1,2) -> 28 | F16: =IF(E16="","","dias") -> dias | G16: ='BASE PEDIDO'!G4 -> BOLETO | H16: =IF(G16="PIX",VLOOKUP(E10,FORNECEDOR[#All],6,FALSE),"") | K16: Estimativa de vencimento: | L16: =$L$24+E16 -> 46162
B17: ='BASE PEDIDO'!F4 -> 28/56/84/112 | E17: =MID(B17,4,2) -> 56 | F17: =IF(E17="","","dias") -> dias | H17: =IF(G16="PIX",VLOOKUP(E10,FORNECEDOR[#All],7,FALSE),"") | L17: =IF(E17=""," ",$D$6+E17) -> 46185
B18: {=_xlfn.TEXTSPLIT(C17," ")} -> #VALUE! | E18: =MID(B17,7,2) -> 84 | F18: =IF(E18="","","dias") -> dias | L18: =IF(E18=""," ",$D$6+E18) -> 46213
E19: =MID(B17,10,3) -> 112 | F19: dias | L19: =IF(E19=""," ",$D$6+E19) -> 46241
L20: =IF(E20=""," ",$D$6+E20)
B22: OBSERVAÇÃO: | E22: NOTA FISCAL DEVE SER FATURADA EM NOME DA EMPRESA | I22: =IF('BASE PEDIDO'!L4="JB","JB CONSTRUÇÕES E EMPREENDIMENTOS LTDA",IF('BASE PEDIDO'!L4="BRASUL","BRASUL CONSTRUTORA LTDA","INTERIORANA CONSTRUTORA LTDA")) -> INTERIORANA CONSTRUTORA LTDA
B24: PRAZO | D24: ='BASE PEDIDO'!C4 -> ENTREGA | F24: ='BASE PEDIDO'!B4 -> 5 | G24: dias | K24: ="DATA PREVISTA DA "&'BASE PEDIDO'!C4 -> DATA PREVISTA DA ENTREGA | L24: =D6+F24 -> 46134
B26: Local de Entrega: | E26: =VLOOKUP(L7,OBRAS[#All],4,FALSE) -> Rua Prof Fauze Calil 30 | H26: Bairro: | I26: =VLOOKUP(L7,OBRAS[#All],5,FALSE) -> Centro
B27: OBRA: | D27: =VLOOKUP(L7,OBRAS[#All],3,FALSE) -> E.E Dr Elias Massud | H27: Contrato Obra: | I27: =VLOOKUP(L7,OBRAS[#All],7,FALSE) -> 0
B28: CEP: | D28: =VLOOKUP(L7,OBRAS[#All],6,FALSE) -> 13190-000 | H28: Cidade: | I28: =VLOOKUP(L7,OBRAS[#All],8,FALSE) -> Monte Mor | K28: UF: | L28: =VLOOKUP(L7,OBRAS[#All],9,FALSE) -> SP
C31: ITEM | D31: DESCRIÇÃO | I31: QTDADE | J31: UNID. | K31: VALOR UNITÁRIO | L31: VALOR TOTAL
C33: 1 | D33: ='BASE PEDIDO'!H4 -> REJ CERAMIC CINZA PLATINA5KG QUARTZOLIT | I33: ='BASE PEDIDO'!J4 -> 20 | J33: ='BASE PEDIDO'!I4 -> SACO | K33: ='BASE PEDIDO'!K4 -> 49.41 | L33: =I33*K33 -> 988.2
C34: 2 | D34: ='BASE PEDIDO'!H5 -> ARG PORCEL INT CZ 20KGQUARTZOLIT | I34: ='BASE PEDIDO'!J5 -> 120 | J34: ='BASE PEDIDO'!I5 -> SACO | K34: ='BASE PEDIDO'!K5 -> 21.51 | L34: =I34*K34 -> 2581.2
C35: 3 | D35: ='BASE PEDIDO'!H6 -> PORC MUNARI BRANCO AC60X60 RET | I35: ='BASE PEDIDO'!J6 -> 300.6 | J35: ='BASE PEDIDO'!I6 -> M2 | K35: ='BASE PEDIDO'!K6 -> 79.03 | L35: =I35*K35 -> 23756.418
C36: 4 | D36: ='BASE PEDIDO'!H7 -> DESCONTO TOTAL | I36: ='BASE PEDIDO'!J7 -> 1 | J36: ='BASE PEDIDO'!I7 -> VERBA | K36: ='BASE PEDIDO'!K7 -> -131.79 | L36: =I36*K36 -> -131.79
C37: 5 | D37: ='BASE PEDIDO'!H8 -> 0 | I37: ='BASE PEDIDO'!J8 -> 0 | J37: ='BASE PEDIDO'!I8 -> 0 | K37: ='BASE PEDIDO'!K8 -> 0 | L37: =I37*K37 -> 0
C38: 6 | D38: ='BASE PEDIDO'!H9 -> 0 | I38: ='BASE PEDIDO'!J9 -> 0 | J38: ='BASE PEDIDO'!I9 -> 0 | K38: ='BASE PEDIDO'!K9 -> 0 | L38: =I38*K38 -> 0
C39: 7 | D39: ='BASE PEDIDO'!H10 -> 0 | I39: ='BASE PEDIDO'!J10 -> 0 | J39: ='BASE PEDIDO'!I10 -> 0 | K39: ='BASE PEDIDO'!K10 -> 0 | L39: =I39*K39 -> 0
C40: 8 | D40: ='BASE PEDIDO'!H11 -> 0 | I40: ='BASE PEDIDO'!J11 -> 0 | J40: ='BASE PEDIDO'!I11 -> 0 | K40: ='BASE PEDIDO'!K11 -> 0 | L40: =I40*K40 -> 0
C41: 9 | D41: ='BASE PEDIDO'!H12 -> 0 | I41: ='BASE PEDIDO'!J12 -> 0 | J41: ='BASE PEDIDO'!I12 -> 0 | K41: ='BASE PEDIDO'!K12 -> 0 | L41: =I41*K41 -> 0
C42: 10 | D42: ='BASE PEDIDO'!H13 -> 0 | I42: ='BASE PEDIDO'!J13 -> 0 | J42: ='BASE PEDIDO'!I13 -> 0 | K42: ='BASE PEDIDO'!K13 -> 0 | L42: =I42*K42 -> 0
C43: 11 | D43: ='BASE PEDIDO'!H14 -> 0 | I43: ='BASE PEDIDO'!J14 -> 0 | J43: ='BASE PEDIDO'!I14 -> 0 | K43: ='BASE PEDIDO'!K14 -> 0 | L43: =I43*K43 -> 0
C44: 12 | D44: ='BASE PEDIDO'!H15 -> 0 | I44: ='BASE PEDIDO'!J15 -> 0 | J44: ='BASE PEDIDO'!I15 -> 0 | K44: ='BASE PEDIDO'!K15 -> 0 | L44: =I44*K44 -> 0
... C67: 35 | D67: ='BASE PEDIDO'!H38 -> 0 | I67: ='BASE PEDIDO'!J38 -> 0 | J67: ='BASE PEDIDO'!I38 -> 0 | K67: ='BASE PEDIDO'!K38 -> 0 | L67: =I67*K67 -> 0
K68: SUB TOTAL | L68: =SUM(L33:L66)-L69 -> 27194.028
K69: DESCONTO | L69: =SUMIF(D33:D60,"DESCONTO",L33:L60) -> 0
K70: TOTAL | L70: =L68+L69 -> 27194.028
L72: Horario de RECEBIMENTO NA OBRA
L73: Segunda a Quinta-feira das 07:30h às 11:30h e das 13:00h as 15:30h
...

Sheet DADOS DAS OBRAS
A1: OBRA | B1: FATURAMENTO | C1: ESCOLA | D1: Local de Entrega: | E1: Bairro: | F1: CEP: | G1: Contrato Obra: | H1: Cidade: | I1: UF: | J1: Empreiteiro | K1: Contato
A2: FCO MIGNONE | B2: BRASUL | C2: EE FRANCISCO MIGNONE | D2: Rua Rio Birigui nº 01 | E2: Gleba do Pessego - Parque do Carmo | F2: 08265-290 | G2: 70/00146/23/01 | H2: São Paulo | I2: SP | J2: BERNARDO | K2: (11) 9.8506-0719
A3: KEIZO - JB | B3: JB | C3: EE KEIZO ISHIHARA | D3: Rua Mário Gessulho, 60 | E3: Conj. Res. Butanta | F3: 05540-130 | G3: 10/00005/23-01-051 | H3: São Paulo | I3: SP | J3: GEORGE | K3: (11) 9.8033-4770
A4: SOLON BORGES - JB | B4: JB | C4: EE/CEL SOLON BORGES DOS REIS | D4: Av. José Joaquim Seabra, 1187 | E4: Rio Pequeno | F4: 05364-000 | G4: 10/00005/23-01-051 | H4: São Paulo | I4: SP | J4: GEORGE | K4: (11) 9.8033-4770
A5: PEDRO COSTA - JB | B5: JB | C5: EE DEP PEDRO COSTA | D5: Rua Nilo Luís Mazzei, 378 | E5: Vila Isolina Mazzei | F5: 02081-070 | G5: 10/00005/23-01-051 | H5: São Paulo | I5: SP | J5: BERNARDO | K5: (11) 9.8506-0719
A6: BENEDITO TOLOSA - JB | B6: JB | C6: EE PROF BENEDITO TOLOSA | D6: Rua Jaguarete, 617 | E6: Casa Verde | F6: 02515-010 | G6: 10/00005/23-01-051 | H6: São Paulo | I6: SP | J6: KERLISON | K6: (11) 9.8570-2178
A7: THEREZA | B7: BRASUL | C7: EE THEREZA SILVEIRA | D7: Rua: Santo Antonio, 41 | E7: Jd. São Miguel | F7: 11440-080 | H7: Guaruja | I7: SP
A8: PE NILDO | B8: BRASUL | C8: EE Padre Nildo do Amaral Junior | D8: R. da Tropicália, s/n | E8: Jardim Pedro José Nunes | F8: 08061-010 | H8: São Paulo | I8: SP
A9: ALDEIA CAPOEIRÃO | B9: BRASUL | C9: EEI ALDEIA CAPOEIRAO | D9: ALDEIA CAPOEIRAO | E9: KM 93 | F9: 11760 - 000 | H9: Itariri | I9: SP | J9: SANDOVAL | K9: (11) 9.7792-3909
A10: ARY BARROSO | B10: BRASUL
A11: ANTONIO FERNANDES | B11: BRASUL | C11: EE PROF ANTONIO FERNANDES | D11: Rua Prof Antonio Fernandes 74 | E11: Vila Tupy | F11: 11900-000 | G11: 69/00811/23/01 | H11: Registro | I11: SP
A12: WALDEMAR RIGOTO - B&B | B12: B&B | C12: E. E. Prof. Waldemar da Silva Rigotto | D12: R. Primeiro de Maio, S/N | E12: Sítio Paecara (Vicente de Carvalho) | F12: 11460-000 | H12: Guaruja | I12: SP
A13: PEDRO BARROS | B13: BRASUL | C13: EE/EMEF PEDRO BARROS | D13: Rod. Régis Bittencourt, 384 | E13: Pedro Barros | F13: 11850-00 | G13: 69/00077/24-001-001 | H13: Miracatu | I13: SP
A14: EE ITARIRI | B14: BRASUL | C14: EE PEI ITARIRI | D14: Rua Benedito Calixto, 306 | E14: Centro Itariri | F14: 11760-000 | G14: 70/00158/23/01 | H14: Itariri | I14: SP
A15: EE WALDOMIRO MARIANI | B15: B&B | C15: EE Prof. Waldomiro Marian | D15: R. Orlando Terras, s/n | E15: Jardim Rea | F15: 11534-870 | H15: Cubatão | I15: SP | K15: (13) 3323-6265
A16: THEREZINHA ARANHA | B16: BRASUL | C16: EE Therezinha A Mantelli | D16: Rua Profº Antonio de Castro Lopes, 930 | E16: PQ Boturussu/Ermelindo Matarazzo | F16: 03805-080 | G16: 70/00146/23/01 | H16: São Paulo | I16: SP
A17: MARIO CORADIN | B17: BRASUL | C17: MARIO CORADIN | D17: Rod. Regis Bittencourt, Km 555 | E17: Rio Vermelho | F17: 11955-000 | G17: 69/01135/23/01 | H17: Barra do Turco | I17: SP
A18: EE GODOFREDO FURTADO - JB | B18: JB | C18: GODOFREDO FURTADO - JB | D18: R. João Moura, 727 - Jardim Paulista, São Paulo | E18: São Paulo | F18: 05412-001 | H18: São Paulo | I18: SP
A19: ALAY CORREA | B19: BRASUL | C19: ALAY JOSE CORREA VEREADOR | D19: R. Serra da Juréia, 130 - Jardim Valeri | E19: Registro | F19: 11900-000 | H19: São Paulo | I19: SP
A20: FDE | B20: BRASUL | C20: Fundação para o Desenvolvimento da Educação | D20: Av. São Luís, 99 - Centro Historico de São Paulo | E20: São Paulo | F20: 01046-001 | H20: São Paulo | I20: SP
A21: JOSE VICENTE BERTOLI | B21: BRASUL | C21: EE Prof. José Vicente Bertoli | D21: Estrada Municipal do Bairro Angatuba, S/N | E21: Angatuba | F21: 11930-000 | H21: Pariquera-Açu | I21: SP
