Workbook
Name bb: LANÇAMENTO[[#Headers],[OBRA]]
Name bb: LANÇAMENTO[[#Headers],[OBRA]]
Name FORNECEDORES: FORNECEDOR[]
Name FORNECEDORES: FORNECEDOR[]
Name FORNECEDORES: FORNECEDOR[]
Name FORNECEDORES: FORNECEDOR[]
Name FORNECEDORES: FORNECEDOR[]
Name FORNECEDORES: FORNECEDOR[]
Name OBRA: LANÇAMENTO[[#Headers],[OBRA]]
Name OBRA: LANÇAMENTO[[#Headers],[OBRA]]
Name OBRA: LANÇAMENTO[[#Headers],[OBRA]]
Name OBRA: LANÇAMENTO[[#Headers],[OBRA]]
Name OBRA: LANÇAMENTO[[#Headers],[OBRA]]
Name OBRA: LANÇAMENTO[[#Headers],[OBRA]]
Name OBRA: LANÇAMENTO[[#Headers],[OBRA]]

Sheet LANÇAMENTO
E1: =TODAY() -> 46129
A2: a | B2: OBRA | C2: FATURAMENTO | D2: ITEM | E2: MATERIAL SOLICITADO | F2: QTDADE | G2: UNID | H2: PEDIDO | I2: FORNECEDOR | J2: DESCRIÇÃO MATERIAL | K2: VALOR UNITARIO | L2: VALOR TOTAL | M2: DATA PEDIDO | N2: MÊS/ANO PEDIDO | O2: CONDIÇÃO PAGAMENTO | P2: FORMA DE PAGAMENTO | Q2: RETIRA OU ENTREGA | R2: PRAZO | S2: PREVISÃO ENTREGA OBRA | T2: RESTA | U2: OBRA COM MATERIAL | V2: OBSERVAÇÃO
A3: 45327 | B3: FCO MIGNONE | C3: =VLOOKUP(LANÇAMENTO[[#This Row],[OBRA]],OBRAS[],2,FALSE) -> BRASUL | D3: OUTROS | E3: ARG USO INTERNO AC1 20KG FORT | F3: 20 | G3: SACO | H3: 878 | I3: C&C | J3: ARG USO INTERNO AC1 20KG FORT | K3: 12.9 | L3: =LANÇAMENTO[[#This Row],[VALOR UNITARIO]]*LANÇAMENTO[[#This Row],[QTDADE]] -> 258 | M3: 45327 | N3: =TEXT(LANÇAMENTO[[#This Row],[DATA PEDIDO]],"MMM")&"-"&TEXT(M3,"AAAA") -> fev-2024 | O3: 30/60/90/120/150 | P3: BOLETO | Q3: ENTREGA | R3: 4 | S3: =IF(LANÇAMENTO[[#This Row],[DATA PEDIDO]]="","",LANÇAMENTO[[#This Row],[DATA PEDIDO]]+LANÇAMENTO[[#This Row],[PRAZO]]) -> 45331 | T3: =IF(LANÇAMENTO[[#This Row],[OBRA COM MATERIAL]]="OK","ENTREGUE",IF(LANÇAMENTO[[#This Row],[PRAZO]]="","",LANÇAMENTO[[#This Row],[PREVISÃO ENTREGA OBRA]]-$E$1)) -> -798
A4: 45873 | B4: GUIDO ROSOLÉN | C4: INTERIORANA | D4: LOCAÇÃO | E4: CAÇAMBA | F4: 1 | G4: UNID. | H4: 7304 | I4: HORTOCAÇAMBAS | J4: CAÇAMBA | K4: 400 | L4: =LANÇAMENTO[[#This Row],[VALOR UNITARIO]]*LANÇAMENTO[[#This Row],[QTDADE]] -> 400 | M4: 45873 | N4: =TEXT(LANÇAMENTO[[#This Row],[DATA PEDIDO]],"MMM")&"-"&TEXT(M4,"AAAA") -> ago-2025 | O4: 7 | P4: BOLETO | Q4: ENTREGA | R4: 0 | S4: =IF(LANÇAMENTO[[#This Row],[DATA PEDIDO]]="","",LANÇAMENTO[[#This Row],[DATA PEDIDO]]+LANÇAMENTO[[#This Row],[PRAZO]]) -> 45873 | T4: =IF(LANÇAMENTO[[#This Row],[OBRA COM MATERIAL]]="OK","ENTREGUE",IF(LANÇAMENTO[[#This Row],[PRAZO]]="","",LANÇAMENTO[[#This Row],[PREVISÃO ENTREGA OBRA]]-$E$1)) -> ENTREGUE | U4: OK
A5: 45873 | B5: DEPUTADO ANTONIO | C5: B&B | D5: COBERTURA / FORRO | E5: TELHA OND. CRFS BRASILIT 2,44X1,10X8MM | F5: 4 | G5: UNID. | H5: 7305 | I5: TELHADÃO | J5: TELHA OND. CRFS BRASILIT 2,44X1,10X8MM | K5: 101.75 | L5: =LANÇAMENTO[[#This Row],[VALOR UNITARIO]]*LANÇAMENTO[[#This Row],[QTDADE]] -> 407 | M5: 45873 | N5: =TEXT(LANÇAMENTO[[#This Row],[DATA PEDIDO]],"MMM")&"-"&TEXT(M5,"AAAA") -> ago-2025 | O5: 28/35/42 | P5: BOLETO | Q5: RETIRA | R5: 1 | S5: =IF(LANÇAMENTO[[#This Row],[DATA PEDIDO]]="","",LANÇAMENTO[[#This Row],[DATA PEDIDO]]+LANÇAMENTO[[#This Row],[PRAZO]]) -> 45874 | T5: =IF(LANÇAMENTO[[#This Row],[OBRA COM MATERIAL]]="OK","ENTREGUE",IF(LANÇAMENTO[[#This Row],[PRAZO]]="","",LANÇAMENTO[[#This Row],[PREVISÃO ENTREGA OBRA]]-$E$1)) -> ENTREGUE | U5: OK
A6: 45873 | B6: DEPUTADO ANTONIO | C6: B&B | D6: COBERTURA / FORRO | E6: TELHA OND. CRFS BRASILIT 2,13X1,10X8MM | F6: 20 | G6: UNID. | H6: 7305 | I6: TELHADÃO | J6: TELHA OND. CRFS BRASILIT 2,13X1,10X8MM | K6: 97.38 | L6: =LANÇAMENTO[[#This Row],[VALOR UNITARIO]]*LANÇAMENTO[[#This Row],[QTDADE]] -> 1947.6 | M6: 45873 | N6: =TEXT(LANÇAMENTO[[#This Row],[DATA PEDIDO]],"MMM")&"-"&TEXT(M6,"AAAA") -> ago-2025 | O6: 28/35/42 | P6: BOLETO | Q6: RETIRA | R6: 1 | S6: =IF(LANÇAMENTO[[#This Row],[DATA PEDIDO]]="","",LANÇAMENTO[[#This Row],[DATA PEDIDO]]+LANÇAMENTO[[#This Row],[PRAZO]]) -> 45874 | T6: =IF(LANÇAMENTO[[#This Row],[OBRA COM MATERIAL]]="OK","ENTREGUE",IF(LANÇAMENTO[[#This Row],[PRAZO]]="","",LANÇAMENTO[[#This Row],[PREVISÃO ENTREGA OBRA]]-$E$1)) -> ENTREGUE | U6: OK
A7: 45873 | B7: DEPUTADO ANTONIO | C7: B&B | D7: COBERTURA / FORRO | E7: TELHA OND. CRFS BRASILIT 1,83X1,10X8MM | F7: 10 | G7: UNID. | H7: 7305 | I7: TELHADÃO | J7: TELHA OND. CRFS BRASILIT 1,83X1,10X8MM | K7: 81.02 | L7: =LANÇAMENTO[[#This Row],[VALOR UNITARIO]]*LANÇAMENTO[[#This Row],[QTDADE]] -> 810.2 | M7: 45873 | N7: =TEXT(LANÇAMENTO[[#This Row],[DATA PEDIDO]],"MMM")&"-"&TEXT(M7,"AAAA") -> ago-2025 | O7: 28/35/42 | P7: BOLETO | Q7: RETIRA | R7: 1 | S7: =IF(LANÇAMENTO[[#This Row],[DATA PEDIDO]]="","",LANÇAMENTO[[#This Row],[DATA PEDIDO]]+LANÇAMENTO[[#This Row],[PRAZO]]) -> 45874 | T7: =IF(LANÇAMENTO[[#This Row],[OBRA COM MATERIAL]]="OK","ENTREGUE",IF(LANÇAMENTO[[#This Row],[PRAZO]]="","",LANÇAMENTO[[#This Row],[PREVISÃO ENTREGA OBRA]]-$E$1)) -> ENTREGUE | U7: OK
A8: 45873 | B8: DEPUTADO ANTONIO | C8: B&B | D8: COBERTURA / FORRO | E8: CUMEEIRA T.O. 1,10X300MM CRFS BRASILIT 15GR | F8: 3 | G8: UNID. | H8: 7305 | I8: TELHADÃO | J8: CUMEEIRA T.O. 1,10X300MM CRFS BRASILIT 15GR | K8: 54.77 | L8: =LANÇAMENTO[[#This Row],[VALOR UNITARIO]]*LANÇAMENTO[[#This Row],[QTDADE]] -> 164.31 | M8: 45873 | N8: =TEXT(LANÇAMENTO[[#This Row],[DATA PEDIDO]],"MMM")&"-"&TEXT(M8,"AAAA") -> ago-2025 | O8: 28/35/42 | P8: BOLETO | Q8: RETIRA | R8: 1 | S8: =IF(LANÇAMENTO[[#This Row],[DATA PEDIDO]]="","",LANÇAMENTO[[#This Row],[DATA PEDIDO]]+LANÇAMENTO[[#This Row],[PRAZO]]) -> 45874 | T8: =IF(LANÇAMENTO[[#This Row],[OBRA COM MATERIAL]]="OK","ENTREGUE",IF(LANÇAMENTO[[#This Row],[PRAZO]]="","",LANÇAMENTO[[#This Row],[PREVISÃO ENTREGA OBRA]]-$E$1)) -> ENTREGUE | U8: OK
A9: 45873 | B9: ALEXANDRINA SANTIAGO | C9: B&B | D9: COBERTURA / FORRO | E9: TELHA CERAMICA ROMANA IMP. REALEZA GOLD BARROBELLO | F9: 50 | G9: UNID. | H9: 7306 | I9: TELHADÃO | J9: TELHA CERAMICA ROMANA IMP. REALEZA GOLD BARROBELLO | K9: 2.28 | L9: =LANÇAMENTO[[#This Row],[VALOR UNITARIO]]*LANÇAMENTO[[#This Row],[QTDADE]] -> 114 | M9: 45873 | N9: =TEXT(LANÇAMENTO[[#This Row],[DATA PEDIDO]],"MMM")&"-"&TEXT(M9,"AAAA") -> ago-2025 | O9: 28 | P9: BOLETO | Q9: RETIRA | R9: 1 | S9: =IF(LANÇAMENTO[[#This Row],[DATA PEDIDO]]="","",LANÇAMENTO[[#This Row],[DATA PEDIDO]]+LANÇAMENTO[[#This Row],[PRAZO]]) -> 45874 | T9: =IF(LANÇAMENTO[[#This Row],[OBRA COM MATERIAL]]="OK","ENTREGUE",IF(LANÇAMENTO[[#This Row],[PRAZO]]="","",LANÇAMENTO[[#This Row],[PREVISÃO ENTREGA OBRA]]-$E$1)) -> ENTREGUE | U9: OK
A10: 45873 | B10: ALEXANDRINA SANTIAGO | C10: B&B | D10: COBERTURA / FORRO | E10: TELHA CERAMICA PAULISTINHA CAPA IMPER BARROBELLO | F10: 13 | G10: UNID. | H10: 7306 | I10: TELHADÃO | J10: TELHA CERAMICA PAULISTINHA CAPA IMPER BARROBELLO | K10: 3.76 | L10: =LANÇAMENTO[[#This Row],[VALOR UNITARIO]]*LANÇAMENTO[[#This Row],[QTDADE]] -> 48.88 | M10: 45873 | N10: =TEXT(LANÇAMENTO[[#This Row],[DATA PEDIDO]],"MMM")&"-"&TEXT(M10,"AAAA") -> ago-2025 | O10: 28 | P10: BOLETO | Q10: RETIRA | R10: 1 | S10: =IF(LANÇAMENTO[[#This Row],[DATA PEDIDO]]="","",LANÇAMENTO[[#This Row],[DATA PEDIDO]]+LANÇAMENTO[[#This Row],[PRAZO]]) -> 45874 | T10: =IF(LANÇAMENTO[[#This Row],[OBRA COM MATERIAL]]="OK","ENTREGUE",IF(LANÇAMENTO[[#This Row],[PRAZO]]="","",LANÇAMENTO[[#This Row],[PREVISÃO ENTREGA OBRA]]-$E$1)) -> ENTREGUE | U10: OK
A11: 45873 | B11: PRÉDIO VAGO | C11: B&B | D11: HIDRAULICA | E11: AMANCO TE SOLD. 50MM | F11: 2 | G11: UNID. | H11: 7307 | I11: CASA MIMOSA | J11: AMANCO TE SOLD. 50MM | K11: 12.02 | L11: =LANÇAMENTO[[#This Row],[VALOR UNITARIO]]*LANÇAMENTO[[#This Row],[QTDADE]] -> 24.04 | M11: 45873 | N11: =TEXT(LANÇAMENTO[[#This Row],[DATA PEDIDO]],"MMM")&"-"&TEXT(M11,"AAAA") -> ago-2025 | O11: 28 | P11: BOLETO | Q11: RETIRA | R11: 1 | S11: =IF(LANÇAMENTO[[#This Row],[DATA PEDIDO]]="","",LANÇAMENTO[[#This Row],[DATA PEDIDO]]+LANÇAMENTO[[#This Row],[PRAZO]]) -> 45874 | T11: =IF(LANÇAMENTO[[#This Row],[OBRA COM MATERIAL]]="OK","ENTREGUE",IF(LANÇAMENTO[[#This Row],[PRAZO]]="","",LANÇAMENTO[[#This Row],[PREVISÃO ENTREGA OBRA]]-$E$1)) -> ENTREGUE | U11: OK
A12: 45873 | B12: PRÉDIO VAGO | C12: B&B | D12: HIDRAULICA | E12: AMANCO CAP SOLD. 50MM | F12: 3 | G12: UNID. | H12: 7307 | I12: CASA MIMOSA | J12: AMANCO CAP SOLD. 50MM | K12: 5.4 | L12: =LANÇAMENTO[[#This Row],[VALOR UNITARIO]]*LANÇAMENTO[[#This Row],[QTDADE]] -> 16.2 | M12: 45873 | N12: =TEXT(LANÇAMENTO[[#This Row],[DATA PEDIDO]],"MMM")&"-"&TEXT(M12,"AAAA") -> ago-2025 | O12: 28 | P12: BOLETO | Q12: RETIRA | R12: 1 | S12: =IF(LANÇAMENTO[[#This Row],[DATA PEDIDO]]="","",LANÇAMENTO[[#This Row],[DATA PEDIDO]]+LANÇAMENTO[[#This Row],[PRAZO]]) -> 45874 | T12: =IF(LANÇAMENTO[[#This Row],[OBRA COM MATERIAL]]="OK","ENTREGUE",IF(LANÇAMENTO[[#This Row],[PRAZO]]="","",LANÇAMENTO[[#This Row],[PREVISÃO ENTREGA OBRA]]-$E$1)) -> ENTREGUE | U12: OK
A13: 45873 | B13: PRÉDIO VAGO | C13: B&B | D13: HIDRAULICA | E13: AMANCO LUVA SOLD. 50MM | F13: 4 | G13: UNID. | H13: 7307 | I13: CASA MIMOSA | J13: AMANCO LUVA SOLD. 50MM | K13: 2.49 | L13: =LANÇAMENTO[[#This Row],[VALOR UNITARIO]]*LANÇAMENTO[[#This Row],[QTDADE]] -> 9.96 | M13: 45873 | N13: =TEXT(LANÇAMENTO[[#This Row],[DATA PEDIDO]],"MMM")&"-"&TEXT(M13,"AAAA") -> ago-2025 | O13: 28 | P13: BOLETO | Q13: RETIRA | R13: 1 | S13: =IF(LANÇAMENTO[[#This Row],[DATA PEDIDO]]="","",LANÇAMENTO[[#This Row],[DATA PEDIDO]]+LANÇAMENTO[[#This Row],[PRAZO]]) -> 45874 | T13: =IF(LANÇAMENTO[[#This Row],[OBRA COM MATERIAL]]="OK","ENTREGUE",IF(LANÇAMENTO[[#This Row],[PRAZO]]="","",LANÇAMENTO[[#This Row],[PREVISÃO ENTREGA OBRA]]-$E$1)) -> ENTREGUE | U13: OK
A14: 45873 | B14: PRÉDIO VAGO | C14: B&B | D14: HIDRAULICA | E14: AMANCO TE ESG. 50MM | F14: 2 | G14: UNID. | H14: 7307 | I14: CASA MIMOSA | J14: AMANCO TE ESG. 50MM | K14: 4.6 | L14: =LANÇAMENTO[[#This Row],[VALOR UNITARIO]]*LANÇAMENTO[[#This Row],[QTDADE]] -> 9.2 | M14: 45873 | N14: =TEXT(LANÇAMENTO[[#This Row],[DATA PEDIDO]],"MMM")&"-"&TEXT(M14,"AAAA") -> ago-2025 | O14: 28 | P14: BOLETO | Q14: RETIRA | R14: 1 | S14: =IF(LANÇAMENTO[[#This Row],[DATA PEDIDO]]="","",LANÇAMENTO[[#This Row],[DATA PEDIDO]]+LANÇAMENTO[[#This Row],[PRAZO]]) -> 45874 | T14: =IF(LANÇAMENTO[[#This Row],[OBRA COM MATERIAL]]="OK","ENTREGUE",IF(LANÇAMENTO[[#This Row],[PRAZO]]="","",LANÇAMENTO[[#This Row],[PREVISÃO ENTREGA OBRA]]-$E$1)) -> ENTREGUE | U14: OK
A15: 45873 | B15: PRÉDIO VAGO | C15: B&B | D15: HIDRAULICA | E15: AMANCO JOELHO 90 ESG. 50MM | F15: 8 | G15: UNID. | H15: 7307 | I15: CASA MIMOSA | J15: AMANCO JOELHO 90 ESG. 50MM | K15: 1.76 | L15: =LANÇAMENTO[[#This Row],[VALOR UNITARIO]]*LANÇAMENTO[[#This Row],[QTDADE]] -> 14.08 | M15: 45873 | N15: =TEXT(LANÇAMENTO[[#This Row],[DATA PEDIDO]],"MMM")&"-"&TEXT(M15,"AAAA") -> ago-2025 | O15: 28 | P15: BOLETO | Q15: RETIRA | R15: 1 | S15: =IF(LANÇAMENTO[[#This Row],[DATA PEDIDO]]="","",LANÇAMENTO[[#This Row],[DATA PEDIDO]]+LANÇAMENTO[[#This Row],[PRAZO]]) -> 45874 | T15: =IF(LANÇAMENTO[[#This Row],[OBRA COM MATERIAL]]="OK","ENTREGUE",IF(LANÇAMENTO[[#This Row],[PRAZO]]="","",LANÇAMENTO[[#This Row],[PREVISÃO ENTREGA OBRA]]-$E$1)) -> ENTREGUE | U15: OK
... A22: 45873 | B22: PRÉDIO VAGO | C22: B&B | D22: HIDRAULICA | E22: AMANCO TUBO 6M MARROM SOLD. 25MM | F22: 1 | G22: UNID. | H22: 7307 | I22: CASA MIMOSA | J22: AMANCO TUBO 6M MARROM SOLD. 25MM | K22: 16.15 | L22: =LANÇAMENTO[[#This Row],[VALOR UNITARIO]]*LANÇAMENTO[[#This Row],[QTDADE]] -> 16.15 | M22: 45873 | N22: =TEXT(LANÇAMENTO[[#This Row],[DATA PEDIDO]],"MMM")&"-"&TEXT(M22,"AAAA") -> ago-2025 | O22: 28 | P22: BOLETO | Q22: RETIRA | R22: 1 | S22: =IF(LANÇAMENTO[[#This Row],[DATA PEDIDO]]="","",LANÇAMENTO[[#This Row],[DATA PEDIDO]]+LANÇAMENTO[[#This Row],[PRAZO]]) -> 45874 | T22: =IF(LANÇAMENTO[[#This Row],[OBRA COM MATERIAL]]="OK","ENTREGUE",IF(LANÇAMENTO[[#This Row],[PRAZO]]="","",LANÇAMENTO[[#This Row],[PREVISÃO ENTREGA OBRA]]-$E$1)) -> ENTREGUE | U22: OK
A23: 45870 | B23: ZILDA DOMINGOS | C23: INTERIORANA | D23: OUTROS | E23: 16 m3 concreto 25 mpa , pedrisco , slump 12 , com bomba | L23: =LANÇAMENTO[[#This Row],[VALOR UNITARIO]]*LANÇAMENTO[[#This Row],[QTDADE]] -> 0 | N23: =TEXT(LANÇAMENTO[[#This Row],[DATA PEDIDO]],"MMM")&"-"&TEXT(M23,"AAAA") -> jan-1900 | S23: =IF(LANÇAMENTO[[#This Row],[DATA PEDIDO]]="","",LANÇAMENTO[[#This Row],[DATA PEDIDO]]+LANÇAMENTO[[#This Row],[PRAZO]]) | T23: =IF(LANÇAMENTO[[#This Row],[OBRA COM MATERIAL]]="OK","ENTREGUE",IF(LANÇAMENTO[[#This Row],[PRAZO]]="","",LANÇAMENTO[[#This Row],[PREVISÃO ENTREGA OBRA]]-$E$1)) -> ENTREGUE | U23: OK
A24: 45873 | B24: ELVIRA SILVA | C24: BRASUL | D24: ELETRICA | E24: ARMACAO PRESBOW P/1 ISOL MEDIA | F24: 6 | G24: UNID. | H24: 7308 | I24: AREA ELETRICOS | J24: ARMACAO PRESBOW P/1 ISOL MEDIA | K24: 18.4 | L24: =LANÇAMENTO[[#This Row],[VALOR UNITARIO]]*LANÇAMENTO[[#This Row],[QTDADE]] -> 110.4 | M24: 45873 | N24: =TEXT(LANÇAMENTO[[#This Row],[DATA PEDIDO]],"MMM")&"-"&TEXT(M24,"AAAA") -> ago-2025 | O24: 28 | P24: BOLETO | Q24: ENTREGA | R24: 0 | S24: =IF(LANÇAMENTO[[#This Row],[DATA PEDIDO]]="","",LANÇAMENTO[[#This Row],[DATA PEDIDO]]+LANÇAMENTO[[#This Row],[PRAZO]]) -> 45873 | T24: =IF(LANÇAMENTO[[#This Row],[OBRA COM MATERIAL]]="OK","ENTREGUE",IF(LANÇAMENTO[[#This Row],[PRAZO]]="","",LANÇAMENTO[[#This Row],[PREVISÃO ENTREGA OBRA]]-$E$1)) -> ENTREGUE | U24: OK
A25: 45873 | B25: ELVIRA SILVA | C25: BRASUL | D25: ELETRICA | E25: ISOLADOR ROLDANA 67X72 PRESSBOW | F25: 6 | G25: UNID. | H25: 7308 | I25: AREA ELETRICOS | J25: ISOLADOR ROLDANA 67X72 PRESSBOW | K25: 14.6 | L25: =LANÇAMENTO[[#This Row],[VALOR UNITARIO]]*LANÇAMENTO[[#This Row],[QTDADE]] -> 87.6 | M25: 45873 | N25: =TEXT(LANÇAMENTO[[#This Row],[DATA PEDIDO]],"MMM")&"-"&TEXT(M25,"AAAA") -> ago-2025 | O25: 28 | P25: BOLETO | Q25: ENTREGA | R25: 0 | S25: =IF(LANÇAMENTO[[#This Row],[DATA PEDIDO]]="","",LANÇAMENTO[[#This Row],[DATA PEDIDO]]+LANÇAMENTO[[#This Row],[PRAZO]]) -> 45873 | T25: =IF(LANÇAMENTO[[#This Row],[OBRA COM MATERIAL]]="OK","ENTREGUE",IF(LANÇAMENTO[[#This Row],[PRAZO]]="","",LANÇAMENTO[[#This Row],[PREVISÃO ENTREGA OBRA]]-$E$1)) -> ENTREGUE | U25: OK
A26: 45873 | B26: ELVIRA SILVA | C26: BRASUL | D26: ELETRICA | E26: ELETRODUTO GALV MED 2 (0,75)C/LV | F26: 6 | G26: UNID. | H26: 7308 | I26: AREA ELETRICOS | J26: ELETRODUTO GALV MED 2 (0,75)C/LV | K26: 84 | L26: =LANÇAMENTO[[#This Row],[VALOR UNITARIO]]*LANÇAMENTO[[#This Row],[QTDADE]] -> 504 | M26: 45873 | N26: =TEXT(LANÇAMENTO[[#This Row],[DATA PEDIDO]],"MMM")&"-"&TEXT(M26,"AAAA") -> ago-2025 | O26: 28 | P26: BOLETO | Q26: ENTREGA | R26: 0 | S26: =IF(LANÇAMENTO[[#This Row],[DATA PEDIDO]]="","",LANÇAMENTO[[#This Row],[DATA PEDIDO]]+LANÇAMENTO[[#This Row],[PRAZO]]) -> 45873 | T26: =IF(LANÇAMENTO[[#This Row],[OBRA COM MATERIAL]]="OK","ENTREGUE",IF(LANÇAMENTO[[#This Row],[PRAZO]]="","",LANÇAMENTO[[#This Row],[PREVISÃO ENTREGA OBRA]]-$E$1)) -> ENTREGUE | U26: OK
A27: 45873 | B27: PRÉDIO VAGO | C27: B&B | D27: LOCAÇÃO | E27: Caçamba | F27: 2 | G27: UNID. | H27: 7309 | I27: SOS CAÇAMBAS | J27: CAÇAMBA | K27: 200 | L27: =LANÇAMENTO[[#This Row],[VALOR UNITARIO]]*LANÇAMENTO[[#This Row],[QTDADE]] -> 400 | M27: 45873 | N27: =TEXT(LANÇAMENTO[[#This Row],[DATA PEDIDO]],"MMM")&"-"&TEXT(M27,"AAAA") -> ago-2025 | O27: 7 | P27: BOLETO | Q27: ENTREGA | R27: 0 | S27: =IF(LANÇAMENTO[[#This Row],[DATA PEDIDO]]="","",LANÇAMENTO[[#This Row],[DATA PEDIDO]]+LANÇAMENTO[[#This Row],[PRAZO]]) -> 45873 | T27: =IF(LANÇAMENTO[[#This Row],[OBRA COM MATERIAL]]="OK","ENTREGUE",IF(LANÇAMENTO[[#This Row],[PRAZO]]="","",LANÇAMENTO[[#This Row],[PREVISÃO ENTREGA OBRA]]-$E$1)) -> ENTREGUE | U27: OK
A28: 45873 | B28: VIRGILIO SILVEIRA | C28: INTERIORANA | D28: LOCAÇÃO | E28: BETONEIRA CID RENTAL 400L 220V | F28: 1 | G28: UNID. | H28: 7310 | I28: Casa do construtor Itapetininga | J28: BETONEIRA CID RENTAL 400L 220V | K28: 280 | L28: =LANÇAMENTO[[#This Row],[VALOR UNITARIO]]*LANÇAMENTO[[#This Row],[QTDADE]] -> 280 | M28: 45873 | N28: =TEXT(LANÇAMENTO[[#This Row],[DATA PEDIDO]],"MMM")&"-"&TEXT(M28,"AAAA") -> ago-2025 | O28: 15 | P28: BOLETO | Q28: ENTREGA | R28: 1 | S28: =IF(LANÇAMENTO[[#This Row],[DATA PEDIDO]]="","",LANÇAMENTO[[#This Row],[DATA PEDIDO]]+LANÇAMENTO[[#This Row],[PRAZO]]) -> 45874 | T28: =IF(LANÇAMENTO[[#This Row],[OBRA COM MATERIAL]]="OK","ENTREGUE",IF(LANÇAMENTO[[#This Row],[PRAZO]]="","",LANÇAMENTO[[#This Row],[PREVISÃO ENTREGA OBRA]]-$E$1)) -> ENTREGUE | U28: OK
A29: 45873 | B29: JOSÉ DE CAMPOS | C29: INTERIORANA | D29: OUTROS | E29: TESTE E LAUDO DE ESTANQUEIDADE DE GÁS | F29: 1 | G29: UNID. | H29: 7311 | I29: CS INSTALAÇÕES | J29: TESTE E LAUDO DE ESTANQUEIDADE DE GÁS | K29: 850 | L29: =LANÇAMENTO[[#This Row],[VALOR UNITARIO]]*LANÇAMENTO[[#This Row],[QTDADE]] -> 850 | M29: 45873 | N29: =TEXT(LANÇAMENTO[[#This Row],[DATA PEDIDO]],"MMM")&"-"&TEXT(M29,"AAAA") -> ago-2025 | O29: 2 | P29: PIX | Q29: ENTREGA | R29: 2 | S29: =IF(LANÇAMENTO[[#This Row],[DATA PEDIDO]]="","",LANÇAMENTO[[#This Row],[DATA PEDIDO]]+LANÇAMENTO[[#This Row],[PRAZO]]) -> 45875 | T29: =IF(LANÇAMENTO[[#This Row],[OBRA COM MATERIAL]]="OK","ENTREGUE",IF(LANÇAMENTO[[#This Row],[PRAZO]]="","",LANÇAMENTO[[#This Row],[PREVISÃO ENTREGA OBRA]]-$E$1)) -> ENTREGUE | U29: OK
A30: 45874 | B30: LUIZ CAMPO | C30: INTERIORANA | D30: REVESTMENTO / PISO | E30: ARGAMASSA PARA PORCELANATO INTERNO 20KG CINZA | F30: 100 | G30: SACO | H30: 7312 | I30: SODIMAC | J30: ARGAMASSA PARA PORCELANATO INTERNO 20KG CINZA | K30: 21.51 | L30: =LANÇAMENTO[[#This Row],[VALOR UNITARIO]]*LANÇAMENTO[[#This Row],[QTDADE]] -> 2151 | M30: 45874 | N30: =TEXT(LANÇAMENTO[[#This Row],[DATA PEDIDO]],"MMM")&"-"&TEXT(M30,"AAAA") -> ago-2025 | O30: 28/56/84/112 | P30: BOLETO | Q30: ENTREGA | R30: 3 | S30: =IF(LANÇAMENTO[[#This Row],[DATA PEDIDO]]="","",LANÇAMENTO[[#This Row],[DATA PEDIDO]]+LANÇAMENTO[[#This Row],[PRAZO]]) -> 45877 | T30: =IF(LANÇAMENTO[[#This Row],[OBRA COM MATERIAL]]="OK","ENTREGUE",IF(LANÇAMENTO[[#This Row],[PRAZO]]="","",LANÇAMENTO[[#This Row],[PREVISÃO ENTREGA OBRA]]-$E$1)) -> ENTREGUE | U30: OK
A31: 45874 | B31: LUIZ CAMPO | C31: INTERIORANA | D31: REVESTMENTO / PISO | E31: REVESTIMENTO RETIFICADO FORMA BRANCO BRILHANTE 32X60CM CAIXA 2,30 M² | F31: 200.1 | G31: M2 | H31: 7312 | I31: SODIMAC | J31: REVESTIMENTO RETIFICADO FORMA BRANCO BRILHANTE 32X60CM CAIXA 2,30 M² | K31: 53.91 | L31: =LANÇAMENTO[[#This Row],[VALOR UNITARIO]]*LANÇAMENTO[[#This Row],[QTDADE]] -> 10787.391 | M31: 45874 | N31: =TEXT(LANÇAMENTO[[#This Row],[DATA PEDIDO]],"MMM")&"-"&TEXT(M31,"AAAA") -> ago-2025 | O31: 28/56/84/112 | P31: BOLETO | Q31: ENTREGA | R31: 3 | S31: =IF(LANÇAMENTO[[#This Row],[DATA PEDIDO]]="","",LANÇAMENTO[[#This Row],[DATA PEDIDO]]+LANÇAMENTO[[#This Row],[PRAZO]]) -> 45877 | T31: =IF(LANÇAMENTO[[#This Row],[OBRA COM MATERIAL]]="OK","ENTREGUE",IF(LANÇAMENTO[[#This Row],[PRAZO]]="","",LANÇAMENTO[[#This Row],[PREVISÃO ENTREGA OBRA]]-$E$1)) -> ENTREGUE | U31: OK
A32: 45874 | B32: LUIZ CAMPO | C32: INTERIORANA | D32: REVESTMENTO / PISO | E32: ARGAMASSA USO INTERNO ACI 20KG 45X25X10CM CINZA | F32: 50 | G32: SACO | H32: 7312 | I32: SODIMAC | J32: ARGAMASSA USO INTERNO ACI 20KG 45X25X10CM CINZA | K32: 15.26 | L32: =LANÇAMENTO[[#This Row],[VALOR UNITARIO]]*LANÇAMENTO[[#This Row],[QTDADE]] -> 763 | M32: 45874 | N32: =TEXT(LANÇAMENTO[[#This Row],[DATA PEDIDO]],"MMM")&"-"&TEXT(M32,"AAAA") -> ago-2025 | O32: 28/56/84/112 | P32: BOLETO | Q32: ENTREGA | R32: 3 | S32: =IF(LANÇAMENTO[[#This Row],[DATA PEDIDO]]="","",LANÇAMENTO[[#This Row],[DATA PEDIDO]]+LANÇAMENTO[[#This Row],[PRAZO]]) -> 45877 | T32: =IF(LANÇAMENTO[[#This Row],[OBRA COM MATERIAL]]="OK","ENTREGUE",IF(LANÇAMENTO[[#This Row],[PRAZO]]="","",LANÇAMENTO[[#This Row],[PREVISÃO ENTREGA OBRA]]-$E$1)) -> ENTREGUE | U32: OK
A33: 45874 | B33: LUIZ CAMPO | C33: INTERIORANA | D33: REVESTMENTO / PISO | E33: REJUNTE FLEXÍVEL 5KG BRANCO WEBER QUARTZOLIT | F33: 8 | G33: SACO | H33: 7312 | I33: SODIMAC | J33: REJUNTE FLEXÍVEL 5KG BRANCO WEBER QUARTZOLIT | K33: 49.41 | L33: =LANÇAMENTO[[#This Row],[VALOR UNITARIO]]*LANÇAMENTO[[#This Row],[QTDADE]] -> 395.28 | M33: 45874 | N33: =TEXT(LANÇAMENTO[[#This Row],[DATA PEDIDO]],"MMM")&"-"&TEXT(M33,"AAAA") -> ago-2025 | O33: 28/56/84/112 | P33: BOLETO | Q33: ENTREGA | R33: 3 | S33: =IF(LANÇAMENTO[[#This Row],[DATA PEDIDO]]="","",LANÇAMENTO[[#This Row],[DATA PEDIDO]]+LANÇAMENTO[[#This Row],[PRAZO]]) -> 45877 | T33: =IF(LANÇAMENTO[[#This Row],[OBRA COM MATERIAL]]="OK","ENTREGUE",IF(LANÇAMENTO[[#This Row],[PRAZO]]="","",LANÇAMENTO[[#This Row],[PREVISÃO ENTREGA OBRA]]-$E$1)) -> ENTREGUE | U33: OK
A34: 45874 | B34: LUIZ CAMPO | C34: INTERIORANA | D34: REVESTMENTO / PISO | E34: REJUNTE FLEXÍVEL, CINZA PLATINA, 5KG | F34: 10 | G34: SACO | H34: 7312 | I34: SODIMAC | J34: REJUNTE FLEXÍVEL, CINZA PLATINA, 5KG | K34: 49.41 | L34: =LANÇAMENTO[[#This Row],[VALOR UNITARIO]]*LANÇAMENTO[[#This Row],[QTDADE]] -> 494.1 | M34: 45874 | N34: =TEXT(LANÇAMENTO[[#This Row],[DATA PEDIDO]],"MMM")&"-"&TEXT(M34,"AAAA") -> ago-2025 | O34: 28/56/84/112 | P34: BOLETO | Q34: ENTREGA | R34: 3 | S34: =IF(LANÇAMENTO[[#This Row],[DATA PEDIDO]]="","",LANÇAMENTO[[#This Row],[DATA PEDIDO]]+LANÇAMENTO[[#This Row],[PRAZO]]) -> 45877 | T34: =IF(LANÇAMENTO[[#This Row],[OBRA COM MATERIAL]]="OK","ENTREGUE",IF(LANÇAMENTO[[#This Row],[PRAZO]]="","",LANÇAMENTO[[#This Row],[PREVISÃO ENTREGA OBRA]]-$E$1)) -> ENTREGUE | U34: OK
A35: 45874 | B35: LUIZ CAMPO | C35: INTERIORANA | D35: REVESTMENTO / PISO | E35: PORCELANATO YORK SGR CINZA 87,7X87,7 CAIXA 1,54M²PORTINARI | F35: 360.36 | G35: M2 | H35: 7312 | I35: SODIMAC | J35: PORCELANATO YORK SGR CINZA 87,7X87,7 CAIXA 1,54M²PORTINARI | K35: 82.71 | L35: =LANÇAMENTO[[#This Row],[VALOR UNITARIO]]*LANÇAMENTO[[#This Row],[QTDADE]] -> 29805.376 | M35: 45874 | N35: =TEXT(LANÇAMENTO[[#This Row],[DATA PEDIDO]],"MMM")&"-"&TEXT(M35,"AAAA") -> ago-2025 | O35: 28/56/84/112 | P35: BOLETO | Q35: ENTREGA | R35: 3 | S35: =IF(LANÇAMENTO[[#This Row],[DATA PEDIDO]]="","",LANÇAMENTO[[#This Row],[DATA PEDIDO]]+LANÇAMENTO[[#This Row],[PRAZO]]) -> 45877 | T35: =IF(LANÇAMENTO[[#This Row],[OBRA COM MATERIAL]]="OK","ENTREGUE",IF(LANÇAMENTO[[#This Row],[PRAZO]]="","",LANÇAMENTO[[#This Row],[PREVISÃO ENTREGA OBRA]]-$E$1)) -> ENTREGUE | U35: OK
... A61: 45874 | B61: WANDA FÉLIX | C61: INTERIORANA | D61: REVESTMENTO / PISO | E61: FRETE | F61: 1 | G61: UNID. | H61: 7321 | I61: SODIMAC | J61: FRETE | K61: 218.13 | L61: =LANÇAMENTO[[#This Row],[VALOR UNITARIO]]*LANÇAMENTO[[#This Row],[QTDADE]] -> 218.13 | M61: 45874 | N61: =TEXT(LANÇAMENTO[[#This Row],[DATA PEDIDO]],"MMM")&"-"&TEXT(M61,"AAAA") -> ago-2025 | O61: 28/56/84 | P61: BOLETO | Q61: ENTREGA | R61: 3 | S61: =IF(LANÇAMENTO[[#This Row],[DATA PEDIDO]]="","",LANÇAMENTO[[#This Row],[DATA PEDIDO]]+LANÇAMENTO[[#This Row],[PRAZO]]) -> 45877 | T61: =IF(LANÇAMENTO[[#This Row],[OBRA COM MATERIAL]]="OK","ENTREGUE",IF(LANÇAMENTO[[#This Row],[PRAZO]]="","",LANÇAMENTO[[#This Row],[PREVISÃO ENTREGA OBRA]]-$E$1)) -> ENTREGUE | U61: OK
A62: 45874 | B62: LUIZ CAMPO | C62: INTERIORANA | D62: LOCAÇÃO | E62: CAÇAMBA | F62: 1 | G62: UNID. | H62: 7322 | I62: HVR LOCAÇÃO | J62: CAÇAMBA | K62: 440 | L62: =LANÇAMENTO[[#This Row],[VALOR UNITARIO]]*LANÇAMENTO[[#This Row],[QTDADE]] -> 440 | M62: 45874 | N62: =TEXT(LANÇAMENTO[[#This Row],[DATA PEDIDO]],"MMM")&"-"&TEXT(M62,"AAAA") -> ago-2025 | O62: 10 | P62: BOLETO | Q62: ENTREGA | R62: 1 | S62: =IF(LANÇAMENTO[[#This Row],[DATA PEDIDO]]="","",LANÇAMENTO[[#This Row],[DATA PEDIDO]]+LANÇAMENTO[[#This Row],[PRAZO]]) -> 45875 | T62: =IF(LANÇAMENTO[[#This Row],[OBRA COM MATERIAL]]="OK","ENTREGUE",IF(LANÇAMENTO[[#This Row],[PRAZO]]="","",LANÇAMENTO[[#This Row],[PREVISÃO ENTREGA OBRA]]-$E$1)) -> ENTREGUE | U62: OK
A63: 45874 | B63: APARECIDA DE FATIMA | C63: INTERIORANA | D63: ELETRICA | E63: TOMADA RED 2P+T 10A 250V C/HASTE PT GRIS | F63: 7 | G63: UNID. | H63: 7323 | I63: AREA ELETRICOS | J63: TOMADA RED 2P+T 10A 250V C/HASTE PT GRIS | K63: 6.9 | L63: =LANÇAMENTO[[#This Row],[VALOR UNITARIO]]*LANÇAMENTO[[#This Row],[QTDADE]] -> 48.3 | M63: 45874 | N63: =TEXT(LANÇAMENTO[[#This Row],[DATA PEDIDO]],"MMM")&"-"&TEXT(M63,"AAAA") -> ago-2025 | O63: 28 | P63: BOLETO | Q63: ENTREGA | R63: 1 | S63: =IF(LANÇAMENTO[[#This Row],[DATA PEDIDO]]="","",LANÇAMENTO[[#This Row],[DATA PEDIDO]]+LANÇAMENTO[[#This Row],[PRAZO]]) -> 45875 | T63: =IF(LANÇAMENTO[[#This Row],[OBRA COM MATERIAL]]="OK","ENTREGUE",IF(LANÇAMENTO[[#This Row],[PRAZO]]="","",LANÇAMENTO[[#This Row],[PREVISÃO ENTREGA OBRA]]-$E$1)) -> ENTREGUE | U63: OK
A64: 45874 | B64: APARECIDA DE FATIMA | C64: INTERIORANA | D64: ELETRICA | E64: TOMADA RED HOR 2P+T 20A 250V S/PLACA PT | F64: 1 | G64: UNID. | H64: 7323 | I64: AREA ELETRICOS | J64: TOMADA RED HOR 2P+T 20A 250V S/PLACA PT | K64: 8.9 | L64: =LANÇAMENTO[[#This Row],[VALOR UNITARIO]]*LANÇAMENTO[[#This Row],[QTDADE]] -> 8.9 | M64: 45874 | N64: =TEXT(LANÇAMENTO[[#This Row],[DATA PEDIDO]],"MMM")&"-"&TEXT(M64,"AAAA") -> ago-2025 | O64: 28 | P64: BOLETO | Q64: ENTREGA | R64: 1 | S64: =IF(LANÇAMENTO[[#This Row],[DATA PEDIDO]]="","",LANÇAMENTO[[#This Row],[DATA PEDIDO]]+LANÇAMENTO[[#This Row],[PRAZO]]) -> 45875 | T64: =IF(LANÇAMENTO[[#This Row],[OBRA COM MATERIAL]]="OK","ENTREGUE",IF(LANÇAMENTO[[#This Row],[PRAZO]]="","",LANÇAMENTO[[#This Row],[PREVISÃO ENTREGA OBRA]]-$E$1)) -> ENTREGUE | U64: OK
A65: 45874 | B65: APARECIDA DE FATIMA | C65: INTERIORANA | D65: ELETRICA | E65: LUMINARIA EMERG 30LED BIV 100LM SLIM SEG | F65: 6 | G65: UNID. | H65: 7323 | I65: AREA ELETRICOS | J65: LUMINARIA EMERG 30LED BIV 100LM SLIM SEG | K65: 20.2 | L65: =LANÇAMENTO[[#This Row],[VALOR UNITARIO]]*LANÇAMENTO[[#This Row],[QTDADE]] -> 121.2 | M65: 45874 | N65: =TEXT(LANÇAMENTO[[#This Row],[DATA PEDIDO]],"MMM")&"-"&TEXT(M65,"AAAA") -> ago-2025 | O65: 28 | P65: BOLETO | Q65: ENTREGA | R65: 1 | S65: =IF(LANÇAMENTO[[#This Row],[DATA PEDIDO]]="","",LANÇAMENTO[[#This Row],[DATA PEDIDO]]+LANÇAMENTO[[#This Row],[PRAZO]]) -> 45875 | T65: =IF(LANÇAMENTO[[#This Row],[OBRA COM MATERIAL]]="OK","ENTREGUE",IF(LANÇAMENTO[[#This Row],[PRAZO]]="","",LANÇAMENTO[[#This Row],[PREVISÃO ENTREGA OBRA]]-$E$1)) -> ENTREGUE | U65: OK
A66: 45874 | B66: APARECIDA DE FATIMA | C66: INTERIORANA | D66: ELETRICA | E66: TAMPA ALUM CEGA 1 | F66: 20 | G66: UNID. | H66: 7323 | I66: AREA ELETRICOS | J66: TAMPA ALUM CEGA 1 | K66: 2.8 | L66: =LANÇAMENTO[[#This Row],[VALOR UNITARIO]]*LANÇAMENTO[[#This Row],[QTDADE]] -> 56 | M66: 45874 | N66: =TEXT(LANÇAMENTO[[#This Row],[DATA PEDIDO]],"MMM")&"-"&TEXT(M66,"AAAA") -> ago-2025 | O66: 28 | P66: BOLETO | Q66: ENTREGA | R66: 1 | S66: =IF(LANÇAMENTO[[#This Row],[DATA PEDIDO]]="","",LANÇAMENTO[[#This Row],[DATA PEDIDO]]+LANÇAMENTO[[#This Row],[PRAZO]]) -> 45875 | T66: =IF(LANÇAMENTO[[#This Row],[OBRA COM MATERIAL]]="OK","ENTREGUE",IF(LANÇAMENTO[[#This Row],[PRAZO]]="","",LANÇAMENTO[[#This Row],[PREVISÃO ENTREGA OBRA]]-$E$1)) -> ENTREGUE | U66: OK
A67: 45874 | B67: APARECIDA DE FATIMA | C67: INTERIORANA | D67: ELETRICA | E67: TAMPA ALUM CEGA 3/4 OU 1/2 | F67: 20 | G67: UNID. | H67: 7323 | I67: AREA ELETRICOS | J67: TAMPA ALUM CEGA 3/4 OU 1/2 | K67: 2.2 | L67: =LANÇAMENTO[[#This Row],[VALOR UNITARIO]]*LANÇAMENTO[[#This Row],[QTDADE]] -> 44 | M67: 45874 | N67: =TEXT(LANÇAMENTO[[#This Row],[DATA PEDIDO]],"MMM")&"-"&TEXT(M67,"AAAA") -> ago-2025 | O67: 28 | P67: BOLETO | Q67: ENTREGA | R67: 1 | S67: =IF(LANÇAMENTO[[#This Row],[DATA PEDIDO]]="","",LANÇAMENTO[[#This Row],[DATA PEDIDO]]+LANÇAMENTO[[#This Row],[PRAZO]]) -> 45875 | T67: =IF(LANÇAMENTO[[#This Row],[OBRA COM MATERIAL]]="OK","ENTREGUE",IF(LANÇAMENTO[[#This Row],[PRAZO]]="","",LANÇAMENTO[[#This Row],[PREVISÃO ENTREGA OBRA]]-$E$1)) -> ENTREGUE | U67: OK
A68: 45874 | B68: APARECIDA DE FATIMA | C68: INTERIORANA | D68: ELETRICA | E68: TAMPA P/1 TOM RED 3/4 OU 1/2 | F68: 8 | G68: UNID. | H68: 7323 | I68: AREA ELETRICOS | J68: TAMPA P/1 TOM RED 3/4 OU 1/2 | K68: 2.2 | L68: =LANÇAMENTO[[#This Row],[VALOR UNITARIO]]*LANÇAMENTO[[#This Row],[QTDADE]] -> 17.6 | M68: 45874 | N68: =TEXT(LANÇAMENTO[[#This Row],[DATA PEDIDO]],"MMM")&"-"&TEXT(M68,"AAAA") -> ago-2025 | O68: 28 | P68: BOLETO | Q68: ENTREGA | R68: 1 | S68: =IF(LANÇAMENTO[[#This Row],[DATA PEDIDO]]="","",LANÇAMENTO[[#This Row],[DATA PEDIDO]]+LANÇAMENTO[[#This Row],[PRAZO]]) -> 45875 | T68: =IF(LANÇAMENTO[[#This Row],[OBRA COM MATERIAL]]="OK","ENTREGUE",IF(LANÇAMENTO[[#This Row],[PRAZO]]="","",LANÇAMENTO[[#This Row],[PREVISÃO ENTREGA OBRA]]-$E$1)) -> ENTREGUE | U68: OK
A69: 45874 | B69: APARECIDA DE FATIMA | C69: INTERIORANA | D69: ELETRICA | E69: TAMPAO PLASTICO PVC 1 | F69: 40 | G69: UNID. | H69: 7323 | I69: AREA ELETRICOS | J69: TAMPAO PLASTICO PVC 1 | K69: 0.8 | L69: =LANÇAMENTO[[#This Row],[VALOR UNITARIO]]*LANÇAMENTO[[#This Row],[QTDADE]] -> 32 | M69: 45874 | N69: =TEXT(LANÇAMENTO[[#This Row],[DATA PEDIDO]],"MMM")&"-"&TEXT(M69,"AAAA") -> ago-2025 | O69: 28 | P69: BOLETO | Q69: ENTREGA | R69: 1 | S69: =IF(LANÇAMENTO[[#This Row],[DATA PEDIDO]]="","",LANÇAMENTO[[#This Row],[DATA PEDIDO]]+LANÇAMENTO[[#This Row],[PRAZO]]) -> 45875 | T69: =IF(LANÇAMENTO[[#This Row],[OBRA COM MATERIAL]]="OK","ENTREGUE",IF(LANÇAMENTO[[#This Row],[PRAZO]]="","",LANÇAMENTO[[#This Row],[PREVISÃO ENTREGA OBRA]]-$E$1)) -> ENTREGUE | U69: OK
A70: 45874 | B70: APARECIDA DE FATIMA | C70: INTERIORANA | D70: ELETRICA | E70: TAMPAO PLASTICO PVC 3/4 | F70: 40 | G70: UNID. | H70: 7323 | I70: AREA ELETRICOS | J70: TAMPAO PLASTICO PVC 3/4 | K70: 0.7 | L70: =LANÇAMENTO[[#This Row],[VALOR UNITARIO]]*LANÇAMENTO[[#This Row],[QTDADE]] -> 28 | M70: 45874 | N70: =TEXT(LANÇAMENTO[[#This Row],[DATA PEDIDO]],"MMM")&"-"&TEXT(M70,"AAAA") -> ago-2025 | O70: 28 | P70: BOLETO | Q70: ENTREGA | R70: 1 | S70: =IF(LANÇAMENTO[[#This Row],[DATA PEDIDO]]="","",LANÇAMENTO[[#This Row],[DATA PEDIDO]]+LANÇAMENTO[[#This Row],[PRAZO]]) -> 45875 | T70: =IF(LANÇAMENTO[[#This Row],[OBRA COM MATERIAL]]="OK","ENTREGUE",IF(LANÇAMENTO[[#This Row],[PRAZO]]="","",LANÇAMENTO[[#This Row],[PREVISÃO ENTREGA OBRA]]-$E$1)) -> ENTREGUE | U70: OK
A71: 45874 | B71: NEUSA DE FATIMA | C71: INTERIORANA | D71: COBERTURA / FORRO | E71: Pu construcao tubo - 420 gramas - Branco | F71: 25 | G71: UNID. | H71: 7325 | I71: VEDAPREMIX | J71: Pu construcao tubo - 420 gramas - Branco | K71: 13.8 | L71: =LANÇAMENTO[[#This Row],[VALOR UNITARIO]]*LANÇAMENTO[[#This Row],[QTDADE]] -> 345 | M71: 45875 | N71: =TEXT(LANÇAMENTO[[#This Row],[DATA PEDIDO]],"MMM")&"-"&TEXT(M71,"AAAA") -> ago-2025 | O71: 7 | P71: PIX | Q71: ENTREGA | R71: 0 | S71: =IF(LANÇAMENTO[[#This Row],[DATA PEDIDO]]="","",LANÇAMENTO[[#This Row],[DATA PEDIDO]]+LANÇAMENTO[[#This Row],[PRAZO]]) -> 45875 | T71: =IF(LANÇAMENTO[[#This Row],[OBRA COM MATERIAL]]="OK","ENTREGUE",IF(LANÇAMENTO[[#This Row],[PRAZO]]="","",LANÇAMENTO[[#This Row],[PREVISÃO ENTREGA OBRA]]-$E$1)) -> ENTREGUE | U71: OK
...

Sheet Planilha1

Sheet Planilha2

Sheet Planilha3

Sheet PEDIDOS EMITIDOS
A1: DATA PEDIDO | B1: 46128 | E1: COMPRADORA | F1: THAMYRES
A3: PEDIDO | B3: FORNECEDOR | C3: OBRA | D3: CONDIÇÃO PAGAMENTO | E3: FORMA DE PAGAMENTO | F3: Soma de VALOR TOTAL
A4: 8344 | B4: ITA AÇOS | C4: AGENOR DE CAMPOS | D4: 28 | E4: BOLETO | F4: 323.68
A5: 8345 | B5: OLD RIVER | C5: PAULINA ROSA | D5: 28 | E5: BOLETO | F5: 573.56
A6: 8346 | B6: ARTESANA | C6: JULIO SECCO | D6: 0 | E6: CARTÃO | F6: 87.55
A7: 8347 | B7: AREA ELETRICOS | C7: OMAR DONATO | D7: 28 | E7: BOLETO | F7: 1313.4
A8: Total Geral | F8: 2298.19

Sheet BASE PEDIDO
A1: PEDIDO | B1: 8347
A3: DATA PEDIDO | B3: PRAZO | C3: RETIRA OU ENTREGA | D3: ESCOLA | E3: FORNECEDOR | F3: CONDIÇÃO PAGAMENTO | G3: FORMA DE PAGAMENTO | H3: DESCRIÇÃO MATERIAL | I3: UNID | J3: QTDADE | K3: VALOR UNITARIO | L3: FATURAMENTO | M3: Soma de VALOR TOTAL
A4: 46128 | B4: 0 | C4: RETIRA | D4: OMAR DONATO | E4: AREA ELETRICOS | F4: 28 | G4: BOLETO | H4: CABO FLEX750V 1,5MM2 PT | I4: ROLO | J4: 2 | K4: 150 | L4: BRASUL | M4: 300
A5: 46128 | B5: 0 | C5: RETIRA | D5: OMAR DONATO | E5: AREA ELETRICOS | F5: 28 | G5: BOLETO | H5: CABO FLEX750V 1,5MM2 MR | I5: ROLO | J5: 2 | K5: 150 | L5: BRASUL | M5: 300
A6: 46128 | B6: 0 | C6: RETIRA | D6: OMAR DONATO | E6: AREA ELETRICOS | F6: 28 | G6: BOLETO | H6: CABO FLEX750V 1,5MM2 VD | I6: ROLO | J6: 2 | K6: 150 | L6: BRASUL | M6: 300
A7: 46128 | B7: 0 | C7: RETIRA | D7: OMAR DONATO | E7: AREA ELETRICOS | F7: 28 | G7: BOLETO | H7: BOTOEIRA BOMBA LIGA/DESLIGA C/MARTELO | I7: UNID. | J7: 6 | K7: 68.9 | L7: BRASUL | M7: 413.4

Sheet JB IMPRIMIR
M1: JB CONSTRUÇÕES E EMPREENDIMENTOS LTDA
M2: Av luis dummount vilares 2078, São Paulo, Brazil 02239-000
M3: Telefone: (11) 3313-8220
M4: e-mail: thamyres@brasulconstrutora.com.br
C6: DATA: | D6: ='BASE PEDIDO'!A4 -> 46128 | H6: PEDIDO DE COMPRA | K6: Nº | L6: ='BASE PEDIDO'!B1 -> 8347
L7: ='BASE PEDIDO'!D4 -> OMAR DONATO
B9: Razão Social: | E9: =VLOOKUP(E10,FORNECEDOR[#All],2,FALSE) -> AEA DISTRIBUIDORA DE MAT. ELETRICOS LTDA
B10: Fornecedor: | E10: ='BASE PEDIDO'!E4 -> AREA ELETRICOS | J10: Vendedor: | K10: =VLOOKUP(E10,FORNECEDOR[#All],4,FALSE) -> Wellison
B11: E-mail: | E11: =VLOOKUP(E10,FORNECEDOR[#All],3,FALSE) -> 0 | J11: Telefone: | K11: =VLOOKUP(E10,FORNECEDOR[#All],5,FALSE) -> 1133931842
B13: Endereço de Cobrança: Rua Coronel Jordão, 440 /450 | I13: Bairro: Vila Paiva | L13: CEP: 02075-030
B14: Cidade: São Paulo | I14: UF: SP | L14: Comprador: Thamyres
B16: Faturamento: | E16: 14 | F16: =IF(E16="","","dias") -> dias | G16: ='BASE PEDIDO'!G4 -> BOLETO | H16: =IF(G16="PIX",VLOOKUP(E10,FORNECEDOR[#All],6,FALSE),"") | K16: Estimativa de vencimento: | L16: =$L$21+E16 -> 46142
B17: ='BASE PEDIDO'!F4 -> 28 | E17: =MID(B17,4,2) | F17: =IF(E17="","","dias") | H17: =IF(G16="PIX",VLOOKUP(E10,FORNECEDOR[#All],7,FALSE),"") | L17: =IF(E17=""," ",$L$21+E17)
C18: OBS: CONTAR FATURAMENTO A PARTIR DO DIA 27/12/24 PARA MANTER OS FATURAMENTOS ANTERIORES DA JB | E18: =MID(B17,7,2) | F18: =IF(E18="","","dias") | L18: =IF(E18=""," ",$L$21+E18)
B19: OBSERVAÇÃO: | E19: NOTA FISCAL DEVE SER FATURADA EM NOME DA EMPRESA | I19: =IF('BASE PEDIDO'!L4="JB","JB CONSTRUÇÕES E EMPREENDIMENTOS LTDA",IF('BASE PEDIDO'!L4="JB CONSTRUÇÕES E EMPREENDIMENTOS LTDA","JB CONSTRUÇÕES E EMPREENDIMENTOS LTDA","JB CONSTRUÇÕES E EMPREENDIMENTOS LTDA")) -> JB CONSTRUÇÕES E EMPREENDIMENTOS LTDA
B21: PRAZO | D21: ='BASE PEDIDO'!C4 -> RETIRA | F21: ='BASE PEDIDO'!B4 -> 0 | G21: dias | K21: ="DATA PREVISTA DA "&'BASE PEDIDO'!C4 -> DATA PREVISTA DA RETIRA | L21: =F21+D6 -> 46128
B23: Local de Entrega: | E23: =VLOOKUP(L7,OBRAS[#All],4,FALSE) -> Estr. Ernesto Zabeu, 253 | H23: Bairro: | I23: =VLOOKUP(L7,OBRAS[#All],5,FALSE) -> Tatetos
B24: OBRA: | D24: =VLOOKUP(L7,OBRAS[#All],3,FALSE) -> ​Escola Estadual Omar Donato Bassani | H24: Contrato Obra: | I24: =VLOOKUP(L7,OBRAS[#All],7,FALSE) -> 0
B25: CEP: | D25: =VLOOKUP(L7,OBRAS[#All],6,FALSE) -> 09837-150 | H25: Cidade: | I25: =VLOOKUP(L7,OBRAS[#All],8,FALSE) -> São Bernardo | K25: UF: | L25: =VLOOKUP(L7,OBRAS[#All],9,FALSE) -> SP
C28: ITEM | D28: DESCRIÇÃO | I28: QTDADE | J28: UNID. | K28: VALOR UNITÁRIO | L28: VALOR TOTAL
C30: 1 | D30: ='BASE PEDIDO'!H4 -> CABO FLEX750V 1,5MM2 PT | I30: ='BASE PEDIDO'!J4 -> 2 | J30: ='BASE PEDIDO'!I4 -> ROLO | K30: ='BASE PEDIDO'!K4 -> 150 | L30: =I30*K30 -> 300
C31: 2 | D31: ='BASE PEDIDO'!H5 -> CABO FLEX750V 1,5MM2 MR | I31: ='BASE PEDIDO'!J5 -> 2 | J31: ='BASE PEDIDO'!I5 -> ROLO | K31: ='BASE PEDIDO'!K5 -> 150 | L31: =I31*K31 -> 300
C32: 3 | D32: ='BASE PEDIDO'!H6 -> CABO FLEX750V 1,5MM2 VD | I32: ='BASE PEDIDO'!J6 -> 2 | J32: ='BASE PEDIDO'!I6 -> ROLO | K32: ='BASE PEDIDO'!K6 -> 150 | L32: =I32*K32 -> 300
C33: 4 | D33: ='BASE PEDIDO'!H7 -> BOTOEIRA BOMBA LIGA/DESLIGA C/MARTELO | I33: ='BASE PEDIDO'!J7 -> 6 | J33: ='BASE PEDIDO'!I7 -> UNID. | K33: ='BASE PEDIDO'!K7 -> 68.9 | L33: =I33*K33 -> 413.4
C34: 5 | D34: ='BASE PEDIDO'!H8 -> 0 | I34: ='BASE PEDIDO'!J8 -> 0 | J34: ='BASE PEDIDO'!I8 -> 0 | K34: ='BASE PEDIDO'!K8 -> 0 | L34: =I34*K34 -> 0
C35: 6 | D35: ='BASE PEDIDO'!H9 -> 0 | I35: ='BASE PEDIDO'!J9 -> 0 | J35: ='BASE PEDIDO'!I9 -> 0 | K35: ='BASE PEDIDO'!K9 -> 0 | L35: =I35*K35 -> 0
C36: 7 | D36: ='BASE PEDIDO'!H10 -> 0 | I36: ='BASE PEDIDO'!J10 -> 0 | J36: ='BASE PEDIDO'!I10 -> 0 | K36: ='BASE PEDIDO'!K10 -> 0 | L36: =I36*K36 -> 0
C37: 8 | D37: ='BASE PEDIDO'!H11 -> 0 | I37: ='BASE PEDIDO'!J11 -> 0 | J37: ='BASE PEDIDO'!I11 -> 0 | K37: ='BASE PEDIDO'!K11 -> 0 | L37: =I37*K37 -> 0
C38: 9 | D38: ='BASE PEDIDO'!H12 -> 0 | I38: ='BASE PEDIDO'!J12 -> 0 | J38: ='BASE PEDIDO'!I12 -> 0 | K38: ='BASE PEDIDO'!K12 -> 0 | L38: =I38*K38 -> 0
C39: 10 | D39: ='BASE PEDIDO'!H13 -> 0 | I39: ='BASE PEDIDO'!J13 -> 0 | J39: ='BASE PEDIDO'!I13 -> 0 | K39: ='BASE PEDIDO'!K13 -> 0 | L39: =I39*K39 -> 0
C40: 11 | D40: ='BASE PEDIDO'!H14 -> 0 | I40: ='BASE PEDIDO'!J14 -> 0 | J40: ='BASE PEDIDO'!I14 -> 0 | K40: ='BASE PEDIDO'!K14 -> 0 | L40: =I40*K40 -> 0
C41: 12 | D41: ='BASE PEDIDO'!H15 -> 0 | I41: ='BASE PEDIDO'!J15 -> 0 | J41: ='BASE PEDIDO'!I15 -> 0 | K41: ='BASE PEDIDO'!K15 -> 0 | L41: =I41*K41 -> 0
... C59: 30 | D59: ='BASE PEDIDO'!H33 -> 0 | I59: ='BASE PEDIDO'!J33 -> 0 | J59: ='BASE PEDIDO'!I33 -> 0 | K59: ='BASE PEDIDO'!K33 -> 0 | L59: =I59*K59 -> 0
K60: SUB TOTAL | L60: =SUM(L30:L59)-L61 -> 1313.4
K61: DESCONTO | L61: =SUMIF(D30:D57,"DESCONTO",L30:L57) -> 0
K62: TOTAL | L62: =L60+L61 -> 1313.4
L64: Horario de RECEBIMENTO NA OBRA
L65: Segunda a Quinta-feira das 07:30h às 11:30h e das 13:00h as 15:30h
L66: Sexta-feira das 07:30h às 11:30h e das 13:00h as 14:30h

Sheet BRASUL IMPRIMIR
M1: BRASUL CONSTRUTORA LTDA
M2: Rua Coronel Jordão, 440, Vila Paiva - São Paulo, SP - CEP 02075-030
M3: Telefone: (11) 3313-8220
M4: e-mail: thamyres@brasulconstrutora.com.br
C6: DATA: | D6: ='BASE PEDIDO'!A4 -> 46128 | H6: PEDIDO DE COMPRA | K6: Nº | L6: ='BASE PEDIDO'!B1 -> 8347
L7: ='BASE PEDIDO'!D4 -> OMAR DONATO
B9: Razão Social: | E9: =VLOOKUP(E10,FORNECEDOR[#All],2,FALSE) -> AEA DISTRIBUIDORA DE MAT. ELETRICOS LTDA
B10: Fornecedor: | E10: ='BASE PEDIDO'!E4 -> AREA ELETRICOS | J10: Vendedor: | K10: =VLOOKUP(E10,FORNECEDOR[#All],4,FALSE) -> Wellison
B11: E-mail: | J11: Telefone: | K11: =VLOOKUP(E10,FORNECEDOR[#All],5,FALSE) -> 1133931842
B13: Endereço de Cobrança: Rua Coronel Jordão, 440 /450 | I13: Bairro: Vila Paiva | L13: CEP: 02075-030
B14: Cidade: São Paulo | I14: UF: SP | L14: Comprador: Thamyres
B16: Faturamento: | E16: 0 | F16: =IF(E16="","","dias") -> dias | G16: ='BASE PEDIDO'!G4 -> BOLETO | H16: =IF(G16="PIX",VLOOKUP(E10,FORNECEDOR[#All],6,FALSE),"") | K16: Estimativa de vencimento: | L16: =$L$23+E16 -> 46128
B17: ='BASE PEDIDO'!F4 -> 28 | E17: 45 | F17: dias | H17: =IF(G16="PIX",VLOOKUP(E10,FORNECEDOR[#All],7,FALSE),"") | L17: =$L$23+E17 -> 46173
E18: 28 | F18: =IF(E18="","","dias") -> dias | L18: =$L$23+E18 -> 46156
E19: 60 | F19: =IF(E19="","","dias") -> dias | L19: =$L$23+E19 -> 46188
E20: 90 | F20: dias | L20: =$L$23+E20 -> 46218
B21: OBSERVAÇÃO: | E21: NOTA FISCAL DEVE SER FATURADA EM NOME DA EMPRESA | I21: =IF('BASE PEDIDO'!L4="JB","JB CONSTRUÇÕES E EMPREENDIMENTOS LTDA",IF('BASE PEDIDO'!L4="BRASUL","BRASUL CONSTRUTORA LTDA","BRASUL CONSTRUTORA LTDA")) -> BRASUL CONSTRUTORA LTDA
B23: PRAZO | D23: ='BASE PEDIDO'!C4 -> RETIRA | F23: ='BASE PEDIDO'!B4 -> 0 | G23: dias | K23: ="DATA PREVISTA DA "&'BASE PEDIDO'!C4 -> DATA PREVISTA DA RETIRA | L23: =D6+F23 -> 46128
B25: Local de Entrega: | E25: =VLOOKUP(L7,OBRAS[#All],4,FALSE) -> Estr. Ernesto Zabeu, 253 | H25: Bairro: | I25: =VLOOKUP(L7,OBRAS[#All],5,FALSE) -> Tatetos
B26: OBRA: | D26: =VLOOKUP(L7,OBRAS[#All],3,FALSE) -> ​Escola Estadual Omar Donato Bassani | H26: Contrato Obra: | I26: =VLOOKUP(L7,OBRAS[#All],7,FALSE) -> 0
B27: CEP: | D27: =VLOOKUP(L7,OBRAS[#All],6,FALSE) -> 09837-150 | H27: Cidade: | I27: =VLOOKUP(L7,OBRAS[#All],8,FALSE) -> São Bernardo | K27: UF: | L27: =VLOOKUP(L7,OBRAS[#All],9,FALSE) -> SP
C30: ITEM | D30: DESCRIÇÃO | I30: QTDADE | J30: UNID. | K30: VALOR UNITÁRIO | L30: VALOR TOTAL
C32: 1 | D32: ='BASE PEDIDO'!H4 -> CABO FLEX750V 1,5MM2 PT | I32: ='BASE PEDIDO'!J4 -> 2 | J32: ='BASE PEDIDO'!I4 -> ROLO | K32: ='BASE PEDIDO'!K4 -> 150 | L32: =I32*K32 -> 300
C33: 2 | D33: ='BASE PEDIDO'!H5 -> CABO FLEX750V 1,5MM2 MR | I33: ='BASE PEDIDO'!J5 -> 2 | J33: ='BASE PEDIDO'!I5 -> ROLO | K33: ='BASE PEDIDO'!K5 -> 150 | L33: =I33*K33 -> 300
C34: 3 | D34: ='BASE PEDIDO'!H6 -> CABO FLEX750V 1,5MM2 VD | I34: ='BASE PEDIDO'!J6 -> 2 | J34: ='BASE PEDIDO'!I6 -> ROLO | K34: ='BASE PEDIDO'!K6 -> 150 | L34: =I34*K34 -> 300
C35: 4 | D35: ='BASE PEDIDO'!H7 -> BOTOEIRA BOMBA LIGA/DESLIGA C/MARTELO | I35: ='BASE PEDIDO'!J7 -> 6 | J35: ='BASE PEDIDO'!I7 -> UNID. | K35: ='BASE PEDIDO'!K7 -> 68.9 | L35: =I35*K35 -> 413.4
C36: 5 | D36: ='BASE PEDIDO'!H8 -> 0 | I36: ='BASE PEDIDO'!J8 -> 0 | J36: ='BASE PEDIDO'!I8 -> 0 | K36: ='BASE PEDIDO'!K8 -> 0 | L36: =I36*K36 -> 0
C37: 6 | D37: ='BASE PEDIDO'!H9 -> 0 | I37: ='BASE PEDIDO'!J9 -> 0 | J37: ='BASE PEDIDO'!I9 -> 0 | K37: ='BASE PEDIDO'!K9 -> 0 | L37: =I37*K37 -> 0
C38: 7 | D38: ='BASE PEDIDO'!H10 -> 0 | I38: ='BASE PEDIDO'!J10 -> 0 | J38: ='BASE PEDIDO'!I10 -> 0 | K38: ='BASE PEDIDO'!K10 -> 0 | L38: =I38*K38 -> 0
C39: 8 | D39: ='BASE PEDIDO'!H11 -> 0 | I39: ='BASE PEDIDO'!J11 -> 0 | J39: ='BASE PEDIDO'!I11 -> 0 | K39: ='BASE PEDIDO'!K11 -> 0 | L39: =I39*K39 -> 0
C40: 9 | D40: ='BASE PEDIDO'!H12 -> 0 | I40: ='BASE PEDIDO'!J12 -> 0 | J40: ='BASE PEDIDO'!I12 -> 0 | K40: ='BASE PEDIDO'!K12 -> 0 | L40: =I40*K40 -> 0
C41: 10 | D41: ='BASE PEDIDO'!H13 -> 0 | I41: ='BASE PEDIDO'!J13 -> 0 | J41: ='BASE PEDIDO'!I13 -> 0 | K41: ='BASE PEDIDO'!K13 -> 0 | L41: =I41*K41 -> 0
C42: 11 | D42: ='BASE PEDIDO'!H14 -> 0 | I42: ='BASE PEDIDO'!J14 -> 0 | J42: ='BASE PEDIDO'!I14 -> 0 | K42: ='BASE PEDIDO'!K14 -> 0 | L42: =I42*K42 -> 0
C43: 12 | D43: ='BASE PEDIDO'!H15 -> 0 | I43: ='BASE PEDIDO'!J15 -> 0 | J43: ='BASE PEDIDO'!I15 -> 0 | K43: ='BASE PEDIDO'!K15 -> 0 | L43: =I43*K43 -> 0
... C64: 33 | D64: ='BASE PEDIDO'!H36 -> 0 | I64: ='BASE PEDIDO'!J36 -> 0 | J64: ='BASE PEDIDO'!I36 -> 0 | K64: ='BASE PEDIDO'!K36 -> 0 | L64: =I64*K64 -> 0
C65: 51 | D65: ='BASE PEDIDO'!H54 -> 0 | I65: ='BASE PEDIDO'!J54 -> 0 | J65: ='BASE PEDIDO'!I54 -> 0 | K65: ='BASE PEDIDO'!K54 -> 0 | L65: =I65*K65 -> 0
K66: SUB TOTAL | L66: =SUM(L30:L65)-L96 -> 1313.4
K67: DESCONTO | L67: =SUMIF(D32:D65,"DESCONTO",L32:L65) -> 0
K68: TOTAL | L68: =L95+L66 -> 1313.4
L70: Horario de RECEBIMENTO NA OBRA
...

Sheet B&B
M1: B & B Engenharia e Construções LTDA
M2: Rua itamonte 33, 440 , Vila Medeiros - São Paulo, SP - CEP 02220-000
M3: Telefone: (11) 3313-8220
M4: e-mail: thamyres@brasulconstrutora.com.br
C6: DATA: | D6: ='BASE PEDIDO'!A4 -> 46128 | H6: PEDIDO DE COMPRA | K6: Nº | L6: ='BASE PEDIDO'!B1 -> 8347
L7: ='BASE PEDIDO'!D4 -> OMAR DONATO
B9: Razão Social: | E9: =VLOOKUP(E10,FORNECEDOR[#All],2,FALSE) -> AEA DISTRIBUIDORA DE MAT. ELETRICOS LTDA
B10: Fornecedor: | E10: ='BASE PEDIDO'!E4 -> AREA ELETRICOS | J10: Vendedor: | K10: =VLOOKUP(E10,FORNECEDOR[#All],4,FALSE) -> Wellison
B11: E-mail: | E11: =VLOOKUP(E10,FORNECEDOR[#All],3,FALSE) -> 0 | J11: Telefone: | K11: =VLOOKUP(E10,FORNECEDOR[#All],5,FALSE) -> 1133931842
B13: Endereço de Cobrança: Rua Coronel Jordão, 440 /450 | I13: Bairro: Vila Paiva | L13: CEP: 02075-030
B14: Cidade: São Paulo | I14: UF: SP | L14: Comprador: Thamyres
B16: Faturamento: | E16: 28 | F16: =IF(E16="","","dias") -> dias | G16: ='BASE PEDIDO'!G4 -> BOLETO | H16: =IF(G16="PIX",VLOOKUP(E10,FORNECEDOR[#All],6,FALSE),"") | K16: Estimativa de vencimento: | L16: =IF(E16=""," ",$L$22+E16) -> 46156
B17: ='BASE PEDIDO'!F4 -> 28 | E17: =MID(B17,4,2) | F17: =IF(E17="","","dias") | H17: =IF(G16="PIX",VLOOKUP(E10,FORNECEDOR[#All],7,FALSE),"") | L17: =IF(E17=""," ",$L$22+E17)
E18: 35 | F18: dias | L18: =IF(E18=""," ",$L$22+E18) -> 46163
E19: 42 | F19: =IF(E19="","","dias") -> dias | L19: =IF(E19=""," ",$L$22+E19) -> 46170
B20: OBSERVAÇÃO: | E20: NOTA FISCAL DEVE SER FATURADA EM NOME DA EMPRESA | I20: =IF('BASE PEDIDO'!L4="B&B","B&B Engenharia e Construções LTDA",IF('BASE PEDIDO'!L4="B&B Engenharia e Construções LTDA","B&B Engenharia e Construções LTDA","B&B Engenharia e Construções LTDA")) -> B&B Engenharia e Construções LTDA
B22: PRAZO | D22: ='BASE PEDIDO'!C4 -> RETIRA | F22: ='BASE PEDIDO'!B4 -> 0 | G22: dias | K22: ="DATA PREVISTA DA "&'BASE PEDIDO'!C4 -> DATA PREVISTA DA RETIRA | L22: =D6+F22 -> 46128
B24: Local de Entrega: | E24: =VLOOKUP(L7,OBRAS[#All],4,FALSE) -> Estr. Ernesto Zabeu, 253 | H24: Bairro: | I24: =VLOOKUP(L7,OBRAS[#All],5,FALSE) -> Tatetos
B25: OBRA: | D25: =VLOOKUP(L7,OBRAS[#All],3,FALSE) -> ​Escola Estadual Omar Donato Bassani | H25: Contrato Obra: | I25: =VLOOKUP(L7,OBRAS[#All],7,FALSE) -> 0
B26: CEP: | D26: =VLOOKUP(L7,OBRAS[#All],6,FALSE) -> 09837-150 | H26: Cidade: | I26: =VLOOKUP(L7,OBRAS[#All],8,FALSE) -> São Bernardo | K26: UF: | L26: =VLOOKUP(L7,OBRAS[#All],9,FALSE) -> SP
C29: ITEM | D29: DESCRIÇÃO | I29: QTDADE | J29: UNID. | K29: VALOR UNITÁRIO | L29: VALOR TOTAL
C31: 1 | D31: ='BASE PEDIDO'!H4 -> CABO FLEX750V 1,5MM2 PT | I31: ='BASE PEDIDO'!J4 -> 2 | J31: ='BASE PEDIDO'!I4 -> ROLO | K31: ='BASE PEDIDO'!K4 -> 150 | L31: =I31*K31 -> 300
C32: 2 | D32: ='BASE PEDIDO'!H5 -> CABO FLEX750V 1,5MM2 MR | I32: ='BASE PEDIDO'!J5 -> 2 | J32: ='BASE PEDIDO'!I5 -> ROLO | K32: ='BASE PEDIDO'!K5 -> 150 | L32: =I32*K32 -> 300
C33: 3 | D33: ='BASE PEDIDO'!H6 -> CABO FLEX750V 1,5MM2 VD | I33: ='BASE PEDIDO'!J6 -> 2 | J33: ='BASE PEDIDO'!I6 -> ROLO | K33: ='BASE PEDIDO'!K6 -> 150 | L33: =I33*K33 -> 300
C34: 4 | D34: ='BASE PEDIDO'!H7 -> BOTOEIRA BOMBA LIGA/DESLIGA C/MARTELO | I34: ='BASE PEDIDO'!J7 -> 6 | J34: ='BASE PEDIDO'!I7 -> UNID. | K34: ='BASE PEDIDO'!K7 -> 68.9 | L34: =I34*K34 -> 413.4
C35: 5 | D35: ='BASE PEDIDO'!H8 -> 0 | I35: ='BASE PEDIDO'!J8 -> 0 | J35: ='BASE PEDIDO'!I8 -> 0 | K35: ='BASE PEDIDO'!K8 -> 0 | L35: =I35*K35 -> 0
C36: 6 | D36: ='BASE PEDIDO'!H9 -> 0 | I36: ='BASE PEDIDO'!J9 -> 0 | J36: ='BASE PEDIDO'!I9 -> 0 | K36: ='BASE PEDIDO'!K9 -> 0 | L36: =I36*K36 -> 0
C37: 7 | D37: ='BASE PEDIDO'!H10 -> 0 | I37: ='BASE PEDIDO'!J10 -> 0 | J37: ='BASE PEDIDO'!I10 -> 0 | K37: ='BASE PEDIDO'!K10 -> 0 | L37: =I37*K37 -> 0
C38: 8 | D38: ='BASE PEDIDO'!H11 -> 0 | I38: ='BASE PEDIDO'!J11 -> 0 | J38: ='BASE PEDIDO'!I11 -> 0 | K38: ='BASE PEDIDO'!K11 -> 0 | L38: =I38*K38 -> 0
C39: 9 | D39: ='BASE PEDIDO'!H12 -> 0 | I39: ='BASE PEDIDO'!J12 -> 0 | J39: ='BASE PEDIDO'!I12 -> 0 | K39: ='BASE PEDIDO'!K12 -> 0 | L39: =I39*K39 -> 0
C40: 10 | D40: ='BASE PEDIDO'!H13 -> 0 | I40: ='BASE PEDIDO'!J13 -> 0 | J40: ='BASE PEDIDO'!I13 -> 0 | K40: ='BASE PEDIDO'!K13 -> 0 | L40: =I40*K40 -> 0
C41: 11 | D41: ='BASE PEDIDO'!H14 -> 0 | I41: ='BASE PEDIDO'!J14 -> 0 | J41: ='BASE PEDIDO'!I14 -> 0 | K41: ='BASE PEDIDO'!K14 -> 0 | L41: =I41*K41 -> 0
C42: 12 | D42: ='BASE PEDIDO'!H15 -> 0 | I42: ='BASE PEDIDO'!J15 -> 0 | J42: ='BASE PEDIDO'!I15 -> 0 | K42: ='BASE PEDIDO'!K15 -> 0 | L42: =I42*K42 -> 0
... C95: 65 | D95: ='BASE PEDIDO'!H68 -> 0 | I95: ='BASE PEDIDO'!J68 -> 0 | J95: ='BASE PEDIDO'!I68 -> 0 | K95: ='BASE PEDIDO'!K68 -> 0 | L95: =I95*K95 -> 0
K96: SUB TOTAL | L96: =SUM(L31:L95)-L97 -> 1313.4
K97: DESCONTO | L97: =SUMIF(D31:D88,"DESCONTO",L31:L88) -> 0
K98: TOTAL | L98: =L96+L97 -> 1313.4
L100: Horario de RECEBIMENTO NA OBRA
L101: Segunda a Quinta-feira das 07:30h às 11:30h e das 13:00h as 15:30h
L102: Sexta-feira das 07:30h às 11:30h e das 13:00h as 14:30h

Sheet INTERIORANA IMPRIMIR
M1: INTERIORANA CONSTRUTORA LTDA
M2: Avª Mofarrej, 348 – Sala 703 – Vila Leopoldina – São Paulo/SP
M3: Telefone: (11) 2892.8916
M4: e-mail: thamyres@brasulconstrutora.com.br
C6: DATA: | D6: ='BASE PEDIDO'!A4 -> 46128 | H6: PEDIDO DE COMPRA | K6: Nº | L6: ='BASE PEDIDO'!B1 -> 8347
L7: ='BASE PEDIDO'!D4 -> OMAR DONATO
B9: Razão Social: | E9: =VLOOKUP(E10,FORNECEDOR[#All],2,FALSE) -> AEA DISTRIBUIDORA DE MAT. ELETRICOS LTDA
B10: Fornecedor: | E10: ='BASE PEDIDO'!E4 -> AREA ELETRICOS | J10: Vendedor: | K10: =VLOOKUP(E10,FORNECEDOR[#All],4,FALSE) -> Wellison
B11: E-mail: | J11: Telefone: | K11: =VLOOKUP(E10,FORNECEDOR[#All],5,FALSE) -> 1133931842
B13: Endereço de Cobrança: Rua Coronel Jordão, 440 /450 | I13: Bairro: Vila Paiva | L13: CEP: 02075-030
B14: Cidade: São Paulo | I14: UF: SP | L14: Comprador: Thamyres
B16: Faturamento: | E16: 28 | F16: =IF(E16="","","dias") -> dias | G16: ='BASE PEDIDO'!G4 -> BOLETO | H16: =IF(G16="PIX",VLOOKUP(E10,FORNECEDOR[#All],6,FALSE),"") | K16: Estimativa de vencimento: | L16: =$L$24+E16 -> 46156
B17: ='BASE PEDIDO'!F4 -> 28 | E17: 60 | F17: dias | L17: =$L$24+E17 -> 46188
E18: 90 | F18: dias | H18: =IF(G16="PIX",VLOOKUP(E10,FORNECEDOR[#All],7,FALSE),"") | L18: =IF(E18=""," ",$D$6+E18) -> 46218
E19: 35 | F19: =IF(E19="","","dias") -> dias | L19: =IF(E19=""," ",$D$6+E19) -> 46163
E20: 60 | F20: =IF(E20="","","dias") -> dias | L20: =IF(E20=""," ",$L$24+E20) -> 46188
E21: 60 | F21: =IF(E21="","","dias") -> dias | L21: =IF(E21=""," ",$L$24+E21) -> 46188
B22: OBSERVAÇÃO: | E22: NOTA FISCAL DEVE SER FATURADA EM NOME DA EMPRESA | I22: =IF('BASE PEDIDO'!L4="JB","JB CONSTRUÇÕES E EMPREENDIMENTOS LTDA",IF('BASE PEDIDO'!L4="BRASUL","BRASUL CONSTRUTORA LTDA","INTERIORANA CONSTRUTORA LTDA")) -> BRASUL CONSTRUTORA LTDA
B24: PRAZO | D24: ='BASE PEDIDO'!C4 -> RETIRA | F24: ='BASE PEDIDO'!B4 -> 0 | G24: dias | K24: ="DATA PREVISTA DA "&'BASE PEDIDO'!C4 -> DATA PREVISTA DA RETIRA | L24: =D6+F24 -> 46128
B26: Local de Entrega: | E26: =VLOOKUP(L7,OBRAS[#All],4,FALSE) -> Estr. Ernesto Zabeu, 253 | H26: Bairro: | I26: =VLOOKUP(L7,OBRAS[#All],5,FALSE) -> Tatetos
B27: OBRA: | D27: =VLOOKUP(L7,OBRAS[#All],3,FALSE) -> ​Escola Estadual Omar Donato Bassani | H27: Contrato Obra: | I27: =VLOOKUP(L7,OBRAS[#All],7,FALSE) -> 0
B28: CEP: | H28: Cidade: | I28: =VLOOKUP(L7,OBRAS[#All],8,FALSE) -> São Bernardo | K28: UF: | L28: =VLOOKUP(L7,OBRAS[#All],9,FALSE) -> SP
C31: ITEM | D31: DESCRIÇÃO | I31: QTDADE | J31: UNID. | K31: VALOR UNITÁRIO | L31: VALOR TOTAL
C33: 1 | D33: ='BASE PEDIDO'!H4 -> CABO FLEX750V 1,5MM2 PT | I33: ='BASE PEDIDO'!J4 -> 2 | J33: ='BASE PEDIDO'!I4 -> ROLO | K33: ='BASE PEDIDO'!K4 -> 150 | L33: =I33*K33 -> 300
C34: 2 | D34: ='BASE PEDIDO'!H5 -> CABO FLEX750V 1,5MM2 MR | I34: ='BASE PEDIDO'!J5 -> 2 | J34: ='BASE PEDIDO'!I5 -> ROLO | K34: ='BASE PEDIDO'!K5 -> 150 | L34: =I34*K34 -> 300
C35: 3 | D35: ='BASE PEDIDO'!H6 -> CABO FLEX750V 1,5MM2 VD | I35: ='BASE PEDIDO'!J6 -> 2 | J35: ='BASE PEDIDO'!I6 -> ROLO | K35: ='BASE PEDIDO'!K6 -> 150 | L35: =I35*K35 -> 300
C36: 4 | D36: ='BASE PEDIDO'!H7 -> BOTOEIRA BOMBA LIGA/DESLIGA C/MARTELO | I36: ='BASE PEDIDO'!J7 -> 6 | J36: ='BASE PEDIDO'!I7 -> UNID. | K36: ='BASE PEDIDO'!K7 -> 68.9 | L36: =I36*K36 -> 413.4
C37: 5 | D37: ='BASE PEDIDO'!H8 -> 0 | I37: ='BASE PEDIDO'!J8 -> 0 | J37: ='BASE PEDIDO'!I8 -> 0 | K37: ='BASE PEDIDO'!K8 -> 0 | L37: =I37*K37 -> 0
C38: 6 | D38: ='BASE PEDIDO'!H9 -> 0 | I38: ='BASE PEDIDO'!J9 -> 0 | J38: ='BASE PEDIDO'!I9 -> 0 | K38: ='BASE PEDIDO'!K9 -> 0 | L38: =I38*K38 -> 0
C39: 7 | D39: ='BASE PEDIDO'!H10 -> 0 | I39: ='BASE PEDIDO'!J10 -> 0 | J39: ='BASE PEDIDO'!I10 -> 0 | K39: ='BASE PEDIDO'!K10 -> 0 | L39: =I39*K39 -> 0
C40: 8 | D40: ='BASE PEDIDO'!H11 -> 0 | I40: ='BASE PEDIDO'!J11 -> 0 | J40: ='BASE PEDIDO'!I11 -> 0 | K40: ='BASE PEDIDO'!K11 -> 0 | L40: =I40*K40 -> 0
C41: 9 | D41: ='BASE PEDIDO'!H12 -> 0 | I41: ='BASE PEDIDO'!J12 -> 0 | J41: ='BASE PEDIDO'!I12 -> 0 | K41: ='BASE PEDIDO'!K12 -> 0 | L41: =I41*K41 -> 0
C42: 10 | D42: ='BASE PEDIDO'!H13 -> 0 | I42: ='BASE PEDIDO'!J13 -> 0 | J42: ='BASE PEDIDO'!I13 -> 0 | K42: ='BASE PEDIDO'!K13 -> 0 | L42: =I42*K42 -> 0
C43: 11 | D43: ='BASE PEDIDO'!H14 -> 0 | I43: ='BASE PEDIDO'!J14 -> 0 | J43: ='BASE PEDIDO'!I14 -> 0 | K43: ='BASE PEDIDO'!K14 -> 0 | L43: =I43*K43 -> 0
C44: 12 | D44: ='BASE PEDIDO'!H15 -> 0 | I44: ='BASE PEDIDO'!J15 -> 0 | J44: ='BASE PEDIDO'!I15 -> 0 | K44: ='BASE PEDIDO'!K15 -> 0 | L44: =I44*K44 -> 0
... C63: 31 | D63: ='BASE PEDIDO'!H34 -> 0 | I63: ='BASE PEDIDO'!J34 -> 0 | J63: ='BASE PEDIDO'!I34 -> 0 | K63: ='BASE PEDIDO'!K34 -> 0 | L63: =I63*K63 -> 0
C64: 32 | D64: ='BASE PEDIDO'!H35 -> 0 | I64: ='BASE PEDIDO'!J35 -> 0 | J64: ='BASE PEDIDO'!I34 -> 0 | K64: ='BASE PEDIDO'!K35 -> 0 | L64: =I64*K64 -> 0
C65: 33 | D65: ='BASE PEDIDO'!H36 -> 0 | I65: ='BASE PEDIDO'!J36 -> 0 | J65: ='BASE PEDIDO'!I35 -> 0 | K65: ='BASE PEDIDO'!K36 -> 0 | L65: =I65*K65 -> 0
C66: 34 | D66: ='BASE PEDIDO'!H37 -> 0 | I66: ='BASE PEDIDO'!J37 -> 0 | J66: ='BASE PEDIDO'!I36 -> 0 | K66: ='BASE PEDIDO'!K37 -> 0 | L66: =I66*K66 -> 0
C67: 35 | D67: ='BASE PEDIDO'!H38 -> 0 | I67: ='BASE PEDIDO'!J38 -> 0 | J67: ='BASE PEDIDO'!I37 -> 0 | K67: ='BASE PEDIDO'!K38 -> 0 | L67: =I67*K67 -> 0
...

Sheet DADOS DAS OBRAS
A1: OBRA | B1: FATURAMENTO | C1: ESCOLA | D1: Local de Entrega: | E1: Bairro: | F1: CEP: | G1: Contrato Obra: | H1: Cidade: | I1: UF: | J1: Empreiteiro | K1: Contato
A2: FCO MIGNONE | B2: BRASUL | C2: EE FRANCISCO MIGNONE | D2: Rua Rio Birigui nº 01 | E2: Gleba do Pessego - Parque do Carmo | F2: 08265-290 | G2: 70/00146/23/01 | H2: São Paulo | I2: SP | J2: BERNARDO | K2: (11) 9.8506-0719
A3: KEIZO - JB | B3: JB | C3: EE KEIZO ISHIHARA | D3: Rua Mário Gessulho, 60 | E3: Conj. Res. Butanta | F3: 05540-130 | G3: 10/00005/23-01-051 | H3: São Paulo | I3: SP | J3: GEORGE | K3: (11) 9.8033-4770
A4: SOLON BORGES - JB | B4: JB | C4: EE/CEL SOLON BORGES DOS REIS | D4: Av. José Joaquim Seabra, 1187 | E4: Rio Pequeno | F4: 05364-000 | G4: 10/00005/23-01-051 | H4: São Paulo | I4: SP | J4: GEORGE | K4: (11) 9.8033-4770
A5: PEDRO COSTA - JB | B5: JB | C5: EE DEP PEDRO COSTA | D5: Rua Nilo Luís Mazzei, 378 | E5: Vila Isolina Mazzei | F5: 02081-070 | G5: 10/00005/23-01-051 | H5: São Paulo | I5: SP | J5: BERNARDO | K5: (11) 9.8506-0719
A6: BENEDITO TOLOSA - JB | B6: JB | C6: EE PROF BENEDITO TOLOSA | D6: Rua Jaguarete, 617 | E6: Casa Verde | F6: 02515-010 | G6: 10/00005/23-01-051 | H6: São Paulo | I6: SP | J6: KERLISON | K6: (11) 9.8570-2178
A7: THEREZA | B7: BRASUL | C7: EE THEREZA SILVEIRA | D7: Rua: Santo Antonio, 41 | E7: Jd. São Miguel | F7: 11440-080 | H7: Guaruja | I7: SP
A8: PE NILDO | B8: BRASUL | C8: EE Padre Nildo do Amaral Junior | D8: R. da Tropicália, s/n | E8: Jardim Pedro José Nunes | F8: 08061-010 | H8: São Paulo | I8: SP
A9: ALDEIA CAPOEIRÃO | B9: BRASUL | C9: EEI ALDEIA CAPOEIRAO | D9: ALDEIA CAPOEIRAO | E9: KM 93 | F9: 11760 - 000 | H9: Itariri | I9: SP | J9: SANDOVAL | K9: (11) 9.7792-3909
A10: ARY BARROSO | B10: BRASUL
A11: ANTONIO FERNANDES | B11: BRASUL | C11: EE PROF ANTONIO FERNANDES | D11: Rua Prof Antonio Fernandes 74 | E11: Vila Tupy | F11: 11900-000 | G11: 69/00811/23/01 | H11: Registro | I11: SP
A12: WALDEMAR RIGOTO - B&B | B12: B&B | C12: E. E. Prof. Waldemar da Silva Rigotto | D12: R. Primeiro de Maio, S/N | E12: Sítio Paecara (Vicente de Carvalho) | F12: 11460-000 | H12: Guaruja | I12: SP
A13: PEDRO BARROS | B13: BRASUL | C13: EE/EMEF PEDRO BARROS | D13: Rod. Régis Bittencourt, 384 | E13: Pedro Barros | F13: 11850-00 | G13: 69/00077/24-001-001 | H13: Miracatu | I13: SP
A14: EE ITARIRI | B14: BRASUL | C14: EE PEI ITARIRI | D14: Rua Benedito Calixto, 306 | E14: Centro Itariri | F14: 11760-000 | G14: 70/00158/23/01 | H14: Itariri | I14: SP
A15: EE WALDOMIRO MARIANI | B15: B&B | C15: EE Prof. Waldomiro Marian | D15: R. Orlando Terras, s/n | E15: Jardim Rea | F15: 11534-870 | H15: Cubatão | I15: SP | K15: (13) 3323-6265
A16: THEREZINHA ARANHA | B16: BRASUL | C16: EE Therezinha A Mantelli | D16: Rua Profº Antonio de Castro Lopes, 930 | E16: PQ Boturussu/Ermelindo Matarazzo | F16: 03805-080 | G16: 70/00146/23/01 | H16: São Paulo | I16: SP
A17: MARIO CORADIN | B17: BRASUL | C17: MARIO CORADIN | D17: Rod. Regis Bittencourt, Km 555 | E17: Rio Vermelho | F17: 11955-000 | G17: 69/01135/23/01 | H17: Barra do Turco | I17: SP
A18: EE GODOFREDO FURTADO - JB | B18: JB | C18: GODOFREDO FURTADO - JB | D18: R. João Moura, 727 - Jardim Paulista, São Paulo | E18: São Paulo | F18: 05412-001 | H18: São Paulo | I18: SP
A19: ALAY CORREA | B19: BRASUL | C19: ALAY JOSE CORREA VEREADOR | D19: R. Serra da Juréia, 130 - Jardim Valeri | E19: Registro | F19: 11900-000 | H19: São Paulo | I19: SP
A20: FDE | B20: BRASUL | C20: Fundação para o Desenvolvimento da Educação | D20: Av. São Luís, 99 - Centro Historico de São Paulo | E20: São Paulo | F20: 01046-001 | H20: São Paulo | I20: SP
A21: JOSE VICENTE BERTOLI | B21: BRASUL | C21: EE Prof. José Vicente Bertoli | D21: Estrada Municipal do Bairro Angatuba, S/N | E21: Angatuba | F21: 11930-000 | H21: Pariquera-Açu | I21: SP
A22: DARWIN FELIX | B22: BRASUL | C22: Escola Estadual Professor Darwin Felix | D22: Rua Quintino Bocaiúva, 406 - V Esperanca | E22: Piquete | F22: 12620-000 | H22: São Paulo | I22: SP
A23: WILSON SIMONINI | B23: BRASUL | C23: EE Wilson Roberto Simonini | D23: Rua João correa magalhães 200 | E23: Pq D João Neri | F23: 08151-260 | G23: 70/00553/22-01 | H23: São Paulo | I23: SP
A24: POETA DOMINGUES | B24: BRASUL | C24: EE POETA DOMINGUES | D24: EE Poeta Domingos Bauer Leite | E24: Miracatu | F24: 11850-000 | H24: Miracatu | I24: SP
A25: CLAY PRESGRAVE | B25: BRASUL | C25: EE Engenheiro Clay Presgrave do Amaral | D25: Av. Engº Clay P. do Amaral, 386 | E25: Ana Dias | F25: 11760-000 | H25: Itariri | I25: SP
A26: ANA ROSA DE ARAUJO | B26: JB | C26: E.E. Dona Ana Rosa De Araújo | D26: R. Eden, 100 | E26: Vila Inah | F26: 05619-000 | H26: São Paulo | I26: SP
A27: FERNANDO ABBUD | B27: BRASUL | C27: E.E Prof. José Fernando Abbud | D27: Av. Afonso Monteiro da Cruz, 261 | E27: Serraria | F27: 09980-550 | H27: Diadema | I27: SP
A28: DE CENTRO | B28: JB | C28: DE CENTRO | D28: Avenida Olavo Fontoura, 2.222 | E28: Casa Verde | F28: 02510-110 | H28: São Paulo | I28: SP
A29: ANTONIO PRADO | B29: JB | C29: EE CONS ANTÔNIO PRADO - JB | D29: R. Vitorino Carmilo, 621 | E29: Barra Funda | F29: 01153-000 | H29: São Paulo | I29: SP
A30: MARIA AP VIANA MUNIZ | B30: BRASUL | C30: MARIA APARECIDA VIANA MUNIZ PROFESSORA | D30: RUA 9 DE JULHO , 112 | E30: CENTRO | H30: Eldorado Registro | I30: SP
A31: ARLINDO BETIO | B31: BRASUL | C31: EE ARLINDO BETIO | D31: R. Vítor Brecheret, 31 | E31: Jardim Casa Grande | H31: Diadema | I31: SP
A32: OROSIMBO MAIA | B32: JB | C32: EE OROSIMBO MAIA | D32: Av. Andrade Neves, 214 | E32: Centro | F32: 13013-160 | H32: Campinas | I32: SP
A33: JOAQUIM FERREIRA | B33: JB | C33: EE JOAQUIM FERREIRA LIMA PROFESSOR | D33: RUA JOAO NOGUEIRA FERRAZ FILHO | E33: Vila Trinta e um de março | F33: 13091-558 | H33: Campinas | I33: SP
A34: MSN LUIS GONZAGA | B34: JB | C34: EE MNS LUIS GONZAGA DE MOURA | D34: R. Carlos Francheu 100 - Centro | E34: Centro | F34: 13023-610 | H34: Campinas | I34: SP
A35: DE MIRACATU | B35: BRASUL | C35: DIRETORIA DE ENSINO MIRACATU | D35: Av. Doná Evarista de Castro Ferreira | E35: Centro | F35: 11850-000 | H35: Miracatu | I35: SP
A36: JOAQUIM LEME PRADO | B36: JB | C36: Escola Estadual Joaquim Leme do Prado | D36: Av. Imirim, 2113 | E36: Imirim | F36: 02465-200 | H36: São Paulo | I36: SP
A37: MARIA MONTESSORI | B37: BRASUL | C37: EE MARIA MONTESSORI | D37: Av. Conceição, 2288 | E37: Vila Maria Alta | F37: 02072-002 | H37: São Paulo | I37: SP
A38: MARIA JOSE MORAIS | B38: BRASUL | C38: EE. Professora Maria José Morais de Carvalho | D38: Estrada dos Moraes, BR-116 | E38: Miracatu | F38: 11850-000 | H38: Miracatu | I38: SP
A39: ANA RITA GODINHO | B39: JB | C39: Escola Estadual Professora Ana Rita Godinho Pousa | D39: R. Benedita Franco Gomes, 165 | E39: Vila Esmeralda | F39: 13077-066 | H39: Campinas | I39: SP
A40: EE Fabio Farias | B40: JB | C40: Escola Estadual Fabio Farias | D40: AV. BRIGADEIRO RAFAEL TOBIAS DE AGUIAR 501 | E40: Jardim Aurelia | F40: 13033-010 | H40: Campinas | I40: SP
...

Sheet FORNECEDORES
A1: FORNECEDOR | B1: Razão Social | C1: E-mail | D1: Vendedor | E1: Telefone | F1: PIX | G1: FAVORECIDO
A2: F PINHEIRO | B2: F Pinheiro Comercio de Mat. p/ Construção LTDA | C2: beatriz@fpinheiro.com.br | D2: Beatriz | E2: (11) 96591-4597 | F2: 54.773.338/0001-05 | G2: F. PINHEIRO COMERCIO DE MATERIAL PARA CONSTRUCAO SLU LTDA
A3: BIG TELHAS | B3: BIG TELHAS CNPJ: 05.167.149/0001-83 | C3: marcos.paulo@telhasmp.com.br | D3: Marcos Paulo | E3: 19 99806-7474
A4: C&C | B4: C&C CASA E CONSTRUÇÃO LTDA | D4: Luciane | E4: (11) 94778-9353
A5: OLD RIVER | B5: PRO LIMA - COMERCIAL E DISTRIBUIDORA LTDA | C5: cotacao@oldriver.com.br | D5: Rudy | E5: 94015-2734
A6: CORANTE | B6: OZ MATERIAIS PARA CONSTRUCAO LTDA - MATRIZ | C6: aretusa@corantetintas.com.br | D6: Aretusa | E6: 11 98269-0417
